File: ENGR270-Material Science Data Analysis/Lab4/Specimen_RawData_1 (4).csv
Time (s),Extension (mm),Load (N),Tensile strain (Strain 1) (mm/mm)
0,-1.56794,-5.96529,-0.00002
0.2,-1.55206,282.84894,0.00003
0.4,-1.53463,641.27869,0.00006
0.6,-1.51781,918.7204,0.00008
0.8,-1.50119,1142.1488,0.00009
1,-1.48444,1329.87549,0.0001
1.2,-1.46775,1501.53845,0.0001
1.4,-1.45131,1651.70264,0.0001
1.6,-1.43431,1795.07507,0.0001
1.8,-1.41769,1924.16882,0.0001
2,-1.40119,2035.19238,0.00009
2.2,-1.38456,2142.25195,0.00007
2.4,-1.36788,2239.88892,0.00007
2.6,-1.35088,2329.91797,0.00005
2.8,-1.33431,2414.58081,0.00004
3,-1.318,2490.03369,0.00003
3.2,-1.30094,2573.24292,0.00001
3.4,-1.2845,2656.40332,0
3.6,-1.26769,2749.63184,-0.00001
3.8,-1.25119,2852.48486,-0.00001
4,-1.23444,2962.30737,-0.00001
4.2,-1.21775,3081.85718,-0.00001
4.4,-1.20131,3193.75146,0
4.6,-1.18425,3308.44336,0.00002
4.8,-1.16769,3422.50439,0.00003
5,-1.15125,3531.96387,0.00005
5.2,-1.13456,3650.32886,0.00006
5.4,-1.11788,3767.54102,0.00008
5.6,-1.10094,3883.9939,0.0001
5.8,-1.08438,4003.93018,0.00011
6,-1.068,4118.60303,0.00013
6.2,-1.051,4243.06055,0.00015
6.4,-1.03444,4362.91016,0.00016
6.6,-1.01775,4481.59375,0.00018
6.8,-1.00119,4605.20459,0.00019
7,-0.98444,4728.9248,0.00021
7.2,-0.96781,4855.41943,0.00023
7.4,-0.95131,4979.4165,0.00025
7.6,-0.93425,5108.79932,0.00027
7.8,-0.91775,5237.23193,0.00029
8,-0.90119,5363.76953,0.0003
8.2,-0.88462,5494.64355,0.00032
8.4,-0.86787,5628.78809,0.00034
8.6,-0.85087,5758.49414,0.00036
8.8,-0.8345,5891.67773,0.00038
9,-0.81794,6022.09375,0.00039
9.2,-0.80094,6161.27344,0.00042
9.4,-0.78444,6293.68359,0.00043
9.6,-0.76769,6428.19727,0.00045
9.8,-0.75125,6562.72754,0.00047
10,-0.73438,6701.1543,0.00049
10.2,-0.71775,6841.08936,0.00051
10.4,-0.70138,6974.89893,0.00053
10.6,-0.68425,7118.17969,0.00056
10.8,-0.66775,7258.11279,0.00057
11,-0.65125,7392.96875,0.00059
11.2,-0.63456,7534.87646,0.00062
11.4,-0.61794,7674.2583,0.00064
11.6,-0.60088,7812.88086,0.00065
11.8,-0.58438,7952.90527,0.00067
12,-0.56806,8086.58545,0.00069
12.2,-0.55088,8233.91016,0.00071
12.4,-0.53444,8369.78516,0.00073
12.6,-0.51781,8506.57812,0.00075
12.8,-0.50119,8647.21973,0.00076
13,-0.48444,8785.73535,0.00079
13.2,-0.46775,8929.38574,0.00081
13.4,-0.45131,9066.20703,0.00083
13.6,-0.43431,9208.03223,0.00084
13.8,-0.41769,9352.91309,0.00086
14,-0.40113,9490.10449,0.00089
14.2,-0.38463,9632.8418,0.00091
14.4,-0.36788,9778.20508,0.00093
14.6,-0.35088,9918.04199,0.00096
14.8,-0.33444,10062.85742,0.00097
15,-0.318,10200.89746,0.001
15.2,-0.30106,10350.52441,0.00102
15.4,-0.28438,10494.91992,0.00104
15.6,-0.26769,10636.43066,0.00106
15.8,-0.25125,10780.05762,0.00108
16,-0.23438,10927.20508,0.00111
16.2,-0.21775,11074.5918,0.00113
16.4,-0.20138,11216.63965,0.00115
16.6,-0.18419,11367.99512,0.00118
16.8,-0.16781,11514.7002,0.0012
17,-0.15119,11660.33496,0.00122
17.2,-0.13456,11809.5127,0.00124
17.4,-0.118,11958.93848,0.00127
17.6,-0.10088,12108.85449,0.00129
17.8,-0.08444,12258.18359,0.00132
18,-0.068,12403.25,0.00134
18.2,-0.05094,12561.42285,0.00136
18.4,-0.0345,12708.4707,0.00139
18.6,-0.01769,12859.33691,0.00141
18.8,-0.00113,13010.89355,0.00143
19,0.0155,13161.60547,0.00146
19.2,0.03219,13318.64453,0.00149
19.4,0.04862,13467.06641,0.00151
19.6,0.06575,13622.96484,0.00154
19.8,0.08225,13776.92969,0.00157
20,0.09875,13925.07129,0.00159
20.2,0.1155,14082.16504,0.00162
20.4,0.13206,14236.68555,0.00165
20.6,0.149,14389.68457,0.00168
20.8,0.16562,14546.39551,0.0017
21,0.18206,14695.9502,0.00173
21.2,0.199,14857.30664,0.00176
21.4,0.21556,15011.30566,0.00178
21.6,0.23225,15163.8623,0.00181
21.8,0.24881,15319.98535,0.00184
22,0.26569,15475.67285,0.00186
22.2,0.28212,15631.59082,0.0019
22.4,0.29869,15785.08887,0.00192
22.6,0.31575,15942.4375,0.00196
22.8,0.33219,16098.11035,0.00199
23,0.34881,16249.94141,0.00202
23.2,0.36537,16405.84375,0.00204
23.4,0.38212,16563.74414,0.00208
23.6,0.39919,16717.66992,0.00211
23.8,0.4155,16871.39453,0.00214
24,0.43206,17021.85352,0.00217
24.2,0.44906,17182.37305,0.00221
24.4,0.4655,17332.91602,0.00224
24.6,0.48231,17484.80273,0.00227
24.8,0.49875,17634.95898,0.00231
25,0.51562,17787.68164,0.00235
25.2,0.53225,17939.99414,0.00238
25.4,0.5485,18081.94141,0.00242
25.6,0.56581,18235.64258,0.00246
25.8,0.58225,18379.91406,0.0025
26,0.59875,18518.19531,0.00254
26.2,0.6155,18663.29883,0.00258
26.4,0.632,18802.96094,0.00263
26.6,0.64912,18941.29297,0.00268
26.8,0.66562,19076.34375,0.00273
27,0.68194,19201.04688,0.00278
27.2,0.69906,19338.63672,0.00284
27.4,0.71562,19460.07812,0.00289
27.6,0.73225,19577.69336,0.00295
27.8,0.74881,19693.01758,0.00301
28,0.76556,19802.83203,0.00308
28.2,0.78219,19908.89648,0.00315
28.4,0.79869,20001.35938,0.00323
28.6,0.81562,20092.28711,0.00331
28.8,0.83231,20173.97656,0.0034
29,0.84887,20236.48047,0.00351
29.2,0.86537,20299.57422,0.00361
29.4,0.88219,20349.99023,0.00373
29.6,0.89912,20386.75391,0.00386
29.8,0.91562,20419.60742,0.00399
30,0.93206,20437.11719,0.00414
30.2,0.94894,20461.16797,0.00429
30.4,0.96569,20473.27539,0.00444
30.6,0.98237,20480.40234,0.0046
30.8,0.99875,20487.97461,0.00476
31,1.01575,20493.73633,0.00493
31.2,1.03219,20498.17969,0.0051
31.4,1.04862,20498.25195,0.00528
31.6,1.06581,20505.48242,0.00546
31.8,1.08212,20503.89062,0.00564
32,1.09894,20504.31055,0.00582
32.2,1.1155,20507.48242,0.00601
32.4,1.132,20509.53711,0.0062
32.6,1.14925,20512.26758,0.00638
32.8,1.16556,20512.95898,0.00658
33,1.182,20513.0332,0.00676
33.2,1.19912,20521.75195,0.00696
33.4,1.2155,20518.76172,0.00715
33.6,1.23237,20523.35742,0.00734
33.8,1.24887,20524.45508,0.00753
34,1.26556,20526.77148,0.00773
34.2,1.28225,20533.61914,0.00793
34.4,1.29862,20530.375,0.00812
34.6,1.31581,20541.01172,0.00831
34.8,1.33231,20541.06836,0.00851
35,1.34875,20539.19727,0.0087
35.2,1.3655,20548.29688,0.0089
35.4,1.38219,20551.35742,0.00909
35.6,1.39906,20553.94727,0.0093
35.8,1.41562,20559.74414,0.00949
36,1.43206,20558.39844,0.0097
36.2,1.449,20570.04297,0.00989
36.4,1.46569,20571.74219,0.0101
36.6,1.48225,20572.55273,0.01029
36.8,1.49881,20578.72461,0.01049
37,1.51575,20581.89258,0.01069
37.2,1.53206,20586.05664,0.01089
37.4,1.54875,20588.39062,0.01109
37.6,1.56581,20595.63477,0.01128
37.8,1.58225,20599.70703,0.01148
38,1.59894,20598.85938,0.01169
38.2,1.61537,20604.96289,0.01188
38.4,1.63219,20612.88672,0.01208
38.6,1.64925,20614.63477,0.01228
38.8,1.66544,20618.11133,0.01248
39,1.68212,20621.24023,0.01268
39.2,1.69906,20629.65039,0.01288
39.4,1.71556,20632.07422,0.01308
39.6,1.73237,20634.59375,0.01328
39.8,1.74875,20637.31445,0.01348
40,1.76569,20643.46289,0.01369
40.2,1.78225,20648.29492,0.01388
40.4,1.79856,20646.92578,0.01408
40.6,1.81587,20659.51953,0.01428
40.8,1.83225,20658.70898,0.01449
41,1.84881,20659.37891,0.01469
41.2,1.86556,20666.77734,0.01489
41.4,1.882,20669.85938,0.01509
41.6,1.89919,20675.78125,0.01529
41.8,1.91562,20679.07227,0.01549
42,1.93187,20677.72852,0.01569
42.2,1.94912,20691.7168,0.0159
42.4,1.96562,20690.86328,0.01609
42.6,1.98231,20693.93359,0.01629
42.8,1.99887,20697.4668,0.01649
43,2.01556,20700.24219,0.01669
43.2,2.03225,20708.55859,0.0169
43.4,2.04869,20706.36719,0.0171
43.6,2.06569,20714.10742,0.0173
43.8,2.08231,20719.39258,0.0175
44,2.09887,20715.82227,0.0177
44.2,2.11537,20723.42773,0.0179
44.4,2.13219,20729.28516,0.0181
44.6,2.14912,20729.89258,0.0183
44.8,2.16562,20736.91992,0.0185
45,2.18206,20735.11719,0.0187
45.2,2.19894,20744.16797,0.0189
45.4,2.21569,20748.95117,0.0191
45.6,2.23237,20747.91992,0.0193
45.8,2.24869,20752.07422,0.0195
46,2.26575,20756.62891,0.0197
46.2,2.28219,20760.01953,0.0199
46.304,2.291,20760.61523,0.02
46.406,2.29619,20741.82227,0.02004
46.606,2.29575,20564.49023,0.02004
46.806,2.29487,20466.91406,0.02003
47.006,2.29444,20404.83789,0.02003
47.206,2.29431,20361.83984,0.02003
47.406,2.29425,20328.41211,0.02003
47.606,2.29425,20301.07812,0.02003
47.806,2.29425,20277.41016,0.02003
48.006,2.29425,20256.60938,0.02003
48.206,2.29425,20238.46875,0.02003
48.406,2.29419,20221.875,0.02003
48.606,2.29419,20207.01562,0.02003
48.806,2.29419,20193.54492,0.02003
49.006,2.29419,20181.04102,0.02003
49.206,2.29419,20169.42578,0.02003
49.406,2.29419,20158.49609,0.02003
49.606,2.29419,20148.65234,0.02003
49.806,2.29419,20139.05273,0.02003
50.006,2.29419,20130.22852,0.02003
50.206,2.29419,20121.88672,0.02003
50.406,2.29419,20113.74219,0.02003
50.606,2.29419,20106.23438,0.02003
50.806,2.29419,20099.14844,0.02003
51.006,2.29419,20092.16992,0.02003
51.206,2.29419,20085.61133,0.02003
51.406,2.29419,20079.43945,0.02003
51.606,2.29419,20073.54297,0.02003
51.806,2.29419,20067.58984,0.02003
52.006,2.29419,20061.91016,0.02003
52.206,2.29419,20056.91797,0.02003
52.406,2.29419,20051.74023,0.02003
52.606,2.29419,20046.70117,0.02003
52.806,2.29419,20041.88672,0.02003
53.006,2.29419,20037.19141,0.02003
53.206,2.29419,20032.53906,0.02003
53.406,2.29419,20028.31641,0.02003
53.606,2.29419,20023.9668,0.02003
53.806,2.29419,20019.85742,0.02003
54.006,2.29419,20015.86719,0.02003
54.206,2.29419,20012.0625,0.02003
54.406,2.29419,20008.17383,0.02003
54.606,2.29419,20004.88867,0.02003
54.806,2.29419,20000.98242,0.02003
55.006,2.29419,19997.70117,0.02003
55.206,2.29419,19994.12891,0.02003
55.406,2.29419,19990.85352,0.02003
55.606,2.29419,19987.72266,0.02003
55.806,2.29419,19984.40039,0.02003
56.006,2.29419,19981.31055,0.02003
56.206,2.29419,19978.45703,0.02003
56.406,2.29419,19975.21875,0.02003
56.606,2.29419,19972.36523,0.02003
56.806,2.29419,19969.57031,0.02003
57.006,2.29419,19966.85742,0.02003
57.206,2.29419,19964.10547,0.02003
57.406,2.29419,19961.49805,0.02003
57.606,2.29419,19958.82422,0.02003
57.806,2.29419,19956.04102,0.02003
58.006,2.29419,19953.90625,0.02003
58.206,2.29419,19951.375,0.02003
58.406,2.29419,19948.82617,0.02003
58.606,2.29419,19946.69531,0.02003
58.806,2.29419,19944.33203,0.02003
59.006,2.29419,19942.00391,0.02003
59.206,2.29419,19939.6875,0.02003
59.406,2.29419,19937.43945,0.02003
59.606,2.29419,19935.27344,0.02003
59.806,2.29419,19933.11328,0.02003
60.006,2.29419,19931.06641,0.02003
60.206,2.29419,19929.10938,0.02003
60.406,2.29419,19927.09375,0.02003
60.606,2.29419,19925.23438,0.02003
60.806,2.29419,19923.66211,0.02003
61.006,2.29419,19922.38867,0.02003
61.206,2.29419,19920.34766,0.02003
61.406,2.29419,19917.37305,0.02003
61.606,2.29419,19915.46875,0.02003
61.806,2.29419,19913.71289,0.02003
62.006,2.29419,19911.76367,0.02003
62.206,2.29419,19910.1543,0.02003
62.406,2.29419,19908.23828,0.02003
62.606,2.29419,19906.74219,0.02003
62.806,2.29419,19905.17578,0.02003
63.006,2.29419,19903.1543,0.02003
63.206,2.29419,19901.58203,0.02003
63.406,2.29419,19899.94141,0.02003
63.606,2.29419,19898.50195,0.02003
63.806,2.29419,19896.875,0.02003
64.006,2.29419,19895.41016,0.02003
64.206,2.29419,19893.59375,0.02003
64.406,2.29419,19892.34375,0.02003
64.606,2.29419,19890.85742,0.02003
64.806,2.29419,19889.16016,0.02003
65.006,2.29419,19887.82031,0.02003
65.206,2.29419,19886.12305,0.02003
65.406,2.29419,19884.85938,0.02003
65.606,2.29419,19883.39062,0.02003
65.806,2.29419,19882.02539,0.02003
66.006,2.29419,19880.78516,0.02003
66.206,2.29419,19879.45508,0.02003
66.406,2.29419,19878.125,0.02003
66.606,2.29419,19876.70898,0.02003
66.806,2.29419,19875.2793,0.02003
67.006,2.29419,19873.93555,0.02003
67.206,2.29419,19872.74414,0.02003
67.406,2.29419,19871.17578,0.02003
67.606,2.29419,19869.98242,0.02003
67.806,2.29419,19869.00781,0.02003
68.006,2.29419,19867.66602,0.02003
68.206,2.29419,19866.41797,0.02003
68.406,2.29419,19865.15625,0.02003
68.606,2.29419,19864.25391,0.02003
68.806,2.29419,19862.86719,0.02003
69.006,2.29419,19861.50586,0.02003
69.206,2.29419,19860.4707,0.02003
69.406,2.29419,19859.4707,0.02003
69.606,2.29419,19858.22266,0.02003
69.806,2.29419,19857.14062,0.02003
70.006,2.29419,19856.0293,0.02003
70.206,2.29419,19854.78906,0.02003
70.406,2.29419,19853.57031,0.02003
70.606,2.29419,19852.82227,0.02003
70.806,2.29419,19851.55859,0.02003
71.006,2.29419,19850.8125,0.02003
71.206,2.29419,19849.4082,0.02003
71.406,2.29419,19848.02539,0.02003
71.606,2.29419,19846.88867,0.02003
71.806,2.29419,19846.05469,0.02003
72.006,2.29419,19844.89648,0.02003
72.206,2.29419,19843.98633,0.02003
72.406,2.29419,19842.4707,0.02003
72.606,2.29419,19841.28906,0.02003
72.806,2.29419,19840.06055,0.02003
73.006,2.29419,19838.79883,0.02003
73.206,2.29419,19837.8125,0.02003
73.406,2.29419,19836.94531,0.02003
73.606,2.29419,19835.91992,0.02003
73.806,2.29419,19834.91406,0.02003
74.006,2.29419,19833.73438,0.02003
74.206,2.29419,19832.70703,0.02003
74.406,2.29419,19832.21094,0.02003
74.606,2.29419,19831.11133,0.02003
74.806,2.29419,19830.20117,0.02003
75.006,2.29419,19829.17969,0.02003
75.206,2.29419,19828.47852,0.02003
75.406,2.29419,19827.41406,0.02003
75.606,2.29419,19826.44727,0.02003
75.806,2.29419,19825.68555,0.02003
76.006,2.29419,19824.73633,0.02003
76.206,2.29419,19823.88867,0.02003
76.406,2.29419,19822.9707,0.02003
76.606,2.29419,19822.33398,0.02003
76.806,2.29419,19821.50391,0.02003
77.006,2.29419,19820.48828,0.02003
77.206,2.29419,19819.46289,0.02003
77.406,2.29419,19818.89062,0.02003
77.606,2.29419,19817.84961,0.02003
77.806,2.29419,19817.14258,0.02003
78.006,2.29419,19816.25,0.02003
78.206,2.29419,19815.47852,0.02003
78.406,2.29419,19814.57227,0.02003
78.606,2.29419,19813.91211,0.02003
78.806,2.29419,19813.37695,0.02003
79.006,2.29419,19812.24023,0.02003
79.206,2.29419,19811.81055,0.02003
79.406,2.29419,19810.99805,0.02003
79.606,2.29419,19810.27148,0.02003
79.806,2.29419,19809.62695,0.02003
80.006,2.29419,19808.98438,0.02003
80.206,2.29419,19808.4043,0.02003
80.406,2.29419,19807.7207,0.02003
80.606,2.29419,19806.53711,0.02003
80.806,2.29419,19805.90234,0.02003
81.006,2.29419,19805.23633,0.02003
81.206,2.29419,19804.38867,0.02003
81.406,2.29419,19803.71289,0.02003
81.606,2.29419,19802.875,0.02003
81.806,2.29419,19802.2207,0.02003
82.006,2.29419,19801.5625,0.02003
82.206,2.29419,19800.75,0.02003
82.406,2.29419,19800.24805,0.02003
82.606,2.29419,19799.39844,0.02003
82.806,2.29419,19798.87305,0.02003
83.006,2.29419,19797.98438,0.02003
83.206,2.29419,19797.41211,0.02003
83.406,2.29419,19796.57031,0.02003
83.606,2.29419,19796.0625,0.02003
83.806,2.29419,19795.41602,0.02003
84.006,2.29419,19794.84766,0.02003
84.206,2.29419,19794.00586,0.02003
84.406,2.29419,19793.39258,0.02003
84.606,2.29419,19792.9043,0.02003
84.806,2.29419,19792.11133,0.02003
85.006,2.29419,19791.58594,0.02003
85.206,2.29419,19790.91992,0.02003
85.406,2.29419,19790.30469,0.02003
85.54,2.29419,19789.89648,0.02003
85.642,2.29481,19790.37109,0.02003
85.842,2.31512,20168.27734,0.02019
86.042,2.332,20463.02539,0.02032
86.242,2.34887,20641.50195,0.02046
86.442,2.3655,20739.63281,0.02059
86.642,2.382,20784.4668,0.02072
86.842,2.39925,20804.33008,0.02085
87.042,2.41556,20812.41602,0.02098
87.242,2.43206,20813.13477,0.02111
87.442,2.44912,20821.1582,0.02125
87.642,2.4655,20817.55078,0.02138
87.842,2.4825,20821.36133,0.02151
88.042,2.49881,20818.41602,0.02164
88.242,2.5155,20820.22852,0.02177
88.442,2.53231,20825.8125,0.0219
88.642,2.54862,20821.12305,0.02203
88.842,2.56581,20830.2832,0.02217
89.042,2.58225,20828.71094,0.02229
89.242,2.59875,20826.03516,0.02242
89.442,2.61556,20834.4082,0.02256
89.642,2.63212,20835.28906,0.02269
89.842,2.64906,20836.75781,0.02282
90.042,2.66562,20842.46094,0.02295
90.242,2.682,20838.84961,0.02308
90.442,2.69906,20850.21484,0.02321
90.642,2.71569,20849.23633,0.02335
90.842,2.73225,20849.38672,0.02348
91.042,2.74887,20855.29883,0.02361
91.242,2.76569,20855.5957,0.02374
91.442,2.78212,20859.99414,0.02387
91.642,2.79875,20860.82617,0.024
91.842,2.81575,20866.18164,0.02413
92.042,2.83225,20868.96094,0.02426
92.242,2.84894,20866.2793,0.02439
92.442,2.86537,20870.98633,0.02452
92.642,2.88219,20877.83594,0.02466
92.842,2.89925,20877.44922,0.02479
93.042,2.91544,20880.43359,0.02492
93.242,2.93212,20882.04492,0.02505
93.442,2.949,20889.86719,0.02518
93.642,2.96556,20889.89648,0.02531
93.842,2.9825,20892.28125,0.02545
94.042,2.99875,20892.2793,0.02557
94.242,3.01575,20898.45898,0.02571
94.442,3.03219,20899.87305,0.02584
94.642,3.04856,20898.55469,0.02597
94.842,3.06587,20908.875,0.0261
95.042,3.08225,20906.80078,0.02623
95.242,3.09881,20906.25391,0.02636
95.442,3.11556,20912.5332,0.02649
95.642,3.13206,20914.01758,0.02662
95.842,3.14919,20918.4375,0.02676
96.042,3.16562,20920.10742,0.02689
96.242,3.18187,20916.67188,0.02702
96.442,3.19912,20930.13281,0.02715
96.642,3.21562,20927.47266,0.02728
96.842,3.23231,20928.00977,0.02741
97.042,3.24881,20931.35352,0.02754
97.242,3.26556,20932.66602,0.02767
97.442,3.28225,20939.29297,0.02781
97.642,3.29869,20935.55859,0.02794
97.842,3.31562,20941.08008,0.02807
98.042,3.33231,20945.61523,0.0282
98.242,3.34887,20941,0.02833
98.442,3.36544,20947.14844,0.02846
98.642,3.38219,20951.79102,0.02859
98.842,3.39912,20950.60938,0.02873
99.042,3.41569,20957.32617,0.02886
99.242,3.43212,20953.4043,0.02899
99.442,3.44894,20960.7168,0.02912
99.642,3.46569,20963.71289,0.02925
99.842,3.48237,20962.17773,0.02938
100.042,3.49875,20964.30273,0.02951
100.242,3.51575,20967.37695,0.02964
100.442,3.53219,20969.80078,0.02977
100.642,3.54869,20969.56836,0.0299
100.842,3.56581,20975.65039,0.03004
101.042,3.58206,20974.08594,0.03017
101.242,3.59894,20976.04492,0.0303
101.442,3.6155,20978.33984,0.03043
101.642,3.632,20981.43945,0.03056
101.842,3.64925,20985.18555,0.0307
102.042,3.6655,20984.66016,0.03082
102.242,3.682,20984.32812,0.03095
102.442,3.69912,20992.9043,0.03109
102.642,3.7155,20989.82422,0.03122
102.842,3.73244,20994.13672,0.03135
103.042,3.74887,20994.05273,0.03148
103.242,3.7655,20995.15234,0.03161
103.442,3.78231,21001.42383,0.03174
103.642,3.79862,20996.28906,0.03187
103.842,3.81581,21005.26758,0.03201
104.042,3.83231,21004.83008,0.03214
104.242,3.84869,21000.16406,0.03227
104.442,3.86556,21009.31445,0.0324
104.642,3.88212,21009.24414,0.03253
104.842,3.899,21009.25977,0.03266
105.042,3.91569,21014.78711,0.03279
105.242,3.932,21010.33398,0.03292
105.442,3.94906,21020.52539,0.03306
105.642,3.96562,21018.78711,0.03319
105.842,3.98225,21017.66016,0.03332
106.042,3.99887,21021.85547,0.03345
106.242,4.01569,21021.62305,0.03358
106.442,4.03212,21024.31445,0.03371
106.642,4.04875,21023.91211,0.03384
106.842,4.06581,21028.78516,0.03398
107.042,4.08219,21029.68164,0.0341
107.242,4.09887,21027.14453,0.03424
107.442,4.11537,21029.9707,0.03437
107.642,4.13219,21035.50586,0.0345
107.842,4.14925,21035.02344,0.03463
108.042,4.16544,21035.36133,0.03476
108.242,4.18212,21036.07227,0.03489
108.442,4.19906,21042.69922,0.03503
108.642,4.21556,21042.19141,0.03516
108.842,4.23244,21042.73047,0.03529
109.042,4.24875,21041.77148,0.03542
109.242,4.26569,21046.06836,0.03555
109.442,4.28225,21047.60352,0.03568
109.642,4.29856,21043.14453,0.03581
109.842,4.31587,21053.31641,0.03595
110.042,4.33225,21050.62695,0.03607
110.242,4.34881,21048.73242,0.0362
110.442,4.3655,21053.10156,0.03634
110.642,4.38206,21053.85547,0.03647
110.842,4.39919,21056.7793,0.0366
111.042,4.41569,21058.38867,0.03673
111.242,4.43194,21053.65625,0.03686
111.442,4.44912,21064.7832,0.03699
111.642,4.46562,21061.87695,0.03712
111.842,4.48231,21061.98438,0.03726
112.042,4.49894,21064.5918,0.03739
112.242,4.51562,21063.26367,0.03752
112.442,4.53219,21068.10156,0.03765
112.642,4.54869,21064.22852,0.03778
112.842,4.56569,21069.33789,0.03791
113.042,4.58231,21071.07422,0.03804
113.242,4.59887,21065.97461,0.03817
113.442,4.61544,21071.07422,0.0383
113.642,4.63219,21073.93945,0.03844
113.842,4.64906,21072.49805,0.03857
114.042,4.66562,21077.32227,0.0387
114.242,4.68206,21072.57617,0.03883
114.442,4.69894,21079.79492,0.03896
114.642,4.71569,21080.75195,0.03909
114.842,4.73237,21078.67773,0.03922
115.042,4.74869,21079.38086,0.03935
115.242,4.76575,21081.94141,0.03949
115.442,4.78219,21083.60156,0.03962
115.642,4.79862,21081.34375,0.03975
115.842,4.81587,21087.37695,0.03988
116.042,4.83212,21084.32422,0.04001
116.242,4.84887,21083.95898,0.04014
116.442,4.8655,21087.20703,0.04027
116.642,4.88206,21088.36523,0.0404
116.842,4.89919,21089.64844,0.04054
117.042,4.91556,21090.73633,0.04067
117.242,4.932,21089.30078,0.0408
117.442,4.94912,21095.86328,0.04093
117.642,4.9655,21092.26367,0.04106
117.842,4.98244,21094.7168,0.04119
118.042,4.99887,21093.62305,0.04132
118.242,5.01556,21094.22656,0.04145
118.442,5.03231,21099.85938,0.04159
118.642,5.04862,21093.64844,0.04171
118.842,5.06581,21101.71094,0.04185
119.042,5.08231,21099.77734,0.04198
119.242,5.09875,21094.7207,0.04211
119.442,5.1155,21101.73047,0.04224
119.642,5.13219,21101.92969,0.04237
119.842,5.14906,21100.95117,0.04251
120.042,5.16569,21105.44922,0.04264
120.242,5.18206,21099.58008,0.04277
120.442,5.199,21108.38672,0.0429
120.642,5.21569,21106.43164,0.04303
120.842,5.23231,21104.42773,0.04316
121.042,5.24887,21107.61328,0.04329
121.242,5.26575,21106.90234,0.04342
121.442,5.28212,21108.66797,0.04355
121.642,5.29875,21107.20508,0.04368
121.842,5.31581,21111.7168,0.04382
122.042,5.33219,21111.63086,0.04395
122.242,5.34887,21107.42969,0.04408
122.442,5.36537,21109.92188,0.04421
122.642,5.38219,21114.01953,0.04434
122.842,5.39925,21112.63477,0.04448
123.042,5.4155,21112.9375,0.0446
123.242,5.43206,21111.35742,0.04473
123.442,5.44906,21118.23047,0.04487
123.642,5.46556,21116.06836,0.045
123.842,5.48244,21116.64062,0.04513
124.042,5.49875,21114.76562,0.04526
124.242,5.51569,21117.53516,0.04539
124.442,5.53231,21119.37695,0.04552
124.642,5.5485,21113.47266,0.04565
124.842,5.56587,21122.94531,0.04579
125.042,5.58225,21119.2832,0.04592
125.242,5.59875,21115.62109,0.04605
125.442,5.6155,21119.85938,0.04618
125.642,5.63206,21119.75781,0.04631
125.842,5.64919,21122.00781,0.04644
126.042,5.66569,21122.32812,0.04657
126.242,5.68187,21117.60156,0.0467
126.442,5.69906,21126.98047,0.04684
126.642,5.71562,21123.49219,0.04697
126.842,5.73225,21121.66797,0.0471
127.042,5.74887,21123.93359,0.04723
127.242,5.76562,21122.63086,0.04736
127.442,5.78225,21127.76953,0.04749
127.642,5.79875,21122.2793,0.04762
127.842,5.81569,21126.31641,0.04775
128.042,5.83225,21127.95508,0.04788
128.242,5.84894,21122.20898,0.04802
128.442,5.86537,21125.8418,0.04815
128.642,5.88219,21128.35547,0.04828
128.842,5.89912,21125.62891,0.04841
129.042,5.91562,21129.43945,0.04854
129.242,5.93206,21124.03906,0.04867
129.442,5.94894,21130.46484,0.0488
129.642,5.96562,21130.10352,0.04894
129.842,5.98237,21127.94922,0.04907
130.042,5.99875,21128.02344,0.0492
130.242,6.01575,21129.31445,0.04933
130.442,6.03219,21129.75781,0.04946
130.642,6.04862,21127.61523,0.04959
130.842,6.06581,21132.1875,0.04972
131.042,6.08212,21129.68555,0.04985
131.242,6.09894,21128.31445,0.04998
131.442,6.1155,21129.35938,0.05012
131.642,6.132,21130.93945,0.05025
131.842,6.14919,21131.89844,0.05038
132.042,6.16556,21131.2207,0.05051
132.242,6.182,21128.94922,0.05064
132.442,6.19912,21135.76758,0.05077
132.642,6.21556,21131.8457,0.0509
132.842,6.23244,21133.06055,0.05104
133.042,6.24887,21131.55273,0.05117
133.242,6.2655,21130.87891,0.0513
133.442,6.28225,21135.33984,0.05143
133.642,6.29862,21127.81836,0.05156
133.842,6.31581,21135.99219,0.05169
134.042,6.33231,21133.82227,0.05182
134.242,6.34869,21127.09961,0.05195
134.442,6.3655,21134.22266,0.05208
134.642,6.38219,21133.42188,0.05222
134.842,6.39906,21132.28516,0.05235
135.042,6.41562,21135.32812,0.05248
135.242,6.432,21128.86133,0.05261
135.442,6.44906,21138.16602,0.05274
135.642,6.46569,21134.65039,0.05287
135.842,6.48225,21131.48633,0.053
136.042,6.49887,21134.83008,0.05313
136.242,6.51569,21132.46094,0.05327
136.442,6.53212,21134.46094,0.0534
136.642,6.54869,21131.625,0.05353
136.842,6.56581,21135.44922,0.05366
137.042,6.58219,21135.00195,0.05379
137.242,6.59894,21130.92188,0.05392
137.442,6.61544,21132.17773,0.05405
137.642,6.63212,21134.94727,0.05418
137.842,6.64919,21133.02148,0.05432
138.042,6.66544,21132.64258,0.05445
138.242,6.68212,21131.83008,0.05458
138.442,6.69906,21136.4668,0.05471
138.642,6.71556,21134.32227,0.05484
138.842,6.73244,21134.13086,0.05497
139.042,6.74875,21132.04102,0.0551
139.242,6.76569,21133.86328,0.05523
139.442,6.78225,21133.75977,0.05537
139.642,6.7985,21128.45117,0.05549
139.842,6.81587,21137.26953,0.05563
140.042,6.83225,21131.94922,0.05576
140.242,6.84875,21128.38086,0.05589
140.442,6.86556,21132.92578,0.05602
140.642,6.88206,21132.01953,0.05615
140.842,6.89919,21133.31641,0.05629
141.042,6.91562,21132.12109,0.05642
141.242,6.93194,21126.94141,0.05654
141.442,6.94906,21135.92383,0.05668
141.642,6.96562,21131.58984,0.05681
141.842,6.98231,21130.55859,0.05694
142.042,6.99887,21131.32812,0.05707
142.242,7.01556,21127.89062,0.0572
142.442,7.03225,21133.28906,0.05733
142.642,7.04869,21127.76953,0.05746
142.842,7.06569,21130.80664,0.0576
143.042,7.08231,21132.08984,0.05773
143.242,7.09887,21125.0918,0.05786
143.442,7.11537,21128.80859,0.05799
143.642,7.13219,21130.36133,0.05812
143.842,7.14912,21127.77539,0.05825
144.042,7.16562,21130.26562,0.05838
144.242,7.18206,21124.11523,0.05851
144.442,7.19894,21130.42578,0.05865
144.642,7.21569,21130.38281,0.05878
144.842,7.23244,21126.62109,0.05891
145.042,7.24875,21126.29297,0.05904
145.242,7.26569,21126.36719,0.05917
145.442,7.28212,21126.41406,0.0593
145.642,7.29869,21124.33594,0.05943
145.842,7.31587,21128.67969,0.05957
146.042,7.33212,21124.84766,0.0597
146.242,7.34894,21122.80469,0.05983
146.442,7.3655,21123.76758,0.05996
146.642,7.382,21124.03906,0.06009
146.842,7.39925,21124.07227,0.06022
147.042,7.41556,21123.19727,0.06035
147.242,7.432,21120.48047,0.06048
147.442,7.44912,21126.61133,0.06062
147.642,7.4655,21121.64258,0.06075
147.842,7.48244,21123.17969,0.06088
148.042,7.49881,21120.32422,0.06101
148.242,7.51556,21120.28516,0.06114
148.442,7.53225,21123.02148,0.06127
148.642,7.54862,21116.15039,0.0614
148.842,7.56581,21122.38867,0.06154
149.042,7.58231,21119.82812,0.06167
149.242,7.59875,21114.01172,0.06179
149.442,7.6155,21119.12305,0.06193
149.642,7.63212,21118.02539,0.06206
149.842,7.64906,21116.30078,0.06219
150.042,7.66562,21118.32617,0.06232
150.242,7.682,21112.05273,0.06245
150.442,7.699,21119.21484,0.06258
150.642,7.71569,21116.35352,0.06272
150.842,7.73225,21112.85938,0.06285
151.042,7.74894,21115.23242,0.06298
151.242,7.76569,21111.6875,0.06311
151.442,7.78212,21113.61914,0.06324
151.642,7.79869,21110.01367,0.06337
151.842,7.81575,21113.26367,0.0635
152.042,7.83225,21112.49805,0.06363
152.242,7.84894,21106.75781,0.06376
152.442,7.86537,21107.36914,0.06389
152.642,7.88219,21111.89453,0.06403
152.842,7.89919,21107.89453,0.06416
153.042,7.91544,21107.44922,0.06429
153.242,7.93212,21105.46484,0.06442
153.442,7.949,21109.50781,0.06455
153.642,7.96556,21107.21289,0.06468
153.842,7.9825,21105.57812,0.06482
154.042,7.99869,21102.27344,0.06494
154.242,8.01569,21104.93359,0.06508
154.442,8.03225,21104.5332,0.06521
154.642,8.04856,21098.91992,0.06534
154.842,8.06587,21106.23242,0.06547
155.042,8.08225,21101.1582,0.0656
155.242,8.09881,21097.01172,0.06573
155.442,8.11556,21099.56055,0.06586
155.642,8.13206,21098.00195,0.06599
155.842,8.14919,21099.31055,0.06613
156.042,8.16562,21097.48633,0.06626
156.242,8.18194,21092.55859,0.06639
156.442,8.19912,21101.70703,0.06652
156.642,8.21562,21095.00195,0.06665
156.842,8.23225,21093.61523,0.06678
157.042,8.24887,21093.74609,0.06691
157.242,8.26556,21091.18555,0.06704
157.442,8.28225,21094.46289,0.06718
157.642,8.29869,21088.83203,0.06731
157.842,8.31569,21090.56641,0.06744
158.042,8.33231,21091.50586,0.06757
158.242,8.34887,21084.20508,0.0677
158.442,8.36544,21087.91797,0.06783
158.642,8.38219,21088.41602,0.06796
158.842,8.39906,21084.21875,0.0681
159.042,8.41562,21087.57422,0.06823
159.242,8.43206,21080.33594,0.06836
159.442,8.44894,21085.02539,0.06849
159.642,8.46569,21084.92188,0.06862
159.842,8.48244,21080.69727,0.06875
160.042,8.49875,21079.7207,0.06888
160.242,8.51569,21080.13086,0.06901
160.442,8.53212,21079.05469,0.06914
160.642,8.54862,21075.66797,0.06927
160.842,8.56587,21079.63477,0.06941
161.042,8.58212,21074.76562,0.06954
161.242,8.59894,21072.77148,0.06967
161.442,8.6155,21071.9707,0.0698
161.642,8.632,21073.08594,0.06993
161.842,8.64919,21071.875,0.07007
162.042,8.66556,21070.68359,0.07019
162.242,8.682,21066.57031,0.07032
162.442,8.69906,21071.94922,0.07046
162.642,8.7155,21066.66992,0.07059
162.842,8.73244,21067.6543,0.07072
163.042,8.74887,21064.75,0.07085
163.242,8.7655,21062.55859,0.07098
163.442,8.78231,21066.19336,0.07111
163.642,8.79862,21058.80859,0.07124
163.842,8.81575,21063.875,0.07138
164.042,8.83231,21060.5625,0.07151
164.242,8.84869,21053.07422,0.07164
164.442,8.86556,21059.21094,0.07177
164.642,8.88212,21056.69531,0.0719
164.842,8.89906,21054.14062,0.07203
165.042,8.91562,21055.87109,0.07216
165.242,8.932,21048.47656,0.07229
165.442,8.949,21055.56055,0.07243
165.642,8.96569,21051.76953,0.07256
165.842,8.98231,21047.20898,0.07269
166.042,8.99894,21049.36328,0.07282
166.242,9.01562,21044.94727,0.07295
166.442,9.03212,21046.44727,0.07308
166.642,9.04875,21043.01172,0.07321
166.842,9.06581,21044.45312,0.07335
167.042,9.08219,21043.27148,0.07348
167.242,9.09894,21037.02148,0.07361
167.442,9.11537,21037.01758,0.07374
167.642,9.13219,21040.54688,0.07387
167.842,9.14919,21036.26172,0.074
168.042,9.16544,21034.36133,0.07413
168.242,9.18212,21031.41602,0.07426
168.442,9.19906,21034.91992,0.0744
168.642,9.21556,21031.91602,0.07453
168.842,9.23237,21028.67578,0.07466
169.042,9.24869,21026.27539,0.07479
169.242,9.26569,21027.28711,0.07492
169.442,9.28225,21025.53516,0.07505
169.642,9.2985,21020.12305,0.07518
169.842,9.31587,21026.38281,0.07532
170.042,9.33225,21020.64648,0.07544
170.242,9.34881,21016.00391,0.07557
170.442,9.3655,21017.71094,0.07571
170.642,9.382,21015.57617,0.07584
170.842,9.39919,21016.20312,0.07597
171.042,9.41562,21013.52734,0.0761
171.242,9.43187,21007.21094,0.07623
171.442,9.44912,21015.39648,0.07636
171.642,9.46562,21008.35352,0.07649
171.842,9.48231,21006.08789,0.07663
172.042,9.49894,21005.5625,0.07676
172.242,9.51556,21001.12891,0.07689
172.442,9.53225,21004.16406,0.07702
172.642,9.54862,20996.71094,0.07715
172.842,9.56569,20999.70703,0.07728
173.042,9.58231,20999.00391,0.07741
173.242,9.59887,20991.14844,0.07754
173.442,9.61537,20992.5,0.07767
173.642,9.63219,20993.32422,0.07781
173.842,9.64912,20988.67969,0.07794
174.042,9.66556,20989.14453,0.07807
174.242,9.68206,20982.47461,0.0782
174.442,9.69894,20986.79883,0.07833
174.642,9.71569,20984.66016,0.07846
174.842,9.73244,20979.87695,0.0786
175.042,9.74875,20977.82812,0.07872
175.242,9.76569,20976.01953,0.07886
175.442,9.78218,20974.8418,0.07899
175.642,9.79862,20970.25977,0.07912
175.842,9.81587,20973.49023,0.07925
176.042,9.83212,20968.44531,0.07938
176.242,9.84894,20964.18945,0.07951
176.442,9.8655,20964.2168,0.07964
176.642,9.882,20962.74219,0.07977
176.842,9.89925,20961.30469,0.07991
177.042,9.91556,20958.16797,0.08004
177.242,9.932,20953.42383,0.08017
177.442,9.94912,20957.66602,0.0803
177.642,9.9655,20951.69336,0.08043
177.842,9.98244,20950.51562,0.08056
178.042,9.99887,20947.08008,0.08069
178.242,10.0155,20943.64453,0.08082
178.442,10.03231,20945.98633,0.08096
178.642,10.04862,20937.19922,0.08108
178.842,10.06581,20941.44727,0.08122
179.042,10.08231,20936.36523,0.08135
179.242,10.09875,20927.70312,0.08148
179.442,10.1155,20932.375,0.08161
179.642,10.13212,20928.95312,0.08174
179.842,10.14906,20924.97266,0.08188
180.042,10.16562,20925.67188,0.08201
180.242,10.18206,20917.96094,0.08214
180.442,10.199,20922.18945,0.08227
180.642,10.21569,20917.55078,0.0824
180.842,10.23231,20911.9043,0.08253
181.042,10.24887,20911.41406,0.08266
181.242,10.26569,20907.16797,0.08279
181.442,10.28206,20904.75781,0.08292
181.642,10.29869,20900.6582,0.08305
181.842,10.31581,20900.97266,0.08319
182.042,10.33219,20897.70898,0.08332
182.242,10.34887,20889.96094,0.08345
182.442,10.36537,20889.13672,0.08358
182.642,10.38218,20889.98633,0.08371
182.842,10.39919,20883.99609,0.08385
183.042,10.41544,20881.25977,0.08397
183.242,10.43212,20876.88672,0.0841
183.442,10.44906,20878.08984,0.08424
183.642,10.46556,20873.1875,0.08437
183.842,10.48244,20869.00195,0.0845
184.042,10.49875,20863.94336,0.08463
184.242,10.51575,20863.52344,0.08476
184.442,10.53225,20859.96289,0.08489
184.642,10.54856,20851.39062,0.08502
184.842,10.56587,20855.89844,0.08516
185.042,10.58225,20848.36133,0.08529
185.242,10.59875,20841.0957,0.08542
185.442,10.6155,20839.99219,0.08555
185.642,10.63206,20837.54492,0.08568
185.842,10.64919,20835.11914,0.08581
186.042,10.66562,20830.07617,0.08594
186.242,10.68187,20820.57617,0.08607
186.442,10.69912,20826.63281,0.08621
186.642,10.71562,20817.75586,0.08634
186.842,10.73231,20812.47266,0.08647
187.042,10.74887,20809.27734,0.0866
187.242,10.76556,20802.95898,0.08673
187.442,10.78225,20803.48047,0.08686
187.642,10.79869,20792.48242,0.08699
187.842,10.81569,20792.13867,0.08712
188.042,10.83231,20789.81836,0.08726
188.242,10.84887,20778.10156,0.08739
188.442,10.86537,20777.05859,0.08752
188.642,10.88219,20774.67969,0.08765
188.842,10.89912,20766.57812,0.08778
189.042,10.91562,20765.76367,0.08791
189.242,10.93206,20754.4668,0.08804
189.442,10.94887,20755.21289,0.08817
189.642,10.96569,20750.46875,0.08831
189.842,10.98237,20740.68555,0.08844
190.042,10.99875,20736.68555,0.08857
190.242,11.01569,20731.70898,0.0887
190.442,11.03219,20726.90625,0.08883
190.642,11.04869,20718.27148,0.08896
190.842,11.06581,20716.49219,0.08909
191.042,11.08212,20708.02539,0.08922
191.242,11.09894,20700.46289,0.08935
191.442,11.1155,20694.8418,0.08949
191.642,11.132,20690.08594,0.08962
191.842,11.14925,20684.99023,0.08975
192.042,11.16556,20677.19922,0.08988
192.242,11.182,20668.7832,0.09001
192.442,11.19906,20667.39258,0.09014
192.642,11.2155,20656.93359,0.09027
192.842,11.23244,20651.47852,0.09041
193.042,11.24887,20642.05469,0.09054
193.242,11.2655,20635.08984,0.09067
193.442,11.28231,20631.11719,0.0908
193.642,11.29862,20617.43945,0.09093
193.842,11.31581,20616.5625,0.09106
194.042,11.33231,20605.9668,0.09119
194.242,11.34869,20592.15625,0.09132
194.442,11.36556,20591.22852,0.09145
194.642,11.38219,20581.88672,0.09159
194.842,11.399,20570.73828,0.09172
195.042,11.41569,20566.39062,0.09185
195.242,11.432,20551.57812,0.09198
195.442,11.449,20550.99219,0.09211
195.642,11.46562,20539.85742,0.09224
195.842,11.48225,20527.19531,0.09237
196.042,11.49887,20521.32031,0.0925
196.242,11.51569,20508.85156,0.09264
196.442,11.53212,20501.23438,0.09277
196.642,11.54869,20489.41797,0.0929
196.842,11.56581,20483.36719,0.09303
197.042,11.58219,20472.47461,0.09316
197.242,11.59887,20456.97656,0.09329
197.442,11.61537,20448.87305,0.09342
197.642,11.63219,20442.12305,0.09355
197.842,11.64919,20427.66016,0.09369
198.042,11.66537,20416.04297,0.09382
198.242,11.68212,20405.14258,0.09395
198.442,11.699,20397.7207,0.09408
198.642,11.71556,20385.2168,0.09421
198.842,11.73244,20371.81836,0.09434
199.042,11.74875,20358.81055,0.09447
199.242,11.76569,20348.08789,0.0946
199.442,11.78225,20335.92383,0.09474
199.642,11.79856,20318.85938,0.09486
199.842,11.81587,20313.96289,0.095
200.042,11.83225,20297.05664,0.09513
200.242,11.84881,20279.88672,0.09526
200.442,11.86556,20270.43945,0.09539
200.642,11.88206,20256.81055,0.09552
200.842,11.89919,20244.2207,0.09566
201.042,11.91562,20229.25781,0.09579
201.242,11.93187,20210.31836,0.09591
201.442,11.94912,20205.63281,0.09605
201.642,11.96562,20185.80664,0.09618
201.842,11.98231,20171.10352,0.09631
202.042,11.99887,20156.28906,0.09644
202.242,12.01562,20137.92773,0.09657
202.442,12.03225,20125.7832,0.0967
202.642,12.04869,20103.41016,0.09683
202.842,12.06569,20091.42578,0.09697
203.042,12.08237,20076.47656,0.0971
203.242,12.09887,20052.38086,0.09723
203.442,12.11537,20039.13281,0.09736
203.642,12.13219,20024.80859,0.09749
203.842,12.14906,20002.57227,0.09762
204.042,12.16562,19988.44922,0.09775
204.242,12.18212,19962.60742,0.09788
204.442,12.19887,19947.90234,0.09802
204.642,12.21568,19929.76367,0.09815
204.842,12.23244,19905.87305,0.09828
205.042,12.24875,19885.55273,0.09841
205.242,12.26569,19865.53125,0.09854
205.442,12.28219,19845.45508,0.09867
205.642,12.29869,19822.92578,0.0988
205.842,12.31587,19805.26367,0.09894
206.042,12.33212,19781,0.09907
206.242,12.34894,19758.43555,0.0992
206.442,12.36556,19737.56445,0.09933
206.642,12.38206,19715.95312,0.09946
206.842,12.39919,19692.53516,0.09959
207.042,12.4155,19667.18945,0.09972
207.242,12.432,19641.20898,0.09985
207.442,12.44912,19620.16016,0.09999
207.642,12.4655,19589.29102,0.10012
207.842,12.48237,19564.57227,0.10025
208.042,12.49894,19537.62305,0.10038
208.242,12.5155,19508.64258,0.10051
208.442,12.53231,19484.92969,0.10064
208.642,12.54862,19449.98828,0.10077
208.842,12.56581,19425.8457,0.10091
209.042,12.58237,19393.5957,0.10104
209.242,12.59869,19352.83008,0.10116
209.442,12.6155,19323.54102,0.1013
209.642,12.63219,19288.9668,0.10143
209.842,12.64906,19251.08203,0.10156
210.042,12.66569,19217.45703,0.10169
210.242,12.68206,19170.04492,0.10182
210.442,12.699,19133.40039,0.10195
210.642,12.71569,19085.87305,0.10209
210.842,12.73225,19031.43945,0.10222
211.042,12.74894,18972.03711,0.10235
211.242,12.76569,18899.04883,0.10248
211.442,12.78212,18815.57227,0.10261
211.642,12.79869,18729.76367,0.10274
211.842,12.81581,18625.46875,0.10287
212.042,12.83225,18489.64258,0.103
212.242,12.84887,18304.0625,0.10313
212.442,12.86544,18071.4043,0.10326
212.642,12.88231,17684.38672,0.1034
212.842,12.89931,17164.50977,0.10353
213.042,12.91594,15674.83398,0.10366
213.242,12.93312,10045.11816,0.1038
213.364,12.94712,-84.63481,0.10391