File: ENGR270-Material Science Data Analysis/Lab4/Specimen_RawData_1 (4).csv
Time,Extension,Load,Tensile strain (Strain 1)
(s),(mm),(N),(mm/mm)
"0.00000","-1.56794","-5.96529","-0.00002"
"0.20000","-1.55206","282.84894","0.00003"
"0.40000","-1.53463","641.27869","0.00006"
"0.60000","-1.51781","918.72040","0.00008"
"0.80000","-1.50119","1142.14880","0.00009"
"1.00000","-1.48444","1329.87549","0.00010"
"1.20000","-1.46775","1501.53845","0.00010"
"1.40000","-1.45131","1651.70264","0.00010"
"1.60000","-1.43431","1795.07507","0.00010"
"1.80000","-1.41769","1924.16882","0.00010"
"2.00000","-1.40119","2035.19238","0.00009"
"2.20000","-1.38456","2142.25195","0.00007"
"2.40000","-1.36788","2239.88892","0.00007"
"2.60000","-1.35088","2329.91797","0.00005"
"2.80000","-1.33431","2414.58081","0.00004"
"3.00000","-1.31800","2490.03369","0.00003"
"3.20000","-1.30094","2573.24292","0.00001"
"3.40000","-1.28450","2656.40332","0.00000"
"3.60000","-1.26769","2749.63184","-0.00001"
"3.80000","-1.25119","2852.48486","-0.00001"
"4.00000","-1.23444","2962.30737","-0.00001"
"4.20000","-1.21775","3081.85718","-0.00001"
"4.40000","-1.20131","3193.75146","0.00000"
"4.60000","-1.18425","3308.44336","0.00002"
"4.80000","-1.16769","3422.50439","0.00003"
"5.00000","-1.15125","3531.96387","0.00005"
"5.20000","-1.13456","3650.32886","0.00006"
"5.40000","-1.11788","3767.54102","0.00008"
"5.60000","-1.10094","3883.99390","0.00010"
"5.80000","-1.08438","4003.93018","0.00011"
"6.00000","-1.06800","4118.60303","0.00013"
"6.20000","-1.05100","4243.06055","0.00015"
"6.40000","-1.03444","4362.91016","0.00016"
"6.60000","-1.01775","4481.59375","0.00018"
"6.80000","-1.00119","4605.20459","0.00019"
"7.00000","-0.98444","4728.92480","0.00021"
"7.20000","-0.96781","4855.41943","0.00023"
"7.40000","-0.95131","4979.41650","0.00025"
"7.60000","-0.93425","5108.79932","0.00027"
"7.80000","-0.91775","5237.23193","0.00029"
"8.00000","-0.90119","5363.76953","0.00030"
"8.20000","-0.88462","5494.64355","0.00032"
"8.40000","-0.86787","5628.78809","0.00034"
"8.60000","-0.85087","5758.49414","0.00036"
"8.80000","-0.83450","5891.67773","0.00038"
"9.00000","-0.81794","6022.09375","0.00039"
"9.20000","-0.80094","6161.27344","0.00042"
"9.40000","-0.78444","6293.68359","0.00043"
"9.60000","-0.76769","6428.19727","0.00045"
"9.80000","-0.75125","6562.72754","0.00047"
"10.00000","-0.73438","6701.15430","0.00049"
"10.20000","-0.71775","6841.08936","0.00051"
"10.40000","-0.70138","6974.89893","0.00053"
"10.60000","-0.68425","7118.17969","0.00056"
"10.80000","-0.66775","7258.11279","0.00057"
"11.00000","-0.65125","7392.96875","0.00059"
"11.20000","-0.63456","7534.87646","0.00062"
"11.40000","-0.61794","7674.25830","0.00064"
"11.60000","-0.60088","7812.88086","0.00065"
"11.80000","-0.58438","7952.90527","0.00067"
"12.00000","-0.56806","8086.58545","0.00069"
"12.20000","-0.55088","8233.91016","0.00071"
"12.40000","-0.53444","8369.78516","0.00073"
"12.60000","-0.51781","8506.57812","0.00075"
"12.80000","-0.50119","8647.21973","0.00076"
"13.00000","-0.48444","8785.73535","0.00079"
"13.20000","-0.46775","8929.38574","0.00081"
"13.40000","-0.45131","9066.20703","0.00083"
"13.60000","-0.43431","9208.03223","0.00084"
"13.80000","-0.41769","9352.91309","0.00086"
"14.00000","-0.40113","9490.10449","0.00089"
"14.20000","-0.38463","9632.84180","0.00091"
"14.40000","-0.36788","9778.20508","0.00093"
"14.60000","-0.35088","9918.04199","0.00096"
"14.80000","-0.33444","10062.85742","0.00097"
"15.00000","-0.31800","10200.89746","0.00100"
"15.20000","-0.30106","10350.52441","0.00102"
"15.40000","-0.28438","10494.91992","0.00104"
"15.60000","-0.26769","10636.43066","0.00106"
"15.80000","-0.25125","10780.05762","0.00108"
"16.00000","-0.23438","10927.20508","0.00111"
"16.20000","-0.21775","11074.59180","0.00113"
"16.40000","-0.20138","11216.63965","0.00115"
"16.60000","-0.18419","11367.99512","0.00118"
"16.80000","-0.16781","11514.70020","0.00120"
"17.00000","-0.15119","11660.33496","0.00122"
"17.20000","-0.13456","11809.51270","0.00124"
"17.40000","-0.11800","11958.93848","0.00127"
"17.60000","-0.10088","12108.85449","0.00129"
"17.80000","-0.08444","12258.18359","0.00132"
"18.00000","-0.06800","12403.25000","0.00134"
"18.20000","-0.05094","12561.42285","0.00136"
"18.40000","-0.03450","12708.47070","0.00139"
"18.60000","-0.01769","12859.33691","0.00141"
"18.80000","-0.00113","13010.89355","0.00143"
"19.00000","0.01550","13161.60547","0.00146"
"19.20000","0.03219","13318.64453","0.00149"
"19.40000","0.04862","13467.06641","0.00151"
"19.60000","0.06575","13622.96484","0.00154"
"19.80000","0.08225","13776.92969","0.00157"
"20.00000","0.09875","13925.07129","0.00159"
"20.20000","0.11550","14082.16504","0.00162"
"20.40000","0.13206","14236.68555","0.00165"
"20.60000","0.14900","14389.68457","0.00168"
"20.80000","0.16562","14546.39551","0.00170"
"21.00000","0.18206","14695.95020","0.00173"
"21.20000","0.19900","14857.30664","0.00176"
"21.40000","0.21556","15011.30566","0.00178"
"21.60000","0.23225","15163.86230","0.00181"
"21.80000","0.24881","15319.98535","0.00184"
"22.00000","0.26569","15475.67285","0.00186"
"22.20000","0.28212","15631.59082","0.00190"
"22.40000","0.29869","15785.08887","0.00192"
"22.60000","0.31575","15942.43750","0.00196"
"22.80000","0.33219","16098.11035","0.00199"
"23.00000","0.34881","16249.94141","0.00202"
"23.20000","0.36537","16405.84375","0.00204"
"23.40000","0.38212","16563.74414","0.00208"
"23.60000","0.39919","16717.66992","0.00211"
"23.80000","0.41550","16871.39453","0.00214"
"24.00000","0.43206","17021.85352","0.00217"
"24.20000","0.44906","17182.37305","0.00221"
"24.40000","0.46550","17332.91602","0.00224"
"24.60000","0.48231","17484.80273","0.00227"
"24.80000","0.49875","17634.95898","0.00231"
"25.00000","0.51562","17787.68164","0.00235"
"25.20000","0.53225","17939.99414","0.00238"
"25.40000","0.54850","18081.94141","0.00242"
"25.60000","0.56581","18235.64258","0.00246"
"25.80000","0.58225","18379.91406","0.00250"
"26.00000","0.59875","18518.19531","0.00254"
"26.20000","0.61550","18663.29883","0.00258"
"26.40000","0.63200","18802.96094","0.00263"
"26.60000","0.64912","18941.29297","0.00268"
"26.80000","0.66562","19076.34375","0.00273"
"27.00000","0.68194","19201.04688","0.00278"
"27.20000","0.69906","19338.63672","0.00284"
"27.40000","0.71562","19460.07812","0.00289"
"27.60000","0.73225","19577.69336","0.00295"
"27.80000","0.74881","19693.01758","0.00301"
"28.00000","0.76556","19802.83203","0.00308"
"28.20000","0.78219","19908.89648","0.00315"
"28.40000","0.79869","20001.35938","0.00323"
"28.60000","0.81562","20092.28711","0.00331"
"28.80000","0.83231","20173.97656","0.00340"
"29.00000","0.84887","20236.48047","0.00351"
"29.20000","0.86537","20299.57422","0.00361"
"29.40000","0.88219","20349.99023","0.00373"
"29.60000","0.89912","20386.75391","0.00386"
"29.80000","0.91562","20419.60742","0.00399"
"30.00000","0.93206","20437.11719","0.00414"
"30.20000","0.94894","20461.16797","0.00429"
"30.40000","0.96569","20473.27539","0.00444"
"30.60000","0.98237","20480.40234","0.00460"
"30.80000","0.99875","20487.97461","0.00476"
"31.00000","1.01575","20493.73633","0.00493"
"31.20000","1.03219","20498.17969","0.00510"
"31.40000","1.04862","20498.25195","0.00528"
"31.60000","1.06581","20505.48242","0.00546"
"31.80000","1.08212","20503.89062","0.00564"
"32.00000","1.09894","20504.31055","0.00582"
"32.20000","1.11550","20507.48242","0.00601"
"32.40000","1.13200","20509.53711","0.00620"
"32.60000","1.14925","20512.26758","0.00638"
"32.80000","1.16556","20512.95898","0.00658"
"33.00000","1.18200","20513.03320","0.00676"
"33.20000","1.19912","20521.75195","0.00696"
"33.40000","1.21550","20518.76172","0.00715"
"33.60000","1.23237","20523.35742","0.00734"
"33.80000","1.24887","20524.45508","0.00753"
"34.00000","1.26556","20526.77148","0.00773"
"34.20000","1.28225","20533.61914","0.00793"
"34.40000","1.29862","20530.37500","0.00812"
"34.60000","1.31581","20541.01172","0.00831"
"34.80000","1.33231","20541.06836","0.00851"
"35.00000","1.34875","20539.19727","0.00870"
"35.20000","1.36550","20548.29688","0.00890"
"35.40000","1.38219","20551.35742","0.00909"
"35.60000","1.39906","20553.94727","0.00930"
"35.80000","1.41562","20559.74414","0.00949"
"36.00000","1.43206","20558.39844","0.00970"
"36.20000","1.44900","20570.04297","0.00989"
"36.40000","1.46569","20571.74219","0.01010"
"36.60000","1.48225","20572.55273","0.01029"
"36.80000","1.49881","20578.72461","0.01049"
"37.00000","1.51575","20581.89258","0.01069"
"37.20000","1.53206","20586.05664","0.01089"
"37.40000","1.54875","20588.39062","0.01109"
"37.60000","1.56581","20595.63477","0.01128"
"37.80000","1.58225","20599.70703","0.01148"
"38.00000","1.59894","20598.85938","0.01169"
"38.20000","1.61537","20604.96289","0.01188"
"38.40000","1.63219","20612.88672","0.01208"
"38.60000","1.64925","20614.63477","0.01228"
"38.80000","1.66544","20618.11133","0.01248"
"39.00000","1.68212","20621.24023","0.01268"
"39.20000","1.69906","20629.65039","0.01288"
"39.40000","1.71556","20632.07422","0.01308"
"39.60000","1.73237","20634.59375","0.01328"
"39.80000","1.74875","20637.31445","0.01348"
"40.00000","1.76569","20643.46289","0.01369"
"40.20000","1.78225","20648.29492","0.01388"
"40.40000","1.79856","20646.92578","0.01408"
"40.60000","1.81587","20659.51953","0.01428"
"40.80000","1.83225","20658.70898","0.01449"
"41.00000","1.84881","20659.37891","0.01469"
"41.20000","1.86556","20666.77734","0.01489"
"41.40000","1.88200","20669.85938","0.01509"
"41.60000","1.89919","20675.78125","0.01529"
"41.80000","1.91562","20679.07227","0.01549"
"42.00000","1.93187","20677.72852","0.01569"
"42.20000","1.94912","20691.71680","0.01590"
"42.40000","1.96562","20690.86328","0.01609"
"42.60000","1.98231","20693.93359","0.01629"
"42.80000","1.99887","20697.46680","0.01649"
"43.00000","2.01556","20700.24219","0.01669"
"43.20000","2.03225","20708.55859","0.01690"
"43.40000","2.04869","20706.36719","0.01710"
"43.60000","2.06569","20714.10742","0.01730"
"43.80000","2.08231","20719.39258","0.01750"
"44.00000","2.09887","20715.82227","0.01770"
"44.20000","2.11537","20723.42773","0.01790"
"44.40000","2.13219","20729.28516","0.01810"
"44.60000","2.14912","20729.89258","0.01830"
"44.80000","2.16562","20736.91992","0.01850"
"45.00000","2.18206","20735.11719","0.01870"
"45.20000","2.19894","20744.16797","0.01890"
"45.40000","2.21569","20748.95117","0.01910"
"45.60000","2.23237","20747.91992","0.01930"
"45.80000","2.24869","20752.07422","0.01950"
"46.00000","2.26575","20756.62891","0.01970"
"46.20000","2.28219","20760.01953","0.01990"
"46.30400","2.29100","20760.61523","0.02000"
"46.40600","2.29619","20741.82227","0.02004"
"46.60600","2.29575","20564.49023","0.02004"
"46.80600","2.29487","20466.91406","0.02003"
"47.00600","2.29444","20404.83789","0.02003"
"47.20600","2.29431","20361.83984","0.02003"
"47.40600","2.29425","20328.41211","0.02003"
"47.60600","2.29425","20301.07812","0.02003"
"47.80600","2.29425","20277.41016","0.02003"
"48.00600","2.29425","20256.60938","0.02003"
"48.20600","2.29425","20238.46875","0.02003"
"48.40600","2.29419","20221.87500","0.02003"
"48.60600","2.29419","20207.01562","0.02003"
"48.80600","2.29419","20193.54492","0.02003"
"49.00600","2.29419","20181.04102","0.02003"
"49.20600","2.29419","20169.42578","0.02003"
"49.40600","2.29419","20158.49609","0.02003"
"49.60600","2.29419","20148.65234","0.02003"
"49.80600","2.29419","20139.05273","0.02003"
"50.00600","2.29419","20130.22852","0.02003"
"50.20600","2.29419","20121.88672","0.02003"
"50.40600","2.29419","20113.74219","0.02003"
"50.60600","2.29419","20106.23438","0.02003"
"50.80600","2.29419","20099.14844","0.02003"
"51.00600","2.29419","20092.16992","0.02003"
"51.20600","2.29419","20085.61133","0.02003"
"51.40600","2.29419","20079.43945","0.02003"
"51.60600","2.29419","20073.54297","0.02003"
"51.80600","2.29419","20067.58984","0.02003"
"52.00600","2.29419","20061.91016","0.02003"
"52.20600","2.29419","20056.91797","0.02003"
"52.40600","2.29419","20051.74023","0.02003"
"52.60600","2.29419","20046.70117","0.02003"
"52.80600","2.29419","20041.88672","0.02003"
"53.00600","2.29419","20037.19141","0.02003"
"53.20600","2.29419","20032.53906","0.02003"
"53.40600","2.29419","20028.31641","0.02003"
"53.60600","2.29419","20023.96680","0.02003"
"53.80600","2.29419","20019.85742","0.02003"
"54.00600","2.29419","20015.86719","0.02003"
"54.20600","2.29419","20012.06250","0.02003"
"54.40600","2.29419","20008.17383","0.02003"
"54.60600","2.29419","20004.88867","0.02003"
"54.80600","2.29419","20000.98242","0.02003"
"55.00600","2.29419","19997.70117","0.02003"
"55.20600","2.29419","19994.12891","0.02003"
"55.40600","2.29419","19990.85352","0.02003"
"55.60600","2.29419","19987.72266","0.02003"
"55.80600","2.29419","19984.40039","0.02003"
"56.00600","2.29419","19981.31055","0.02003"
"56.20600","2.29419","19978.45703","0.02003"
"56.40600","2.29419","19975.21875","0.02003"
"56.60600","2.29419","19972.36523","0.02003"
"56.80600","2.29419","19969.57031","0.02003"
"57.00600","2.29419","19966.85742","0.02003"
"57.20600","2.29419","19964.10547","0.02003"
"57.40600","2.29419","19961.49805","0.02003"
"57.60600","2.29419","19958.82422","0.02003"
"57.80600","2.29419","19956.04102","0.02003"
"58.00600","2.29419","19953.90625","0.02003"
"58.20600","2.29419","19951.37500","0.02003"
"58.40600","2.29419","19948.82617","0.02003"
"58.60600","2.29419","19946.69531","0.02003"
"58.80600","2.29419","19944.33203","0.02003"
"59.00600","2.29419","19942.00391","0.02003"
"59.20600","2.29419","19939.68750","0.02003"
"59.40600","2.29419","19937.43945","0.02003"
"59.60600","2.29419","19935.27344","0.02003"
"59.80600","2.29419","19933.11328","0.02003"
"60.00600","2.29419","19931.06641","0.02003"
"60.20600","2.29419","19929.10938","0.02003"
"60.40600","2.29419","19927.09375","0.02003"
"60.60600","2.29419","19925.23438","0.02003"
"60.80600","2.29419","19923.66211","0.02003"
"61.00600","2.29419","19922.38867","0.02003"
"61.20600","2.29419","19920.34766","0.02003"
"61.40600","2.29419","19917.37305","0.02003"
"61.60600","2.29419","19915.46875","0.02003"
"61.80600","2.29419","19913.71289","0.02003"
"62.00600","2.29419","19911.76367","0.02003"
"62.20600","2.29419","19910.15430","0.02003"
"62.40600","2.29419","19908.23828","0.02003"
"62.60600","2.29419","19906.74219","0.02003"
"62.80600","2.29419","19905.17578","0.02003"
"63.00600","2.29419","19903.15430","0.02003"
"63.20600","2.29419","19901.58203","0.02003"
"63.40600","2.29419","19899.94141","0.02003"
"63.60600","2.29419","19898.50195","0.02003"
"63.80600","2.29419","19896.87500","0.02003"
"64.00600","2.29419","19895.41016","0.02003"
"64.20600","2.29419","19893.59375","0.02003"
"64.40600","2.29419","19892.34375","0.02003"
"64.60600","2.29419","19890.85742","0.02003"
"64.80600","2.29419","19889.16016","0.02003"
"65.00600","2.29419","19887.82031","0.02003"
"65.20600","2.29419","19886.12305","0.02003"
"65.40600","2.29419","19884.85938","0.02003"
"65.60600","2.29419","19883.39062","0.02003"
"65.80600","2.29419","19882.02539","0.02003"
"66.00600","2.29419","19880.78516","0.02003"
"66.20600","2.29419","19879.45508","0.02003"
"66.40600","2.29419","19878.12500","0.02003"
"66.60600","2.29419","19876.70898","0.02003"
"66.80600","2.29419","19875.27930","0.02003"
"67.00600","2.29419","19873.93555","0.02003"
"67.20600","2.29419","19872.74414","0.02003"
"67.40600","2.29419","19871.17578","0.02003"
"67.60600","2.29419","19869.98242","0.02003"
"67.80600","2.29419","19869.00781","0.02003"
"68.00600","2.29419","19867.66602","0.02003"
"68.20600","2.29419","19866.41797","0.02003"
"68.40600","2.29419","19865.15625","0.02003"
"68.60600","2.29419","19864.25391","0.02003"
"68.80600","2.29419","19862.86719","0.02003"
"69.00600","2.29419","19861.50586","0.02003"
"69.20600","2.29419","19860.47070","0.02003"
"69.40600","2.29419","19859.47070","0.02003"
"69.60600","2.29419","19858.22266","0.02003"
"69.80600","2.29419","19857.14062","0.02003"
"70.00600","2.29419","19856.02930","0.02003"
"70.20600","2.29419","19854.78906","0.02003"
"70.40600","2.29419","19853.57031","0.02003"
"70.60600","2.29419","19852.82227","0.02003"
"70.80600","2.29419","19851.55859","0.02003"
"71.00600","2.29419","19850.81250","0.02003"
"71.20600","2.29419","19849.40820","0.02003"
"71.40600","2.29419","19848.02539","0.02003"
"71.60600","2.29419","19846.88867","0.02003"
"71.80600","2.29419","19846.05469","0.02003"
"72.00600","2.29419","19844.89648","0.02003"
"72.20600","2.29419","19843.98633","0.02003"
"72.40600","2.29419","19842.47070","0.02003"
"72.60600","2.29419","19841.28906","0.02003"
"72.80600","2.29419","19840.06055","0.02003"
"73.00600","2.29419","19838.79883","0.02003"
"73.20600","2.29419","19837.81250","0.02003"
"73.40600","2.29419","19836.94531","0.02003"
"73.60600","2.29419","19835.91992","0.02003"
"73.80600","2.29419","19834.91406","0.02003"
"74.00600","2.29419","19833.73438","0.02003"
"74.20600","2.29419","19832.70703","0.02003"
"74.40600","2.29419","19832.21094","0.02003"
"74.60600","2.29419","19831.11133","0.02003"
"74.80600","2.29419","19830.20117","0.02003"
"75.00600","2.29419","19829.17969","0.02003"
"75.20600","2.29419","19828.47852","0.02003"
"75.40600","2.29419","19827.41406","0.02003"
"75.60600","2.29419","19826.44727","0.02003"
"75.80600","2.29419","19825.68555","0.02003"
"76.00600","2.29419","19824.73633","0.02003"
"76.20600","2.29419","19823.88867","0.02003"
"76.40600","2.29419","19822.97070","0.02003"
"76.60600","2.29419","19822.33398","0.02003"
"76.80600","2.29419","19821.50391","0.02003"
"77.00600","2.29419","19820.48828","0.02003"
"77.20600","2.29419","19819.46289","0.02003"
"77.40600","2.29419","19818.89062","0.02003"
"77.60600","2.29419","19817.84961","0.02003"
"77.80600","2.29419","19817.14258","0.02003"
"78.00600","2.29419","19816.25000","0.02003"
"78.20600","2.29419","19815.47852","0.02003"
"78.40600","2.29419","19814.57227","0.02003"
"78.60600","2.29419","19813.91211","0.02003"
"78.80600","2.29419","19813.37695","0.02003"
"79.00600","2.29419","19812.24023","0.02003"
"79.20600","2.29419","19811.81055","0.02003"
"79.40600","2.29419","19810.99805","0.02003"
"79.60600","2.29419","19810.27148","0.02003"
"79.80600","2.29419","19809.62695","0.02003"
"80.00600","2.29419","19808.98438","0.02003"
"80.20600","2.29419","19808.40430","0.02003"
"80.40600","2.29419","19807.72070","0.02003"
"80.60600","2.29419","19806.53711","0.02003"
"80.80600","2.29419","19805.90234","0.02003"
"81.00600","2.29419","19805.23633","0.02003"
"81.20600","2.29419","19804.38867","0.02003"
"81.40600","2.29419","19803.71289","0.02003"
"81.60600","2.29419","19802.87500","0.02003"
"81.80600","2.29419","19802.22070","0.02003"
"82.00600","2.29419","19801.56250","0.02003"
"82.20600","2.29419","19800.75000","0.02003"
"82.40600","2.29419","19800.24805","0.02003"
"82.60600","2.29419","19799.39844","0.02003"
"82.80600","2.29419","19798.87305","0.02003"
"83.00600","2.29419","19797.98438","0.02003"
"83.20600","2.29419","19797.41211","0.02003"
"83.40600","2.29419","19796.57031","0.02003"
"83.60600","2.29419","19796.06250","0.02003"
"83.80600","2.29419","19795.41602","0.02003"
"84.00600","2.29419","19794.84766","0.02003"
"84.20600","2.29419","19794.00586","0.02003"
"84.40600","2.29419","19793.39258","0.02003"
"84.60600","2.29419","19792.90430","0.02003"
"84.80600","2.29419","19792.11133","0.02003"
"85.00600","2.29419","19791.58594","0.02003"
"85.20600","2.29419","19790.91992","0.02003"
"85.40600","2.29419","19790.30469","0.02003"
"85.54000","2.29419","19789.89648","0.02003"
"85.64200","2.29481","19790.37109","0.02003"
"85.84200","2.31512","20168.27734","0.02019"
"86.04200","2.33200","20463.02539","0.02032"
"86.24200","2.34887","20641.50195","0.02046"
"86.44200","2.36550","20739.63281","0.02059"
"86.64200","2.38200","20784.46680","0.02072"
"86.84200","2.39925","20804.33008","0.02085"
"87.04200","2.41556","20812.41602","0.02098"
"87.24200","2.43206","20813.13477","0.02111"
"87.44200","2.44912","20821.15820","0.02125"
"87.64200","2.46550","20817.55078","0.02138"
"87.84200","2.48250","20821.36133","0.02151"
"88.04200","2.49881","20818.41602","0.02164"
"88.24200","2.51550","20820.22852","0.02177"
"88.44200","2.53231","20825.81250","0.02190"
"88.64200","2.54862","20821.12305","0.02203"
"88.84200","2.56581","20830.28320","0.02217"
"89.04200","2.58225","20828.71094","0.02229"
"89.24200","2.59875","20826.03516","0.02242"
"89.44200","2.61556","20834.40820","0.02256"
"89.64200","2.63212","20835.28906","0.02269"
"89.84200","2.64906","20836.75781","0.02282"
"90.04200","2.66562","20842.46094","0.02295"
"90.24200","2.68200","20838.84961","0.02308"
"90.44200","2.69906","20850.21484","0.02321"
"90.64200","2.71569","20849.23633","0.02335"
"90.84200","2.73225","20849.38672","0.02348"
"91.04200","2.74887","20855.29883","0.02361"
"91.24200","2.76569","20855.59570","0.02374"
"91.44200","2.78212","20859.99414","0.02387"
"91.64200","2.79875","20860.82617","0.02400"
"91.84200","2.81575","20866.18164","0.02413"
"92.04200","2.83225","20868.96094","0.02426"
"92.24200","2.84894","20866.27930","0.02439"
"92.44200","2.86537","20870.98633","0.02452"
"92.64200","2.88219","20877.83594","0.02466"
"92.84200","2.89925","20877.44922","0.02479"
"93.04200","2.91544","20880.43359","0.02492"
"93.24200","2.93212","20882.04492","0.02505"
"93.44200","2.94900","20889.86719","0.02518"
"93.64200","2.96556","20889.89648","0.02531"
"93.84200","2.98250","20892.28125","0.02545"
"94.04200","2.99875","20892.27930","0.02557"
"94.24200","3.01575","20898.45898","0.02571"
"94.44200","3.03219","20899.87305","0.02584"
"94.64200","3.04856","20898.55469","0.02597"
"94.84200","3.06587","20908.87500","0.02610"
"95.04200","3.08225","20906.80078","0.02623"
"95.24200","3.09881","20906.25391","0.02636"
"95.44200","3.11556","20912.53320","0.02649"
"95.64200","3.13206","20914.01758","0.02662"
"95.84200","3.14919","20918.43750","0.02676"
"96.04200","3.16562","20920.10742","0.02689"
"96.24200","3.18187","20916.67188","0.02702"
"96.44200","3.19912","20930.13281","0.02715"
"96.64200","3.21562","20927.47266","0.02728"
"96.84200","3.23231","20928.00977","0.02741"
"97.04200","3.24881","20931.35352","0.02754"
"97.24200","3.26556","20932.66602","0.02767"
"97.44200","3.28225","20939.29297","0.02781"
"97.64200","3.29869","20935.55859","0.02794"
"97.84200","3.31562","20941.08008","0.02807"
"98.04200","3.33231","20945.61523","0.02820"
"98.24200","3.34887","20941.00000","0.02833"
"98.44200","3.36544","20947.14844","0.02846"
"98.64200","3.38219","20951.79102","0.02859"
"98.84200","3.39912","20950.60938","0.02873"
"99.04200","3.41569","20957.32617","0.02886"
"99.24200","3.43212","20953.40430","0.02899"
"99.44200","3.44894","20960.71680","0.02912"
"99.64200","3.46569","20963.71289","0.02925"
"99.84200","3.48237","20962.17773","0.02938"
"100.04200","3.49875","20964.30273","0.02951"
"100.24200","3.51575","20967.37695","0.02964"
"100.44200","3.53219","20969.80078","0.02977"
"100.64200","3.54869","20969.56836","0.02990"
"100.84200","3.56581","20975.65039","0.03004"
"101.04200","3.58206","20974.08594","0.03017"
"101.24200","3.59894","20976.04492","0.03030"
"101.44200","3.61550","20978.33984","0.03043"
"101.64200","3.63200","20981.43945","0.03056"
"101.84200","3.64925","20985.18555","0.03070"
"102.04200","3.66550","20984.66016","0.03082"
"102.24200","3.68200","20984.32812","0.03095"
"102.44200","3.69912","20992.90430","0.03109"
"102.64200","3.71550","20989.82422","0.03122"
"102.84200","3.73244","20994.13672","0.03135"
"103.04200","3.74887","20994.05273","0.03148"
"103.24200","3.76550","20995.15234","0.03161"
"103.44200","3.78231","21001.42383","0.03174"
"103.64200","3.79862","20996.28906","0.03187"
"103.84200","3.81581","21005.26758","0.03201"
"104.04200","3.83231","21004.83008","0.03214"
"104.24200","3.84869","21000.16406","0.03227"
"104.44200","3.86556","21009.31445","0.03240"
"104.64200","3.88212","21009.24414","0.03253"
"104.84200","3.89900","21009.25977","0.03266"
"105.04200","3.91569","21014.78711","0.03279"
"105.24200","3.93200","21010.33398","0.03292"
"105.44200","3.94906","21020.52539","0.03306"
"105.64200","3.96562","21018.78711","0.03319"
"105.84200","3.98225","21017.66016","0.03332"
"106.04200","3.99887","21021.85547","0.03345"
"106.24200","4.01569","21021.62305","0.03358"
"106.44200","4.03212","21024.31445","0.03371"
"106.64200","4.04875","21023.91211","0.03384"
"106.84200","4.06581","21028.78516","0.03398"
"107.04200","4.08219","21029.68164","0.03410"
"107.24200","4.09887","21027.14453","0.03424"
"107.44200","4.11537","21029.97070","0.03437"
"107.64200","4.13219","21035.50586","0.03450"
"107.84200","4.14925","21035.02344","0.03463"
"108.04200","4.16544","21035.36133","0.03476"
"108.24200","4.18212","21036.07227","0.03489"
"108.44200","4.19906","21042.69922","0.03503"
"108.64200","4.21556","21042.19141","0.03516"
"108.84200","4.23244","21042.73047","0.03529"
"109.04200","4.24875","21041.77148","0.03542"
"109.24200","4.26569","21046.06836","0.03555"
"109.44200","4.28225","21047.60352","0.03568"
"109.64200","4.29856","21043.14453","0.03581"
"109.84200","4.31587","21053.31641","0.03595"
"110.04200","4.33225","21050.62695","0.03607"
"110.24200","4.34881","21048.73242","0.03620"
"110.44200","4.36550","21053.10156","0.03634"
"110.64200","4.38206","21053.85547","0.03647"
"110.84200","4.39919","21056.77930","0.03660"
"111.04200","4.41569","21058.38867","0.03673"
"111.24200","4.43194","21053.65625","0.03686"
"111.44200","4.44912","21064.78320","0.03699"
"111.64200","4.46562","21061.87695","0.03712"
"111.84200","4.48231","21061.98438","0.03726"
"112.04200","4.49894","21064.59180","0.03739"
"112.24200","4.51562","21063.26367","0.03752"
"112.44200","4.53219","21068.10156","0.03765"
"112.64200","4.54869","21064.22852","0.03778"
"112.84200","4.56569","21069.33789","0.03791"
"113.04200","4.58231","21071.07422","0.03804"
"113.24200","4.59887","21065.97461","0.03817"
"113.44200","4.61544","21071.07422","0.03830"
"113.64200","4.63219","21073.93945","0.03844"
"113.84200","4.64906","21072.49805","0.03857"
"114.04200","4.66562","21077.32227","0.03870"
"114.24200","4.68206","21072.57617","0.03883"
"114.44200","4.69894","21079.79492","0.03896"
"114.64200","4.71569","21080.75195","0.03909"
"114.84200","4.73237","21078.67773","0.03922"
"115.04200","4.74869","21079.38086","0.03935"
"115.24200","4.76575","21081.94141","0.03949"
"115.44200","4.78219","21083.60156","0.03962"
"115.64200","4.79862","21081.34375","0.03975"
"115.84200","4.81587","21087.37695","0.03988"
"116.04200","4.83212","21084.32422","0.04001"
"116.24200","4.84887","21083.95898","0.04014"
"116.44200","4.86550","21087.20703","0.04027"
"116.64200","4.88206","21088.36523","0.04040"
"116.84200","4.89919","21089.64844","0.04054"
"117.04200","4.91556","21090.73633","0.04067"
"117.24200","4.93200","21089.30078","0.04080"
"117.44200","4.94912","21095.86328","0.04093"
"117.64200","4.96550","21092.26367","0.04106"
"117.84200","4.98244","21094.71680","0.04119"
"118.04200","4.99887","21093.62305","0.04132"
"118.24200","5.01556","21094.22656","0.04145"
"118.44200","5.03231","21099.85938","0.04159"
"118.64200","5.04862","21093.64844","0.04171"
"118.84200","5.06581","21101.71094","0.04185"
"119.04200","5.08231","21099.77734","0.04198"
"119.24200","5.09875","21094.72070","0.04211"
"119.44200","5.11550","21101.73047","0.04224"
"119.64200","5.13219","21101.92969","0.04237"
"119.84200","5.14906","21100.95117","0.04251"
"120.04200","5.16569","21105.44922","0.04264"
"120.24200","5.18206","21099.58008","0.04277"
"120.44200","5.19900","21108.38672","0.04290"
"120.64200","5.21569","21106.43164","0.04303"
"120.84200","5.23231","21104.42773","0.04316"
"121.04200","5.24887","21107.61328","0.04329"
"121.24200","5.26575","21106.90234","0.04342"
"121.44200","5.28212","21108.66797","0.04355"
"121.64200","5.29875","21107.20508","0.04368"
"121.84200","5.31581","21111.71680","0.04382"
"122.04200","5.33219","21111.63086","0.04395"
"122.24200","5.34887","21107.42969","0.04408"
"122.44200","5.36537","21109.92188","0.04421"
"122.64200","5.38219","21114.01953","0.04434"
"122.84200","5.39925","21112.63477","0.04448"
"123.04200","5.41550","21112.93750","0.04460"
"123.24200","5.43206","21111.35742","0.04473"
"123.44200","5.44906","21118.23047","0.04487"
"123.64200","5.46556","21116.06836","0.04500"
"123.84200","5.48244","21116.64062","0.04513"
"124.04200","5.49875","21114.76562","0.04526"
"124.24200","5.51569","21117.53516","0.04539"
"124.44200","5.53231","21119.37695","0.04552"
"124.64200","5.54850","21113.47266","0.04565"
"124.84200","5.56587","21122.94531","0.04579"
"125.04200","5.58225","21119.28320","0.04592"
"125.24200","5.59875","21115.62109","0.04605"
"125.44200","5.61550","21119.85938","0.04618"
"125.64200","5.63206","21119.75781","0.04631"
"125.84200","5.64919","21122.00781","0.04644"
"126.04200","5.66569","21122.32812","0.04657"
"126.24200","5.68187","21117.60156","0.04670"
"126.44200","5.69906","21126.98047","0.04684"
"126.64200","5.71562","21123.49219","0.04697"
"126.84200","5.73225","21121.66797","0.04710"
"127.04200","5.74887","21123.93359","0.04723"
"127.24200","5.76562","21122.63086","0.04736"
"127.44200","5.78225","21127.76953","0.04749"
"127.64200","5.79875","21122.27930","0.04762"
"127.84200","5.81569","21126.31641","0.04775"
"128.04200","5.83225","21127.95508","0.04788"
"128.24200","5.84894","21122.20898","0.04802"
"128.44200","5.86537","21125.84180","0.04815"
"128.64200","5.88219","21128.35547","0.04828"
"128.84200","5.89912","21125.62891","0.04841"
"129.04200","5.91562","21129.43945","0.04854"
"129.24200","5.93206","21124.03906","0.04867"
"129.44200","5.94894","21130.46484","0.04880"
"129.64200","5.96562","21130.10352","0.04894"
"129.84200","5.98237","21127.94922","0.04907"
"130.04200","5.99875","21128.02344","0.04920"
"130.24200","6.01575","21129.31445","0.04933"
"130.44200","6.03219","21129.75781","0.04946"
"130.64200","6.04862","21127.61523","0.04959"
"130.84200","6.06581","21132.18750","0.04972"
"131.04200","6.08212","21129.68555","0.04985"
"131.24200","6.09894","21128.31445","0.04998"
"131.44200","6.11550","21129.35938","0.05012"
"131.64200","6.13200","21130.93945","0.05025"
"131.84200","6.14919","21131.89844","0.05038"
"132.04200","6.16556","21131.22070","0.05051"
"132.24200","6.18200","21128.94922","0.05064"
"132.44200","6.19912","21135.76758","0.05077"
"132.64200","6.21556","21131.84570","0.05090"
"132.84200","6.23244","21133.06055","0.05104"
"133.04200","6.24887","21131.55273","0.05117"
"133.24200","6.26550","21130.87891","0.05130"
"133.44200","6.28225","21135.33984","0.05143"
"133.64200","6.29862","21127.81836","0.05156"
"133.84200","6.31581","21135.99219","0.05169"
"134.04200","6.33231","21133.82227","0.05182"
"134.24200","6.34869","21127.09961","0.05195"
"134.44200","6.36550","21134.22266","0.05208"
"134.64200","6.38219","21133.42188","0.05222"
"134.84200","6.39906","21132.28516","0.05235"
"135.04200","6.41562","21135.32812","0.05248"
"135.24200","6.43200","21128.86133","0.05261"
"135.44200","6.44906","21138.16602","0.05274"
"135.64200","6.46569","21134.65039","0.05287"
"135.84200","6.48225","21131.48633","0.05300"
"136.04200","6.49887","21134.83008","0.05313"
"136.24200","6.51569","21132.46094","0.05327"
"136.44200","6.53212","21134.46094","0.05340"
"136.64200","6.54869","21131.62500","0.05353"
"136.84200","6.56581","21135.44922","0.05366"
"137.04200","6.58219","21135.00195","0.05379"
"137.24200","6.59894","21130.92188","0.05392"
"137.44200","6.61544","21132.17773","0.05405"
"137.64200","6.63212","21134.94727","0.05418"
"137.84200","6.64919","21133.02148","0.05432"
"138.04200","6.66544","21132.64258","0.05445"
"138.24200","6.68212","21131.83008","0.05458"
"138.44200","6.69906","21136.46680","0.05471"
"138.64200","6.71556","21134.32227","0.05484"
"138.84200","6.73244","21134.13086","0.05497"
"139.04200","6.74875","21132.04102","0.05510"
"139.24200","6.76569","21133.86328","0.05523"
"139.44200","6.78225","21133.75977","0.05537"
"139.64200","6.79850","21128.45117","0.05549"
"139.84200","6.81587","21137.26953","0.05563"
"140.04200","6.83225","21131.94922","0.05576"
"140.24200","6.84875","21128.38086","0.05589"
"140.44200","6.86556","21132.92578","0.05602"
"140.64200","6.88206","21132.01953","0.05615"
"140.84200","6.89919","21133.31641","0.05629"
"141.04200","6.91562","21132.12109","0.05642"
"141.24200","6.93194","21126.94141","0.05654"
"141.44200","6.94906","21135.92383","0.05668"
"141.64200","6.96562","21131.58984","0.05681"
"141.84200","6.98231","21130.55859","0.05694"
"142.04200","6.99887","21131.32812","0.05707"
"142.24200","7.01556","21127.89062","0.05720"
"142.44200","7.03225","21133.28906","0.05733"
"142.64200","7.04869","21127.76953","0.05746"
"142.84200","7.06569","21130.80664","0.05760"
"143.04200","7.08231","21132.08984","0.05773"
"143.24200","7.09887","21125.09180","0.05786"
"143.44200","7.11537","21128.80859","0.05799"
"143.64200","7.13219","21130.36133","0.05812"
"143.84200","7.14912","21127.77539","0.05825"
"144.04200","7.16562","21130.26562","0.05838"
"144.24200","7.18206","21124.11523","0.05851"
"144.44200","7.19894","21130.42578","0.05865"
"144.64200","7.21569","21130.38281","0.05878"
"144.84200","7.23244","21126.62109","0.05891"
"145.04200","7.24875","21126.29297","0.05904"
"145.24200","7.26569","21126.36719","0.05917"
"145.44200","7.28212","21126.41406","0.05930"
"145.64200","7.29869","21124.33594","0.05943"
"145.84200","7.31587","21128.67969","0.05957"
"146.04200","7.33212","21124.84766","0.05970"
"146.24200","7.34894","21122.80469","0.05983"
"146.44200","7.36550","21123.76758","0.05996"
"146.64200","7.38200","21124.03906","0.06009"
"146.84200","7.39925","21124.07227","0.06022"
"147.04200","7.41556","21123.19727","0.06035"
"147.24200","7.43200","21120.48047","0.06048"
"147.44200","7.44912","21126.61133","0.06062"
"147.64200","7.46550","21121.64258","0.06075"
"147.84200","7.48244","21123.17969","0.06088"
"148.04200","7.49881","21120.32422","0.06101"
"148.24200","7.51556","21120.28516","0.06114"
"148.44200","7.53225","21123.02148","0.06127"
"148.64200","7.54862","21116.15039","0.06140"
"148.84200","7.56581","21122.38867","0.06154"
"149.04200","7.58231","21119.82812","0.06167"
"149.24200","7.59875","21114.01172","0.06179"
"149.44200","7.61550","21119.12305","0.06193"
"149.64200","7.63212","21118.02539","0.06206"
"149.84200","7.64906","21116.30078","0.06219"
"150.04200","7.66562","21118.32617","0.06232"
"150.24200","7.68200","21112.05273","0.06245"
"150.44200","7.69900","21119.21484","0.06258"
"150.64200","7.71569","21116.35352","0.06272"
"150.84200","7.73225","21112.85938","0.06285"
"151.04200","7.74894","21115.23242","0.06298"
"151.24200","7.76569","21111.68750","0.06311"
"151.44200","7.78212","21113.61914","0.06324"
"151.64200","7.79869","21110.01367","0.06337"
"151.84200","7.81575","21113.26367","0.06350"
"152.04200","7.83225","21112.49805","0.06363"
"152.24200","7.84894","21106.75781","0.06376"
"152.44200","7.86537","21107.36914","0.06389"
"152.64200","7.88219","21111.89453","0.06403"
"152.84200","7.89919","21107.89453","0.06416"
"153.04200","7.91544","21107.44922","0.06429"
"153.24200","7.93212","21105.46484","0.06442"
"153.44200","7.94900","21109.50781","0.06455"
"153.64200","7.96556","21107.21289","0.06468"
"153.84200","7.98250","21105.57812","0.06482"
"154.04200","7.99869","21102.27344","0.06494"
"154.24200","8.01569","21104.93359","0.06508"
"154.44200","8.03225","21104.53320","0.06521"
"154.64200","8.04856","21098.91992","0.06534"
"154.84200","8.06587","21106.23242","0.06547"
"155.04200","8.08225","21101.15820","0.06560"
"155.24200","8.09881","21097.01172","0.06573"
"155.44200","8.11556","21099.56055","0.06586"
"155.64200","8.13206","21098.00195","0.06599"
"155.84200","8.14919","21099.31055","0.06613"
"156.04200","8.16562","21097.48633","0.06626"
"156.24200","8.18194","21092.55859","0.06639"
"156.44200","8.19912","21101.70703","0.06652"
"156.64200","8.21562","21095.00195","0.06665"
"156.84200","8.23225","21093.61523","0.06678"
"157.04200","8.24887","21093.74609","0.06691"
"157.24200","8.26556","21091.18555","0.06704"
"157.44200","8.28225","21094.46289","0.06718"
"157.64200","8.29869","21088.83203","0.06731"
"157.84200","8.31569","21090.56641","0.06744"
"158.04200","8.33231","21091.50586","0.06757"
"158.24200","8.34887","21084.20508","0.06770"
"158.44200","8.36544","21087.91797","0.06783"
"158.64200","8.38219","21088.41602","0.06796"
"158.84200","8.39906","21084.21875","0.06810"
"159.04200","8.41562","21087.57422","0.06823"
"159.24200","8.43206","21080.33594","0.06836"
"159.44200","8.44894","21085.02539","0.06849"
"159.64200","8.46569","21084.92188","0.06862"
"159.84200","8.48244","21080.69727","0.06875"
"160.04200","8.49875","21079.72070","0.06888"
"160.24200","8.51569","21080.13086","0.06901"
"160.44200","8.53212","21079.05469","0.06914"
"160.64200","8.54862","21075.66797","0.06927"
"160.84200","8.56587","21079.63477","0.06941"
"161.04200","8.58212","21074.76562","0.06954"
"161.24200","8.59894","21072.77148","0.06967"
"161.44200","8.61550","21071.97070","0.06980"
"161.64200","8.63200","21073.08594","0.06993"
"161.84200","8.64919","21071.87500","0.07007"
"162.04200","8.66556","21070.68359","0.07019"
"162.24200","8.68200","21066.57031","0.07032"
"162.44200","8.69906","21071.94922","0.07046"
"162.64200","8.71550","21066.66992","0.07059"
"162.84200","8.73244","21067.65430","0.07072"
"163.04200","8.74887","21064.75000","0.07085"
"163.24200","8.76550","21062.55859","0.07098"
"163.44200","8.78231","21066.19336","0.07111"
"163.64200","8.79862","21058.80859","0.07124"
"163.84200","8.81575","21063.87500","0.07138"
"164.04200","8.83231","21060.56250","0.07151"
"164.24200","8.84869","21053.07422","0.07164"
"164.44200","8.86556","21059.21094","0.07177"
"164.64200","8.88212","21056.69531","0.07190"
"164.84200","8.89906","21054.14062","0.07203"
"165.04200","8.91562","21055.87109","0.07216"
"165.24200","8.93200","21048.47656","0.07229"
"165.44200","8.94900","21055.56055","0.07243"
"165.64200","8.96569","21051.76953","0.07256"
"165.84200","8.98231","21047.20898","0.07269"
"166.04200","8.99894","21049.36328","0.07282"
"166.24200","9.01562","21044.94727","0.07295"
"166.44200","9.03212","21046.44727","0.07308"
"166.64200","9.04875","21043.01172","0.07321"
"166.84200","9.06581","21044.45312","0.07335"
"167.04200","9.08219","21043.27148","0.07348"
"167.24200","9.09894","21037.02148","0.07361"
"167.44200","9.11537","21037.01758","0.07374"
"167.64200","9.13219","21040.54688","0.07387"
"167.84200","9.14919","21036.26172","0.07400"
"168.04200","9.16544","21034.36133","0.07413"
"168.24200","9.18212","21031.41602","0.07426"
"168.44200","9.19906","21034.91992","0.07440"
"168.64200","9.21556","21031.91602","0.07453"
"168.84200","9.23237","21028.67578","0.07466"
"169.04200","9.24869","21026.27539","0.07479"
"169.24200","9.26569","21027.28711","0.07492"
"169.44200","9.28225","21025.53516","0.07505"
"169.64200","9.29850","21020.12305","0.07518"
"169.84200","9.31587","21026.38281","0.07532"
"170.04200","9.33225","21020.64648","0.07544"
"170.24200","9.34881","21016.00391","0.07557"
"170.44200","9.36550","21017.71094","0.07571"
"170.64200","9.38200","21015.57617","0.07584"
"170.84200","9.39919","21016.20312","0.07597"
"171.04200","9.41562","21013.52734","0.07610"
"171.24200","9.43187","21007.21094","0.07623"
"171.44200","9.44912","21015.39648","0.07636"
"171.64200","9.46562","21008.35352","0.07649"
"171.84200","9.48231","21006.08789","0.07663"
"172.04200","9.49894","21005.56250","0.07676"
"172.24200","9.51556","21001.12891","0.07689"
"172.44200","9.53225","21004.16406","0.07702"
"172.64200","9.54862","20996.71094","0.07715"
"172.84200","9.56569","20999.70703","0.07728"
"173.04200","9.58231","20999.00391","0.07741"
"173.24200","9.59887","20991.14844","0.07754"
"173.44200","9.61537","20992.50000","0.07767"
"173.64200","9.63219","20993.32422","0.07781"
"173.84200","9.64912","20988.67969","0.07794"
"174.04200","9.66556","20989.14453","0.07807"
"174.24200","9.68206","20982.47461","0.07820"
"174.44200","9.69894","20986.79883","0.07833"
"174.64200","9.71569","20984.66016","0.07846"
"174.84200","9.73244","20979.87695","0.07860"
"175.04200","9.74875","20977.82812","0.07872"
"175.24200","9.76569","20976.01953","0.07886"
"175.44200","9.78218","20974.84180","0.07899"
"175.64200","9.79862","20970.25977","0.07912"
"175.84200","9.81587","20973.49023","0.07925"
"176.04200","9.83212","20968.44531","0.07938"
"176.24200","9.84894","20964.18945","0.07951"
"176.44200","9.86550","20964.21680","0.07964"
"176.64200","9.88200","20962.74219","0.07977"
"176.84200","9.89925","20961.30469","0.07991"
"177.04200","9.91556","20958.16797","0.08004"
"177.24200","9.93200","20953.42383","0.08017"
"177.44200","9.94912","20957.66602","0.08030"
"177.64200","9.96550","20951.69336","0.08043"
"177.84200","9.98244","20950.51562","0.08056"
"178.04200","9.99887","20947.08008","0.08069"
"178.24200","10.01550","20943.64453","0.08082"
"178.44200","10.03231","20945.98633","0.08096"
"178.64200","10.04862","20937.19922","0.08108"
"178.84200","10.06581","20941.44727","0.08122"
"179.04200","10.08231","20936.36523","0.08135"
"179.24200","10.09875","20927.70312","0.08148"
"179.44200","10.11550","20932.37500","0.08161"
"179.64200","10.13212","20928.95312","0.08174"
"179.84200","10.14906","20924.97266","0.08188"
"180.04200","10.16562","20925.67188","0.08201"
"180.24200","10.18206","20917.96094","0.08214"
"180.44200","10.19900","20922.18945","0.08227"
"180.64200","10.21569","20917.55078","0.08240"
"180.84200","10.23231","20911.90430","0.08253"
"181.04200","10.24887","20911.41406","0.08266"
"181.24200","10.26569","20907.16797","0.08279"
"181.44200","10.28206","20904.75781","0.08292"
"181.64200","10.29869","20900.65820","0.08305"
"181.84200","10.31581","20900.97266","0.08319"
"182.04200","10.33219","20897.70898","0.08332"
"182.24200","10.34887","20889.96094","0.08345"
"182.44200","10.36537","20889.13672","0.08358"
"182.64200","10.38218","20889.98633","0.08371"
"182.84200","10.39919","20883.99609","0.08385"
"183.04200","10.41544","20881.25977","0.08397"
"183.24200","10.43212","20876.88672","0.08410"
"183.44200","10.44906","20878.08984","0.08424"
"183.64200","10.46556","20873.18750","0.08437"
"183.84200","10.48244","20869.00195","0.08450"
"184.04200","10.49875","20863.94336","0.08463"
"184.24200","10.51575","20863.52344","0.08476"
"184.44200","10.53225","20859.96289","0.08489"
"184.64200","10.54856","20851.39062","0.08502"
"184.84200","10.56587","20855.89844","0.08516"
"185.04200","10.58225","20848.36133","0.08529"
"185.24200","10.59875","20841.09570","0.08542"
"185.44200","10.61550","20839.99219","0.08555"
"185.64200","10.63206","20837.54492","0.08568"
"185.84200","10.64919","20835.11914","0.08581"
"186.04200","10.66562","20830.07617","0.08594"
"186.24200","10.68187","20820.57617","0.08607"
"186.44200","10.69912","20826.63281","0.08621"
"186.64200","10.71562","20817.75586","0.08634"
"186.84200","10.73231","20812.47266","0.08647"
"187.04200","10.74887","20809.27734","0.08660"
"187.24200","10.76556","20802.95898","0.08673"
"187.44200","10.78225","20803.48047","0.08686"
"187.64200","10.79869","20792.48242","0.08699"
"187.84200","10.81569","20792.13867","0.08712"
"188.04200","10.83231","20789.81836","0.08726"
"188.24200","10.84887","20778.10156","0.08739"
"188.44200","10.86537","20777.05859","0.08752"
"188.64200","10.88219","20774.67969","0.08765"
"188.84200","10.89912","20766.57812","0.08778"
"189.04200","10.91562","20765.76367","0.08791"
"189.24200","10.93206","20754.46680","0.08804"
"189.44200","10.94887","20755.21289","0.08817"
"189.64200","10.96569","20750.46875","0.08831"
"189.84200","10.98237","20740.68555","0.08844"
"190.04200","10.99875","20736.68555","0.08857"
"190.24200","11.01569","20731.70898","0.08870"
"190.44200","11.03219","20726.90625","0.08883"
"190.64200","11.04869","20718.27148","0.08896"
"190.84200","11.06581","20716.49219","0.08909"
"191.04200","11.08212","20708.02539","0.08922"
"191.24200","11.09894","20700.46289","0.08935"
"191.44200","11.11550","20694.84180","0.08949"
"191.64200","11.13200","20690.08594","0.08962"
"191.84200","11.14925","20684.99023","0.08975"
"192.04200","11.16556","20677.19922","0.08988"
"192.24200","11.18200","20668.78320","0.09001"
"192.44200","11.19906","20667.39258","0.09014"
"192.64200","11.21550","20656.93359","0.09027"
"192.84200","11.23244","20651.47852","0.09041"
"193.04200","11.24887","20642.05469","0.09054"
"193.24200","11.26550","20635.08984","0.09067"
"193.44200","11.28231","20631.11719","0.09080"
"193.64200","11.29862","20617.43945","0.09093"
"193.84200","11.31581","20616.56250","0.09106"
"194.04200","11.33231","20605.96680","0.09119"
"194.24200","11.34869","20592.15625","0.09132"
"194.44200","11.36556","20591.22852","0.09145"
"194.64200","11.38219","20581.88672","0.09159"
"194.84200","11.39900","20570.73828","0.09172"
"195.04200","11.41569","20566.39062","0.09185"
"195.24200","11.43200","20551.57812","0.09198"
"195.44200","11.44900","20550.99219","0.09211"
"195.64200","11.46562","20539.85742","0.09224"
"195.84200","11.48225","20527.19531","0.09237"
"196.04200","11.49887","20521.32031","0.09250"
"196.24200","11.51569","20508.85156","0.09264"
"196.44200","11.53212","20501.23438","0.09277"
"196.64200","11.54869","20489.41797","0.09290"
"196.84200","11.56581","20483.36719","0.09303"
"197.04200","11.58219","20472.47461","0.09316"
"197.24200","11.59887","20456.97656","0.09329"
"197.44200","11.61537","20448.87305","0.09342"
"197.64200","11.63219","20442.12305","0.09355"
"197.84200","11.64919","20427.66016","0.09369"
"198.04200","11.66537","20416.04297","0.09382"
"198.24200","11.68212","20405.14258","0.09395"
"198.44200","11.69900","20397.72070","0.09408"
"198.64200","11.71556","20385.21680","0.09421"
"198.84200","11.73244","20371.81836","0.09434"
"199.04200","11.74875","20358.81055","0.09447"
"199.24200","11.76569","20348.08789","0.09460"
"199.44200","11.78225","20335.92383","0.09474"
"199.64200","11.79856","20318.85938","0.09486"
"199.84200","11.81587","20313.96289","0.09500"
"200.04200","11.83225","20297.05664","0.09513"
"200.24200","11.84881","20279.88672","0.09526"
"200.44200","11.86556","20270.43945","0.09539"
"200.64200","11.88206","20256.81055","0.09552"
"200.84200","11.89919","20244.22070","0.09566"
"201.04200","11.91562","20229.25781","0.09579"
"201.24200","11.93187","20210.31836","0.09591"
"201.44200","11.94912","20205.63281","0.09605"
"201.64200","11.96562","20185.80664","0.09618"
"201.84200","11.98231","20171.10352","0.09631"
"202.04200","11.99887","20156.28906","0.09644"
"202.24200","12.01562","20137.92773","0.09657"
"202.44200","12.03225","20125.78320","0.09670"
"202.64200","12.04869","20103.41016","0.09683"
"202.84200","12.06569","20091.42578","0.09697"
"203.04200","12.08237","20076.47656","0.09710"
"203.24200","12.09887","20052.38086","0.09723"
"203.44200","12.11537","20039.13281","0.09736"
"203.64200","12.13219","20024.80859","0.09749"
"203.84200","12.14906","20002.57227","0.09762"
"204.04200","12.16562","19988.44922","0.09775"
"204.24200","12.18212","19962.60742","0.09788"
"204.44200","12.19887","19947.90234","0.09802"
"204.64200","12.21568","19929.76367","0.09815"
"204.84200","12.23244","19905.87305","0.09828"
"205.04200","12.24875","19885.55273","0.09841"
"205.24200","12.26569","19865.53125","0.09854"
"205.44200","12.28219","19845.45508","0.09867"
"205.64200","12.29869","19822.92578","0.09880"
"205.84200","12.31587","19805.26367","0.09894"
"206.04200","12.33212","19781.00000","0.09907"
"206.24200","12.34894","19758.43555","0.09920"
"206.44200","12.36556","19737.56445","0.09933"
"206.64200","12.38206","19715.95312","0.09946"
"206.84200","12.39919","19692.53516","0.09959"
"207.04200","12.41550","19667.18945","0.09972"
"207.24200","12.43200","19641.20898","0.09985"
"207.44200","12.44912","19620.16016","0.09999"
"207.64200","12.46550","19589.29102","0.10012"
"207.84200","12.48237","19564.57227","0.10025"
"208.04200","12.49894","19537.62305","0.10038"
"208.24200","12.51550","19508.64258","0.10051"
"208.44200","12.53231","19484.92969","0.10064"
"208.64200","12.54862","19449.98828","0.10077"
"208.84200","12.56581","19425.84570","0.10091"
"209.04200","12.58237","19393.59570","0.10104"
"209.24200","12.59869","19352.83008","0.10116"
"209.44200","12.61550","19323.54102","0.10130"
"209.64200","12.63219","19288.96680","0.10143"
"209.84200","12.64906","19251.08203","0.10156"
"210.04200","12.66569","19217.45703","0.10169"
"210.24200","12.68206","19170.04492","0.10182"
"210.44200","12.69900","19133.40039","0.10195"
"210.64200","12.71569","19085.87305","0.10209"
"210.84200","12.73225","19031.43945","0.10222"
"211.04200","12.74894","18972.03711","0.10235"
"211.24200","12.76569","18899.04883","0.10248"
"211.44200","12.78212","18815.57227","0.10261"
"211.64200","12.79869","18729.76367","0.10274"
"211.84200","12.81581","18625.46875","0.10287"
"212.04200","12.83225","18489.64258","0.10300"
"212.24200","12.84887","18304.06250","0.10313"
"212.44200","12.86544","18071.40430","0.10326"
"212.64200","12.88231","17684.38672","0.10340"
"212.84200","12.89931","17164.50977","0.10353"
"213.04200","12.91594","15674.83398","0.10366"
"213.24200","12.93312","10045.11816","0.10380"
"213.36400","12.94712","-84.63481","0.10391"