File: ENGR270-Material Science Data Analysis/Lab4/Specimen_RawData_1.csv
Time,Extension,Load,Tensile strain (Strain 1)
(s),(mm),(N),(mm/mm)
"0.00000","-0.01644","-0.49682","0.00001"
"0.10000","-0.01131","50.17495","0.00002"
"0.20000","-0.00044","295.96613","0.00004"
"0.30000","0.00844","470.63281","0.00005"
"0.40000","0.01694","606.79187","0.00006"
"0.50000","0.02531","717.12292","0.00007"
"0.60000","0.03375","806.57733","0.00007"
"0.70000","0.04219","880.83307","0.00006"
"0.80000","0.05056","942.59216","0.00006"
"0.90000","0.05856","1001.23730","0.00005"
"1.00000","0.06712","1057.91895","0.00002"
"1.10000","0.07537","1107.96948","-0.00001"
"1.20000","0.08344","1155.28442","-0.00005"
"1.30000","0.09219","1204.68909","-0.00010"
"1.40000","0.10056","1248.73071","-0.00013"
"1.50000","0.10881","1288.30029","-0.00015"
"1.60000","0.11712","1330.17920","-0.00015"
"1.70000","0.12550","1372.26379","-0.00016"
"1.80000","0.13381","1410.48718","-0.00017"
"1.90000","0.14181","1450.83325","-0.00016"
"2.00000","0.15044","1493.34619","-0.00017"
"2.10000","0.15894","1533.84534","-0.00017"
"2.20000","0.16706","1575.30945","-0.00017"
"2.30000","0.17556","1619.00574","-0.00018"
"2.40000","0.18387","1662.33960","-0.00018"
"2.50000","0.19200","1703.62927","-0.00018"
"2.60000","0.20025","1747.15576","-0.00017"
"2.70000","0.20869","1793.28540","-0.00017"
"2.80000","0.21719","1837.78516","-0.00017"
"2.90000","0.22537","1883.08472","-0.00018"
"3.00000","0.23381","1929.18835","-0.00017"
"3.10000","0.24225","1972.26892","-0.00017"
"3.20000","0.25031","2014.43286","-0.00017"
"3.30000","0.25869","2059.10547","-0.00017"
"3.40000","0.26706","2103.49243","-0.00016"
"3.50000","0.27537","2146.99170","-0.00016"
"3.60000","0.28375","2192.47241","-0.00016"
"3.70000","0.29225","2239.66821","-0.00015"
"3.80000","0.30056","2282.61328","-0.00015"
"3.90000","0.30856","2327.73926","-0.00014"
"4.00000","0.31706","2375.05225","-0.00014"
"4.10000","0.32531","2418.40039","-0.00013"
"4.20000","0.33344","2464.19751","-0.00013"
"4.30000","0.34219","2514.42310","-0.00013"
"4.40000","0.35062","2562.01953","-0.00012"
"4.50000","0.35881","2606.75781","-0.00011"
"4.60000","0.36706","2656.27124","-0.00011"
"4.70000","0.37550","2705.24121","-0.00010"
"4.80000","0.38375","2750.15088","-0.00009"
"4.90000","0.39187","2800.09009","-0.00008"
"5.00000","0.40044","2852.07056","-0.00008"
"5.10000","0.40900","2901.03027","-0.00007"
"5.20000","0.41706","2949.52686","-0.00006"
"5.30000","0.42556","3001.47559","-0.00005"
"5.40000","0.43387","3051.59961","-0.00004"
"5.50000","0.44200","3100.21753","-0.00004"
"5.60000","0.45025","3151.19702","-0.00003"
"5.70000","0.45862","3204.60010","-0.00002"
"5.80000","0.46719","3255.74463","-0.00001"
"5.90000","0.47537","3308.04028","0.00000"
"6.00000","0.48381","3361.52734","0.00001"
"6.10000","0.49225","3413.03955","0.00002"
"6.20000","0.50037","3464.38550","0.00002"
"6.30000","0.50869","3517.62134","0.00003"
"6.40000","0.51706","3571.20044","0.00005"
"6.50000","0.52544","3624.36816","0.00006"
"6.60000","0.53375","3680.08691","0.00006"
"6.70000","0.54225","3736.44727","0.00007"
"6.80000","0.55056","3787.39941","0.00008"
"6.90000","0.55856","3842.34180","0.00009"
"7.00000","0.56712","3900.47363","0.00010"
"7.10000","0.57544","3952.91553","0.00011"
"7.20000","0.58344","4007.33838","0.00012"
"7.30000","0.59212","4067.17773","0.00013"
"7.40000","0.60050","4123.11035","0.00013"
"7.50000","0.60875","4176.77441","0.00015"
"7.60000","0.61712","4235.37695","0.00015"
"7.70000","0.62550","4292.50781","0.00017"
"7.80000","0.63375","4345.57812","0.00017"
"7.90000","0.64181","4403.65820","0.00018"
"8.00000","0.65044","4464.31543","0.00019"
"8.10000","0.65900","4523.21240","0.00020"
"8.20000","0.66712","4579.74072","0.00021"
"8.30000","0.67556","4639.64941","0.00022"
"8.40000","0.68381","4697.96289","0.00023"
"8.50000","0.69200","4754.96533","0.00024"
"8.60000","0.70025","4815.39160","0.00025"
"8.70000","0.70869","4877.70312","0.00026"
"8.80000","0.71719","4936.44482","0.00027"
"8.90000","0.72531","4996.71826","0.00028"
"9.00000","0.73375","5057.97510","0.00029"
"9.10000","0.74225","5118.42529","0.00030"
"9.20000","0.75037","5176.71338","0.00031"
"9.30000","0.75869","5239.03467","0.00032"
"9.40000","0.76712","5300.38672","0.00033"
"9.50000","0.77537","5359.45459","0.00034"
"9.60000","0.78375","5423.78418","0.00035"
"9.70000","0.79225","5488.68408","0.00036"
"9.80000","0.80056","5547.45703","0.00038"
"9.90000","0.80862","5609.65039","0.00038"
"10.00000","0.81706","5673.56738","0.00039"
"10.10000","0.82531","5732.90088","0.00040"
"10.20000","0.83350","5796.63721","0.00041"
"10.30000","0.84219","5864.06006","0.00042"
"10.40000","0.85056","5926.55371","0.00043"
"10.50000","0.85875","5985.90137","0.00044"
"10.60000","0.86700","6050.35400","0.00045"
"10.70000","0.87550","6115.34131","0.00047"
"10.80000","0.88381","6175.64014","0.00047"
"10.90000","0.89187","6239.46436","0.00049"
"11.00000","0.90050","6307.66162","0.00050"
"11.10000","0.90894","6370.56104","0.00051"
"11.20000","0.91700","6433.34912","0.00052"
"11.30000","0.92556","6501.24707","0.00053"
"11.40000","0.93387","6566.27100","0.00054"
"11.50000","0.94206","6629.26074","0.00055"
"11.60000","0.95025","6693.62012","0.00056"
"11.70000","0.95856","6760.94727","0.00058"
"11.80000","0.96725","6828.29932","0.00059"
"11.90000","0.97537","6894.97949","0.00060"
"12.00000","0.98381","6961.25928","0.00061"
"12.10000","0.99225","7026.01367","0.00062"
"12.20000","1.00031","7088.51611","0.00062"
"12.30000","1.00862","7157.20898","0.00064"
"12.40000","1.01712","7224.85059","0.00065"
"12.50000","1.02544","7289.98535","0.00066"
"12.60000","1.03375","7358.71338","0.00068"
"12.70000","1.04219","7427.62598","0.00069"
"12.80000","1.05056","7490.82715","0.00070"
"12.90000","1.05862","7559.05225","0.00071"
"13.00000","1.06706","7628.15918","0.00072"
"13.10000","1.07544","7690.95410","0.00073"
"13.20000","1.08344","7756.86279","0.00074"
"13.30000","1.09212","7828.86084","0.00076"
"13.40000","1.10062","7896.68701","0.00077"
"13.50000","1.10881","7959.65918","0.00079"
"13.60000","1.11712","8026.77295","0.00079"
"13.70000","1.12550","8093.19238","0.00080"
"13.80000","1.13369","8154.25977","0.00082"
"13.90000","1.14175","8221.59473","0.00083"
"14.00000","1.15050","8293.08301","0.00084"
"14.10000","1.15900","8358.45312","0.00085"
"14.20000","1.16712","8423.06055","0.00087"
"14.30000","1.17556","8490.26660","0.00088"
"14.40000","1.18381","8555.74316","0.00089"
"14.50000","1.19206","8620.97852","0.00090"
"14.60000","1.20031","8687.62793","0.00091"
"14.70000","1.20869","8755.01953","0.00093"
"14.80000","1.21719","8819.83984","0.00094"
"14.90000","1.22531","8886.81250","0.00095"
"15.00000","1.23375","8954.76074","0.00096"
"15.10000","1.24231","9021.37500","0.00097"
"15.20000","1.25037","9083.76172","0.00098"
"15.30000","1.25869","9150.50977","0.00099"
"15.40000","1.26700","9215.15820","0.00101"
"15.50000","1.27537","9280.35352","0.00102"
"15.60000","1.28387","9350.93652","0.00103"
"15.70000","1.29225","9418.40234","0.00105"
"15.80000","1.30069","9480.01074","0.00106"
"15.90000","1.30856","9545.45996","0.00107"
"16.00000","1.31694","9613.12402","0.00109"
"16.10000","1.32531","9676.13184","0.00110"
"16.20000","1.33350","9743.61133","0.00111"
"16.30000","1.34219","9813.17578","0.00113"
"16.40000","1.35056","9878.86523","0.00115"
"16.50000","1.35869","9939.27441","0.00116"
"16.60000","1.36700","10007.96191","0.00118"
"16.70000","1.37556","10075.80273","0.00119"
"16.80000","1.38381","10136.56641","0.00121"
"16.90000","1.39187","10201.65723","0.00122"
"17.00000","1.40037","10270.24707","0.00124"
"17.10000","1.40887","10334.86719","0.00125"
"17.20000","1.41712","10401.53613","0.00127"
"17.30000","1.42562","10468.56934","0.00129"
"17.40000","1.43387","10532.09473","0.00130"
"17.50000","1.44206","10596.27246","0.00132"
"17.60000","1.45019","10658.92090","0.00134"
"17.70000","1.45862","10728.59473","0.00136"
"17.80000","1.46725","10794.33203","0.00138"
"17.90000","1.47537","10858.48633","0.00139"
"18.00000","1.48381","10924.09277","0.00141"
"18.10000","1.49219","10986.66016","0.00143"
"18.20000","1.50031","11048.88281","0.00144"
"18.30000","1.50869","11116.02539","0.00147"
"18.40000","1.51706","11179.24023","0.00149"
"18.50000","1.52544","11242.34766","0.00151"
"18.60000","1.53369","11308.42676","0.00153"
"18.70000","1.54212","11375.11523","0.00155"
"18.80000","1.55062","11437.42090","0.00156"
"18.90000","1.55862","11500.61230","0.00159"
"19.00000","1.56706","11564.55957","0.00161"
"19.10000","1.57537","11624.33691","0.00163"
"19.20000","1.58331","11686.33301","0.00165"
"19.30000","1.59212","11756.24609","0.00168"
"19.40000","1.60069","11820.38477","0.00170"
"19.50000","1.60881","11877.28027","0.00173"
"19.60000","1.61706","11940.79492","0.00175"
"19.70000","1.62544","12002.84473","0.00177"
"19.80000","1.63369","12060.73730","0.00180"
"19.90000","1.64187","12123.67090","0.00182"
"20.00000","1.65050","12188.62695","0.00185"
"20.10000","1.65906","12248.56641","0.00187"
"20.20000","1.66700","12306.57520","0.00190"
"20.30000","1.67550","12369.15234","0.00193"
"20.40000","1.68387","12430.63477","0.00196"
"20.50000","1.69212","12488.32324","0.00199"
"20.60000","1.70031","12545.58008","0.00202"
"20.70000","1.70869","12606.70996","0.00205"
"20.80000","1.71706","12664.03613","0.00208"
"20.90000","1.72537","12724.93457","0.00211"
"21.00000","1.73381","12783.93555","0.00214"
"21.10000","1.74231","12839.69141","0.00217"
"21.20000","1.75037","12892.35840","0.00221"
"21.30000","1.75856","12949.02832","0.00224"
"21.40000","1.76706","13006.66602","0.00227"
"21.50000","1.77550","13061.80664","0.00230"
"21.60000","1.78381","13118.72461","0.00235"
"21.70000","1.79225","13175.16602","0.00238"
"21.80000","1.80056","13224.97754","0.00242"
"21.90000","1.80850","13277.38867","0.00246"
"22.00000","1.81706","13334.48633","0.00249"
"22.10000","1.82544","13384.10254","0.00253"
"22.20000","1.83350","13433.80957","0.00257"
"22.30000","1.84219","13490.60059","0.00262"
"22.40000","1.85050","13540.22461","0.00265"
"22.50000","1.85881","13587.74902","0.00270"
"22.60000","1.86712","13639.07715","0.00274"
"22.70000","1.87550","13687.96191","0.00279"
"22.80000","1.88381","13731.44531","0.00283"
"22.90000","1.89175","13778.85449","0.00288"
"23.00000","1.90044","13831.38867","0.00293"
"23.10000","1.90906","13877.57617","0.00298"
"23.20000","1.91712","13921.08496","0.00303"
"23.30000","1.92562","13967.83594","0.00308"
"23.40000","1.93381","14011.03613","0.00313"
"23.50000","1.94200","14053.36230","0.00318"
"23.60000","1.95025","14096.33887","0.00323"
"23.70000","1.95869","14142.77734","0.00329"
"23.80000","1.96725","14183.04004","0.00335"
"23.90000","1.97537","14224.22949","0.00340"
"24.00000","1.98369","14264.83105","0.00346"
"24.10000","1.99231","14306.42480","0.00352"
"24.20000","2.00044","14342.47656","0.00357"
"24.30000","2.00869","14381.16895","0.00364"
"24.40000","2.01712","14418.87500","0.00370"
"24.50000","2.02537","14454.55273","0.00376"
"24.60000","2.03369","14492.85156","0.00382"
"24.70000","2.04225","14533.69727","0.00389"
"24.80000","2.05069","14565.33984","0.00396"
"24.90000","2.05862","14597.96387","0.00402"
"25.00000","2.06700","14634.79688","0.00409"
"25.10000","2.07531","14665.78125","0.00416"
"25.20000","2.08350","14699.39844","0.00423"
"25.30000","2.09219","14737.88477","0.00431"
"25.40000","2.10062","14768.75879","0.00438"
"25.50000","2.10881","14795.98145","0.00445"
"25.60000","2.11700","14827.22754","0.00452"
"25.70000","2.12544","14860.42188","0.00459"
"25.80000","2.13387","14887.75000","0.00467"
"25.90000","2.14187","14915.74512","0.00474"
"26.00000","2.15050","14948.84668","0.00482"
"26.10000","2.15894","14976.58203","0.00490"
"26.20000","2.16700","15003.22559","0.00498"
"26.30000","2.17562","15034.84961","0.00505"
"26.40000","2.18387","15060.71387","0.00514"
"26.50000","2.19212","15084.91504","0.00521"
"26.60000","2.20019","15109.30957","0.00529"
"26.70000","2.20856","15139.85742","0.00537"
"26.80000","2.21725","15166.80859","0.00545"
"26.90000","2.22544","15192.32715","0.00554"
"27.00000","2.23381","15216.87988","0.00562"
"27.10000","2.24231","15241.78809","0.00570"
"27.20000","2.25031","15261.08789","0.00579"
"27.30000","2.25862","15287.54980","0.00587"
"27.40000","2.26712","15313.04590","0.00596"
"27.50000","2.27550","15334.45410","0.00604"
"27.60000","2.28381","15358.06641","0.00612"
"27.70000","2.29219","15383.51660","0.00621"
"27.80000","2.30056","15401.82422","0.00630"
"27.90000","2.30862","15425.44336","0.00638"
"28.00000","2.31706","15449.69727","0.00647"
"28.10000","2.32544","15467.97559","0.00655"
"28.20000","2.33344","15488.22852","0.00664"
"28.30000","2.34206","15515.28906","0.00672"
"28.40000","2.35056","15537.77441","0.00681"
"28.50000","2.35887","15554.35645","0.00690"
"28.60000","2.36706","15574.01758","0.00699"
"28.70000","2.37550","15596.04590","0.00707"
"28.80000","2.38375","15611.94238","0.00716"
"28.90000","2.39175","15632.75781","0.00725"
"29.00000","2.40056","15659.68066","0.00734"
"29.10000","2.40906","15676.52637","0.00742"
"29.20000","2.41712","15692.68555","0.00751"
"29.30000","2.42556","15714.06543","0.00760"
"29.40000","2.43375","15732.52832","0.00769"
"29.50000","2.44212","15751.75977","0.00777"
"29.60000","2.45031","15769.13574","0.00786"
"29.70000","2.45875","15791.12012","0.00795"
"29.80000","2.46725","15808.35156","0.00804"
"29.90000","2.47531","15825.67383","0.00812"
"30.00000","2.48375","15846.59473","0.00821"
"30.10000","2.49237","15865.14746","0.00830"
"30.20000","2.50044","15878.07227","0.00839"
"30.30000","2.50869","15896.75977","0.00848"
"30.40000","2.51700","15915.10352","0.00856"
"30.50000","2.52544","15932.45898","0.00865"
"30.60000","2.53387","15952.85254","0.00873"
"30.70000","2.54225","15971.64160","0.00883"
"30.80000","2.55069","15984.33398","0.00891"
"30.90000","2.55856","15999.25293","0.00900"
"31.00000","2.56694","16019.79395","0.00908"
"31.10000","2.57537","16035.13770","0.00918"
"31.20000","2.58356","16051.66016","0.00926"
"31.30000","2.59225","16072.97656","0.00935"
"31.40000","2.60062","16088.76270","0.00943"
"31.50000","2.60869","16099.48145","0.00952"
"31.60000","2.61700","16118.37402","0.00961"
"31.70000","2.62556","16137.72559","0.00970"
"31.80000","2.63387","16148.44824","0.00979"
"31.90000","2.64187","16163.90625","0.00987"
"32.00000","2.65037","16184.01074","0.00996"
"32.10000","2.65894","16199.28613","0.01005"
"32.20000","2.66719","16215.55957","0.01014"
"32.30000","2.67562","16231.61426","0.01022"
"32.40000","2.68394","16246.56738","0.01031"
"32.50000","2.69206","16259.16211","0.01040"
"32.60000","2.70019","16272.95312","0.01048"
"32.70000","2.70869","16295.29297","0.01057"
"32.80000","2.71731","16310.10156","0.01066"
"32.90000","2.72544","16323.25195","0.01075"
"33.00000","2.73375","16338.95312","0.01084"
"33.10000","2.74212","16352.74316","0.01093"
"33.20000","2.75031","16366.18945","0.01101"
"33.30000","2.75875","16384.22070","0.01110"
"33.40000","2.76712","16397.99805","0.01118"
"33.50000","2.77550","16411.59961","0.01127"
"33.60000","2.78369","16426.26367","0.01136"
"33.70000","2.79212","16444.30078","0.01145"
"33.80000","2.80069","16457.85547","0.01154"
"33.90000","2.80869","16470.27930","0.01163"
"34.00000","2.81706","16485.82031","0.01171"
"34.10000","2.82537","16497.36523","0.01180"
"34.20000","2.83344","16511.27734","0.01189"
"34.30000","2.84219","16532.85156","0.01197"
"34.40000","2.85069","16547.57227","0.01206"
"34.50000","2.85887","16554.88672","0.01215"
"34.60000","2.86706","16569.78711","0.01224"
"34.70000","2.87537","16585.10742","0.01232"
"34.80000","2.88369","16596.23438","0.01241"
"34.90000","2.89194","16612.01953","0.01250"
"35.00000","2.90056","16629.82617","0.01259"
"35.10000","2.90906","16641.64453","0.01268"
"35.20000","2.91694","16650.68359","0.01276"
"35.30000","2.92550","16669.08984","0.01285"
"35.40000","2.93387","16683.20312","0.01294"
"35.50000","2.94219","16695.04492","0.01303"
"35.60000","2.95031","16705.99219","0.01311"
"35.70000","2.95862","16723.27539","0.01320"
"35.80000","2.96712","16735.00586","0.01328"
"35.90000","2.97537","16750.52148","0.01338"
"36.00000","2.98387","16765.03711","0.01346"
"36.10000","2.99237","16776.85352","0.01355"
"36.20000","3.00044","16785.53320","0.01364"
"36.30000","3.00856","16799.02344","0.01372"
"36.40000","3.01706","16814.54883","0.01381"
"36.50000","3.02556","16828.23828","0.01390"
"36.60000","3.03387","16841.20508","0.01399"
"36.70000","3.04225","16855.54102","0.01408"
"36.80000","3.05056","16864.27539","0.01416"
"36.90000","3.05850","16876.57031","0.01425"
"37.00000","3.06712","16894.63867","0.01433"
"37.10000","3.07550","16904.72461","0.01442"
"37.20000","3.08350","16914.16602","0.01451"
"37.30000","3.09212","16933.17188","0.01460"
"37.40000","3.10050","16944.99609","0.01469"
"37.50000","3.10881","16954.09180","0.01477"
"37.60000","3.11706","16968.14648","0.01486"
"37.70000","3.12556","16981.35352","0.01495"
"37.80000","3.13387","16989.43164","0.01504"
"37.90000","3.14175","17000.70898","0.01512"
"38.00000","3.15044","17019.94141","0.01521"
"38.10000","3.15906","17031.94727","0.01530"
"38.20000","3.16719","17041.06250","0.01538"
"38.30000","3.17562","17054.25000","0.01547"
"38.40000","3.18381","17065.87891","0.01557"
"38.50000","3.19200","17076.39453","0.01565"
"38.60000","3.20025","17088.23047","0.01573"
"38.70000","3.20875","17105.10156","0.01583"
"38.80000","3.21731","17115.64258","0.01591"
"38.90000","3.22537","17126.01172","0.01600"
"39.00000","3.23362","17138.44141","0.01609"
"39.10000","3.24231","17152.72070","0.01618"
"39.20000","3.25044","17160.24805","0.01627"
"39.30000","3.25869","17171.97461","0.01635"
"39.40000","3.26719","17185.42578","0.01644"
"39.50000","3.27537","17194.24805","0.01652"
"39.60000","3.28375","17208.77344","0.01661"
"39.70000","3.29231","17224.65234","0.01670"
"39.80000","3.30069","17231.34180","0.01679"
"39.90000","3.30862","17240.42188","0.01688"
"40.00000","3.31700","17254.33984","0.01696"
"40.10000","3.32531","17263.48828","0.01705"
"40.20000","3.33350","17275.99414","0.01714"
"40.30000","3.34219","17292.84766","0.01723"
"40.40000","3.35062","17303.34570","0.01732"
"40.50000","3.35881","17309.03320","0.01740"
"40.60000","3.36694","17320.50977","0.01749"
"40.70000","3.37550","17335.83203","0.01758"
"40.80000","3.38387","17343.71484","0.01767"
"40.90000","3.39187","17353.26953","0.01776"
"41.00000","3.40056","17369.78906","0.01784"
"41.10000","3.40887","17377.90820","0.01793"
"41.20000","3.41700","17388.00000","0.01802"
"41.30000","3.42569","17403.54102","0.01811"
"41.40000","3.43394","17413.18164","0.01820"
"41.50000","3.44219","17420.29883","0.01828"
"41.60000","3.45025","17429.60742","0.01837"
"41.70000","3.45856","17444.47852","0.01846"
"41.80000","3.46725","17457.27539","0.01855"
"41.90000","3.47544","17467.05078","0.01864"
"42.00000","3.48381","17477.70703","0.01873"
"42.10000","3.49231","17489.23242","0.01882"
"42.20000","3.50031","17494.55469","0.01891"
"42.30000","3.50856","17507.28516","0.01899"
"42.40000","3.51719","17520.96680","0.01908"
"42.50000","3.52556","17529.58594","0.01917"
"42.60000","3.53381","17539.93945","0.01927"
"42.70000","3.54212","17552.32812","0.01936"
"42.80000","3.55056","17559.96289","0.01944"
"42.90000","3.55869","17570.74609","0.01954"
"43.00000","3.56712","17583.70312","0.01962"
"43.10000","3.57550","17590.71680","0.01971"
"43.20000","3.58344","17599.24219","0.01980"
"43.30000","3.59206","17615.34375","0.01989"
"43.40000","3.60062","17627.55273","0.01998"
"43.43000","3.60306","17630.05273","0.02000"
"43.43200","3.60325","17630.09961","0.02000"
"43.46200","3.60569","17631.31055","0.02003"
"43.56200","3.60312","17535.20312","0.02009"
"43.66200","3.59075","17261.67578","0.02008"
"43.76200","3.58087","17011.83984","0.02005"
"43.86200","3.57225","16817.11719","0.02003"
"43.96200","3.56369","16634.50977","0.02001"
"44.06200","3.55512","16460.07422","0.01999"
"44.16200","3.54706","16291.46680","0.01997"
"44.26200","3.53850","16123.45605","0.01995"
"44.36200","3.53012","15962.65332","0.01993"
"44.46200","3.52200","15807.27246","0.01991"
"44.56200","3.51362","15647.65137","0.01988"
"44.66200","3.50537","15493.92188","0.01986"
"44.76200","3.49706","15343.75391","0.01985"
"44.86200","3.48875","15187.41406","0.01983"
"44.96200","3.48019","15032.05176","0.01981"
"45.06200","3.47169","14881.95312","0.01978"
"45.16200","3.46350","14731.54297","0.01976"
"45.26200","3.45506","14579.88574","0.01975"
"45.36200","3.44681","14433.33789","0.01973"
"45.46200","3.43862","14289.30273","0.01971"
"45.56200","3.43025","14138.62402","0.01969"
"45.66200","3.42187","13989.31250","0.01967"
"45.76200","3.41331","13843.40332","0.01965"
"45.86200","3.40519","13696.84668","0.01963"
"45.96200","3.39675","13550.58301","0.01961"
"46.06200","3.38837","13410.02148","0.01959"
"46.16200","3.38044","13271.11133","0.01957"
"46.26200","3.37200","13129.16113","0.01955"
"46.36200","3.36344","12986.49902","0.01954"
"46.46200","3.35519","12850.55859","0.01952"
"46.56200","3.34675","12710.65332","0.01950"
"46.66200","3.33837","12571.69531","0.01948"
"46.76200","3.33006","12441.09961","0.01946"
"46.86200","3.32200","12305.67578","0.01944"
"46.96200","3.31362","12173.57520","0.01943"
"47.06200","3.30506","12042.92871","0.01941"
"47.16200","3.29694","11913.69043","0.01939"
"47.26200","3.28850","11782.94141","0.01938"
"47.36200","3.28000","11655.73047","0.01936"
"47.46200","3.27187","11535.03906","0.01934"
"47.56200","3.26350","11409.86426","0.01933"
"47.66200","3.25531","11289.70215","0.01931"
"47.76200","3.24694","11172.56445","0.01930"
"47.86200","3.23869","11050.83105","0.01928"
"47.96200","3.23012","10929.30762","0.01927"
"48.06200","3.22156","10811.43652","0.01925"
"48.16200","3.21344","10696.01660","0.01923"
"48.26200","3.20506","10578.59863","0.01922"
"48.36200","3.19681","10465.46582","0.01921"
"48.46200","3.18862","10356.68066","0.01919"
"48.56200","3.18025","10243.24414","0.01918"
"48.66200","3.17181","10131.80273","0.01917"
"48.76200","3.16337","10027.76855","0.01915"
"48.86200","3.15525","9925.51855","0.01914"
"48.96200","3.14675","9823.60352","0.01912"
"49.06200","3.13837","9727.87500","0.01911"
"49.16200","3.13037","9635.82422","0.01910"
"49.26200","3.12194","9540.51367","0.01909"
"49.36200","3.11344","9444.74316","0.01908"
"49.46200","3.10519","9355.44727","0.01907"
"49.56200","3.09681","9260.56543","0.01905"
"49.66200","3.08837","9167.01562","0.01904"
"49.76200","3.07994","9079.13672","0.01903"
"49.86200","3.07200","8988.59082","0.01901"
"49.96200","3.06362","8898.49219","0.01900"
"50.06200","3.05506","8807.73242","0.01900"
"50.16200","3.04694","8718.85645","0.01898"
"50.26200","3.03837","8626.12988","0.01897"
"50.36200","3.03000","8535.34570","0.01896"
"50.46200","3.02181","8450.58496","0.01895"
"50.56200","3.01350","8358.40625","0.01894"
"50.66200","3.00531","8269.90625","0.01892"
"50.76200","2.99681","8182.37354","0.01892"
"50.86200","2.98856","8090.60400","0.01890"
"50.96200","2.98012","7998.84717","0.01889"
"51.06200","2.97156","7910.48926","0.01888"
"51.16200","2.96350","7822.73389","0.01887"
"51.26200","2.95506","7732.69385","0.01886"
"51.36200","2.94675","7643.76660","0.01884"
"51.46200","2.93862","7558.34082","0.01883"
"51.56200","2.93025","7465.88281","0.01882"
"51.66200","2.92181","7373.03418","0.01880"
"51.76200","2.91337","7286.01367","0.01879"
"51.86200","2.90519","7196.10693","0.01878"
"51.96200","2.89681","7106.33105","0.01877"
"52.06200","2.88837","7017.94482","0.01876"
"52.16200","2.88037","6932.79492","0.01875"
"52.26200","2.87200","6843.63184","0.01874"
"52.36200","2.86344","6752.75537","0.01872"
"52.46200","2.85512","6669.29053","0.01870"
"52.56200","2.84681","6580.63818","0.01870"
"52.66200","2.83837","6491.66260","0.01868"
"52.76200","2.83000","6408.74365","0.01867"
"52.86200","2.82200","6324.48486","0.01866"
"52.96200","2.81362","6238.75781","0.01865"
"53.06200","2.80506","6153.38477","0.01864"
"53.16200","2.79694","6070.14209","0.01863"
"53.26200","2.78850","5983.63965","0.01861"
"53.36200","2.78006","5899.07861","0.01860"
"53.46200","2.77181","5819.83887","0.01859"
"53.56200","2.76356","5735.37500","0.01858"
"53.66200","2.75531","5653.63477","0.01856"
"53.76200","2.74687","5574.55518","0.01855"
"53.86200","2.73869","5491.17969","0.01854"
"53.96200","2.73012","5408.02051","0.01853"
"54.06200","2.72156","5327.67627","0.01852"
"54.16200","2.71344","5248.61426","0.01851"
"54.26200","2.70506","5167.14307","0.01850"
"54.36200","2.69675","5088.43945","0.01849"
"54.46200","2.68856","5014.05859","0.01847"
"54.56200","2.68019","4933.37842","0.01846"
"54.66200","2.67181","4852.39160","0.01846"
"54.76200","2.66331","4776.59814","0.01844"
"54.86200","2.65519","4699.17432","0.01843"
"54.96200","2.64675","4620.69922","0.01842"
"55.06200","2.63837","4545.89893","0.01841"
"55.16200","2.63037","4472.09814","0.01840"
"55.26200","2.62194","4395.29102","0.01839"
"55.36200","2.61344","4317.38330","0.01837"
"55.46200","2.60512","4245.90869","0.01836"
"55.56200","2.59681","4171.09961","0.01836"
"55.66200","2.58831","4094.72998","0.01834"
"55.76200","2.57994","4024.91650","0.01833"
"55.86200","2.57200","3953.71753","0.01832"
"55.96200","2.56362","3881.13232","0.01831"
"56.06200","2.55500","3808.88721","0.01830"
"56.16200","2.54694","3739.60913","0.01829"
"56.26200","2.53844","3665.25977","0.01828"
"56.36200","2.53000","3592.74072","0.01827"
"56.46200","2.52175","3525.96094","0.01825"
"56.56200","2.51356","3455.98389","0.01825"
"56.66200","2.50531","3386.72144","0.01824"
"56.76200","2.49687","3319.58569","0.01823"
"56.86200","2.48869","3250.16724","0.01822"
"56.96200","2.48012","3180.23853","0.01821"
"57.06200","2.47162","3113.09058","0.01820"
"57.16200","2.46350","3047.90088","0.01819"
"57.26200","2.45506","2980.35059","0.01817"
"57.36200","2.44675","2915.03491","0.01816"
"57.46200","2.43862","2854.02759","0.01815"
"57.56200","2.43019","2787.69165","0.01814"
"57.66200","2.42181","2723.01147","0.01813"
"57.76200","2.41331","2661.36548","0.01813"
"57.86200","2.40519","2597.97290","0.01811"
"57.96200","2.39675","2534.83618","0.01811"
"58.06200","2.38831","2475.09595","0.01809"
"58.16200","2.38037","2418.15698","0.01809"
"58.26200","2.37200","2357.26904","0.01807"
"58.36200","2.36344","2295.06250","0.01807"
"58.46200","2.35512","2238.27905","0.01805"
"58.56200","2.34681","2180.00586","0.01805"
"58.66200","2.33837","2119.97803","0.01804"
"58.76200","2.32994","2065.38379","0.01803"
"58.86200","2.32194","2009.57410","0.01802"
"58.96200","2.31362","1952.49854","0.01801"
"59.06200","2.30500","1896.57849","0.01800"
"59.16200","2.29694","1842.91785","0.01799"
"59.26200","2.28844","1785.93774","0.01798"
"59.36200","2.28000","1730.08167","0.01797"
"59.46200","2.27175","1678.21277","0.01797"
"59.56200","2.26356","1623.53345","0.01795"
"59.66200","2.25525","1569.49048","0.01794"
"59.76200","2.24687","1518.09473","0.01794"
"59.86200","2.23869","1464.81018","0.01793"
"59.96200","2.23006","1410.89355","0.01792"
"60.06200","2.22156","1360.11414","0.01791"
"60.16200","2.21344","1312.25220","0.01790"
"60.26200","2.20506","1262.01404","0.01789"
"60.36200","2.19681","1213.76770","0.01788"
"60.46200","2.18862","1169.29565","0.01787"
"60.56200","2.18019","1121.55652","0.01786"
"60.66200","2.17181","1074.29663","0.01786"
"60.76200","2.16325","1030.16724","0.01784"
"60.86200","2.15525","986.59369","0.01783"
"60.96200","2.14675","941.86713","0.01783"
"61.06200","2.13831","899.26508","0.01782"
"61.16200","2.13044","860.11810","0.01781"
"61.26200","2.12200","818.56128","0.01780"
"61.36200","2.11344","776.60315","0.01779"
"61.46200","2.10512","740.03937","0.01778"
"61.56200","2.09681","701.64978","0.01777"
"61.66200","2.08831","663.17285","0.01775"
"61.76200","2.07994","629.04016","0.01774"
"61.86200","2.07194","597.74377","0.01773"
"61.96200","2.06369","565.33203","0.01772"
"62.06200","2.05494","533.98407","0.01771"
"62.16200","2.04687","505.46661","0.01770"
"62.26200","2.03844","476.27734","0.01769"
"62.36200","2.03000","448.69870","0.01768"
"62.46200","2.02181","424.65231","0.01767"
"62.56200","2.01356","399.70862","0.01766"
"62.66200","2.00525","375.80814","0.01765"
"62.76200","1.99681","354.98264","0.01764"
"62.86200","1.98862","334.94263","0.01764"
"62.96200","1.98012","313.79016","0.01763"
"63.06200","1.97156","294.11951","0.01763"
"63.16200","1.96344","276.57483","0.01762"
"63.26200","1.95500","258.69873","0.01762"
"63.36200","1.94675","241.87212","0.01761"
"63.46200","1.93856","227.27962","0.01761"
"63.56200","1.93025","211.65411","0.01760"
"63.66200","1.92175","196.56653","0.01760"
"63.76200","1.91325","181.56299","0.01759"
"63.86200","1.90525","166.73918","0.01758"
"63.96200","1.89675","153.49504","0.01757"
"64.06200","1.88831","152.51746","0.01757"
"64.16200","1.88037","141.22514","0.01756"
"64.26200","1.87194","130.60561","0.01756"
"64.36200","1.86344","120.19851","0.01756"
"64.46200","1.85506","110.44530","0.01755"
"64.56200","1.84681","100.56544","0.01754"
"64.66200","1.83837","89.60135","0.01754"
"64.76200","1.82987","80.07993","0.01753"
"64.86200","1.82194","72.03671","0.01752"
"64.96200","1.81362","64.53253","0.01752"
"65.06200","1.80494","56.94715","0.01752"
"65.16200","1.79694","50.52640","0.01751"
"65.26200","1.78844","42.93853","0.01750"
"65.36200","1.78000","35.63331","0.01750"
"65.46200","1.77175","20.31588","0.01749"
"65.53000","1.76606","4.91561","0.01747"
"65.53200","1.76594","4.56426","0.01747"
"65.53400","1.76575","4.21192","0.01747"
"65.61600","1.76675","5.56002","0.01746"