File: ENGR270-Material Science Data Analysis/Lab4/Specimen_RawData_1 (1).csv
Time (s),Extension (mm),Load (N),Tensile strain (Strain 1) (mm/mm)
0,-0.01781,-4.57702,0.00001
0.1,-0.01213,52.35023,0.00002
0.2,-0.00175,289.35413,0.00004
0.3,0.00681,471.61429,0.00006
0.4,0.01562,617.08899,0.00007
0.5,0.02412,691.17627,0.00008
0.6,0.03237,735.89685,0.00008
0.7,0.04062,776.18298,0.00008
0.8,0.04912,815.66144,0.00008
0.9,0.05737,850.44623,0.00009
1,0.06537,884.77808,0.00008
1.1,0.07406,920.82306,0.00008
1.2,0.08256,955.56824,0.00008
1.3,0.09069,988.70154,0.00009
1.4,0.09919,1025.40601,0.00008
1.5,0.10744,1062.31787,0.00008
1.6,0.11569,1098.44666,0.00008
1.7,0.12381,1136.52209,0.00008
1.8,0.13225,1176.73145,0.00008
1.9,0.14081,1216.03381,0.00008
2,0.14894,1255.90967,0.00008
2.1,0.15744,1297.12488,0.00008
2.2,0.16587,1340.07263,0.00009
2.3,0.17394,1380.23633,0.00009
2.4,0.18231,1423.15308,0.00009
2.5,0.19062,1467.89417,0.00009
2.6,0.199,1511.46423,0.00009
2.7,0.20737,1558.80066,0.00009
2.8,0.21575,1606.39209,0.00009
2.9,0.22419,1651.84363,0.00009
3,0.23219,1698.76978,0.00009
3.1,0.24069,1748.87122,0.00009
3.2,0.249,1796.5166,0.0001
3.3,0.25706,1844.41187,0.00009
3.4,0.26575,1897.20667,0.0001
3.5,0.27412,1948.69189,0.0001
3.6,0.28237,1996.92822,0.0001
3.7,0.29062,2048.52417,0.0001
3.8,0.29906,2101.45532,0.0001
3.9,0.30737,2150.43896,0.00011
4,0.31537,2201.81104,0.00011
4.1,0.32406,2257.15771,0.00011
4.2,0.33256,2309.927,0.00011
4.3,0.34075,2360.71338,0.00011
4.4,0.34912,2414.37793,0.00012
4.5,0.35744,2467.17041,0.00012
4.6,0.36569,2517.79443,0.00012
4.7,0.37387,2568.24854,0.00013
4.8,0.38225,2619.53271,0.00012
4.9,0.39081,2668.51978,0.00013
5,0.39894,2717.20557,0.00013
5.1,0.40744,2765.84717,0.00014
5.2,0.41587,2813.20288,0.00014
5.3,0.424,2857.78735,0.00014
5.4,0.43225,2905.35547,0.00015
5.5,0.44062,2953.38818,0.00015
5.6,0.44906,2999.89893,0.00016
5.7,0.45737,3050.22144,0.00016
5.8,0.46581,3100.17188,0.00016
5.9,0.47425,3146.29272,0.00017
6,0.48219,3193.7561,0.00017
6.1,0.49069,3245.36011,0.00018
6.2,0.499,3293.14575,0.00019
6.3,0.50706,3341.52515,0.00019
6.4,0.51575,3395.30322,0.0002
6.5,0.52419,3445.70752,0.0002
6.6,0.53237,3492.33716,0.00021
6.7,0.54062,3544.64917,0.00022
6.8,0.54912,3597.46899,0.00022
6.9,0.55737,3645.22192,0.00022
7,0.56544,3696.51807,0.00023
7.1,0.57406,3750.97876,0.00024
7.2,0.5825,3802.46338,0.00025
7.3,0.59075,3854.67969,0.00025
7.4,0.59919,3908.57495,0.00026
7.5,0.60744,3961.41968,0.00026
7.6,0.61562,4012.60669,0.00027
7.7,0.62375,4065.54932,0.00027
7.8,0.63225,4122.10205,0.00028
7.9,0.64087,4176.59375,0.00029
8,0.649,4230.83594,0.0003
8.1,0.65737,4285.94238,0.0003
8.2,0.66575,4340.24902,0.00031
8.3,0.674,4393.9458,0.00032
8.4,0.68231,4450.79443,0.00032
8.5,0.69069,4507.45312,0.00033
8.6,0.69912,4561.5752,0.00034
8.7,0.70731,4618.80615,0.00034
8.8,0.71575,4677.36816,0.00035
8.9,0.72431,4733.39014,0.00036
9,0.73225,4788.84033,0.00037
9.1,0.74069,4847.91895,0.00037
9.2,0.74894,4902.67236,0.00038
9.3,0.75706,4959.23193,0.00039
9.4,0.76575,5022.30273,0.0004
9.5,0.77419,5081.92432,0.0004
9.6,0.78244,5135.9292,0.00041
9.7,0.79062,5195.6665,0.00042
9.8,0.799,5255.2627,0.00043
9.9,0.80731,5311.31836,0.00044
10,0.8155,5372.57617,0.00044
10.1,0.82412,5434.90186,0.00045
10.2,0.83256,5493.86133,0.00046
10.3,0.84062,5550.46631,0.00047
10.4,0.84912,5614.33252,0.00048
10.5,0.8575,5676.02051,0.00049
10.6,0.86569,5734.6875,0.0005
10.7,0.87387,5794.94922,0.00051
10.8,0.88225,5857.87109,0.00051
10.9,0.89075,5918.73877,0.00052
11,0.89894,5981.57129,0.00053
11.1,0.90744,6045.58789,0.00054
11.2,0.91587,6106.21777,0.00055
11.3,0.924,6164.92383,0.00055
11.4,0.93219,6227.45068,0.00056
11.5,0.94062,6291.57129,0.00057
11.6,0.94912,6354.01514,0.00058
11.7,0.95737,6418.02686,0.00059
11.8,0.96581,6483.66504,0.0006
11.9,0.97419,6543.35107,0.00061
12,0.98206,6605.42334,0.00062
12.1,0.99069,6673.38135,0.00062
12.2,0.999,6734.40381,0.00064
12.3,1.00712,6796.34277,0.00064
12.4,1.01575,6865.08496,0.00065
12.5,1.02406,6929.43701,0.00066
12.6,1.03237,6990.46338,0.00067
12.7,1.04062,7058.12354,0.00068
12.8,1.04912,7122.81543,0.00069
12.9,1.05744,7184.43115,0.0007
13,1.06537,7247.46436,0.00071
13.1,1.074,7317.38574,0.00072
13.2,1.08256,7384.21094,0.00073
13.3,1.09075,7447.5708,0.00074
13.4,1.09919,7513.96338,0.00075
13.5,1.10737,7578.24854,0.00076
13.6,1.11556,7641.69189,0.00077
13.7,1.12381,7707.34717,0.00077
13.8,1.13231,7776.16211,0.00078
13.9,1.14087,7840.79199,0.00079
14,1.14894,7905.78223,0.0008
14.1,1.15731,7971.71875,0.00081
14.2,1.16581,8038.28613,0.00081
14.3,1.174,8102.13672,0.00083
14.4,1.18231,8168.0791,0.00083
14.5,1.19069,8233.78223,0.00084
14.6,1.199,8297.44434,0.00085
14.7,1.20731,8366.27637,0.00086
14.8,1.21581,8435.39941,0.00087
14.9,1.22425,8497.74902,0.00088
15,1.23219,8561.94922,0.00089
15.1,1.24062,8629.29102,0.00089
15.2,1.24887,8692.12598,0.0009
15.3,1.25712,8758.78516,0.00091
15.4,1.26575,8829.9668,0.00092
15.5,1.27419,8896.1709,0.00093
15.6,1.28244,8958.43262,0.00093
15.7,1.2905,9024.68457,0.00094
15.8,1.299,9093.41895,0.00095
15.9,1.30744,9158.26562,0.00096
16,1.31544,9223.4668,0.00097
16.1,1.32406,9294.00293,0.00098
16.2,1.3325,9360.5293,0.00099
16.3,1.34062,9425.6543,0.001
16.4,1.34919,9496.45215,0.00101
16.5,1.3575,9563.52637,0.00101
16.6,1.36569,9627.52148,0.00102
16.7,1.37381,9693.81641,0.00103
16.8,1.38212,9762.97949,0.00104
16.9,1.39081,9832.62988,0.00105
17,1.399,9901.16211,0.00105
17.1,1.40737,9968.6084,0.00106
17.2,1.41581,10035.72559,0.00107
17.3,1.42394,10099.88477,0.00108
17.4,1.43219,10169.15723,0.00109
17.5,1.44069,10238.80957,0.00109
17.6,1.44912,10305.22266,0.00111
17.7,1.45737,10374.98633,0.00111
17.8,1.46569,10444.59863,0.00112
17.9,1.47419,10510.45312,0.00113
18,1.48219,10578.77246,0.00114
18.1,1.49069,10649.30371,0.00114
18.2,1.499,10714.98438,0.00115
18.3,1.50706,10781.21387,0.00116
18.4,1.51562,10854.02832,0.00117
18.5,1.52419,10924.85156,0.00118
18.6,1.5325,10990.89746,0.00118
18.7,1.54062,11059.76367,0.0012
18.8,1.54906,11128.80371,0.0012
18.9,1.55731,11193.00684,0.00121
19,1.56537,11262.71973,0.00122
19.1,1.57412,11337.64941,0.00123
19.2,1.58262,11406.10156,0.00124
19.3,1.59075,11473.54492,0.00125
19.4,1.59912,11544.18945,0.00126
19.5,1.60737,11613.89844,0.00126
19.6,1.61575,11683.60742,0.00127
19.7,1.62387,11752.08789,0.00129
19.8,1.63225,11824.56348,0.00129
19.9,1.64081,11893.9375,0.00131
20,1.64887,11963.77832,0.00131
20.1,1.65737,12036.8291,0.00132
20.2,1.66587,12108.47461,0.00133
20.3,1.67406,12174.09375,0.00134
20.4,1.68225,12244.64062,0.00135
20.5,1.69056,12314.40332,0.00136
20.6,1.69906,12384.93555,0.00137
20.7,1.70744,12459.62402,0.00139
20.8,1.71581,12532.41699,0.0014
20.9,1.72431,12599.73242,0.00141
21,1.73212,12667.36816,0.00142
21.1,1.7405,12740.43359,0.00143
21.2,1.749,12810.56543,0.00143
21.3,1.75712,12879.60156,0.00145
21.4,1.76575,12955.26465,0.00146
21.5,1.77412,13026.875,0.00147
21.6,1.78231,13092.14941,0.00148
21.7,1.79056,13165.45117,0.00149
21.8,1.79912,13238.73828,0.0015
21.9,1.80744,13305.21289,0.00151
22,1.81544,13375.1543,0.00152
22.1,1.82394,13449.09668,0.00153
22.2,1.8325,13520.80273,0.00154
22.3,1.84081,13592.53125,0.00156
22.4,1.84925,13664.61621,0.00157
22.5,1.85744,13733.58984,0.00158
22.6,1.86562,13801.94727,0.00159
22.7,1.87375,13871.30762,0.00161
22.8,1.88219,13946.74316,0.00162
22.9,1.89087,14019.57227,0.00163
23,1.899,14089.82715,0.00164
23.1,1.90731,14159.89062,0.00166
23.2,1.91569,14230.25977,0.00167
23.3,1.924,14298.83203,0.00168
23.4,1.93237,14373.375,0.00169
23.5,1.94069,14442.69434,0.00171
23.6,1.94906,14511.13477,0.00172
23.7,1.95725,14582.35059,0.00173
23.8,1.96569,14657.08203,0.00175
23.9,1.97431,14726.93359,0.00176
24,1.98219,14794.48633,0.00177
24.1,1.99069,14866.19141,0.00178
24.2,1.99887,14932.4043,0.0018
24.3,2.00694,15000.04785,0.00181
24.4,2.01575,15077.62109,0.00182
24.5,2.02419,15148.94824,0.00184
24.6,2.03244,15212.19727,0.00185
24.7,2.04062,15281.82227,0.00186
24.8,2.04894,15349.78711,0.00188
24.9,2.05737,15415.48926,0.00189
25,2.0655,15485.11426,0.00191
25.1,2.07412,15557.27734,0.00192
25.2,2.08262,15624.31445,0.00194
25.3,2.09062,15687.7373,0.00195
25.4,2.09906,15757.17773,0.00197
25.5,2.10744,15826.58398,0.00199
25.6,2.11581,15891.65918,0.002
25.7,2.12387,15954.66699,0.00202
25.8,2.13219,16022.50195,0.00204
25.9,2.14075,16088.61523,0.00206
26,2.149,16155.5293,0.00207
26.1,2.15744,16221.48633,0.00209
26.2,2.16587,16285.58008,0.00211
26.3,2.17406,16344.66602,0.00213
26.4,2.18212,16407.16797,0.00215
26.5,2.19062,16472.70703,0.00217
26.6,2.19919,16536.17969,0.00219
26.7,2.20737,16598.76953,0.00221
26.8,2.21581,16662.1543,0.00224
26.9,2.22412,16717.65625,0.00225
27,2.23212,16775.66992,0.00228
27.1,2.24069,16839.96094,0.00231
27.2,2.249,16894.5293,0.00233
27.3,2.25712,16948.75,0.00235
27.4,2.26569,17010.19727,0.00238
27.5,2.27406,17065.64648,0.00241
27.6,2.28244,17117.29883,0.00244
27.7,2.29062,17171.02539,0.00246
27.8,2.29906,17223.74805,0.00249
27.9,2.30744,17269.52734,0.00252
28,2.31531,17316.57031,0.00256
28.1,2.32406,17369.85547,0.00259
28.2,2.33262,17417.11133,0.00263
28.3,2.34081,17456.45508,0.00267
28.4,2.34919,17498.49805,0.00271
28.5,2.35737,17537.02344,0.00275
28.6,2.36562,17571.50977,0.0028
28.7,2.37387,17605.44336,0.00285
28.8,2.38231,17640.75586,0.0029
28.9,2.39087,17668.1543,0.00296
29,2.39894,17692.26367,0.00303
29.1,2.40725,17715.20312,0.0031
29.2,2.41587,17739.23242,0.00317
29.3,2.42406,17752.64844,0.00325
29.4,2.43231,17768.14453,0.00332
29.5,2.44075,17783.95703,0.00341
29.6,2.44906,17794.42969,0.0035
29.7,2.45737,17807.05859,0.00359
29.8,2.46581,17821.24414,0.00369
29.9,2.47437,17827.04883,0.00378
30,2.48225,17831.95703,0.00387
30.1,2.49062,17842.81055,0.00396
30.2,2.49894,17848.7207,0.00405
30.3,2.50719,17856.74023,0.00414
30.4,2.51581,17868.92578,0.00424
30.5,2.52419,17874.55273,0.00434
30.6,2.5325,17876.7832,0.00443
30.7,2.5405,17883.27539,0.00452
30.8,2.54906,17894.52344,0.00461
30.9,2.55756,17899.07031,0.00471
31,2.5655,17903.2168,0.0048
31.1,2.57412,17915.08984,0.0049
31.2,2.5825,17920.76172,0.00499
31.3,2.59069,17925.80469,0.00509
31.4,2.59925,17935.82227,0.00518
31.5,2.6075,17942.30469,0.00528
31.6,2.61581,17947.20898,0.00537
31.7,2.62375,17950.63281,0.00547
31.8,2.63212,17963.25977,0.00557
31.9,2.64094,17973.71094,0.00566
32,2.64906,17979.18164,0.00576
32.1,2.65737,17985.25391,0.00585
32.2,2.66581,17994.10742,0.00595
32.3,2.67394,17996.57031,0.00605
32.4,2.68225,18007.19141,0.00614
32.5,2.69075,18018.30859,0.00624
32.6,2.69919,18023.97461,0.00633
32.7,2.70744,18030.76758,0.00643
32.8,2.71569,18040.86133,0.00652
32.9,2.72425,18046.80469,0.00662
33,2.73225,18053.36328,0.00671
33.1,2.74069,18063.29883,0.0068
33.2,2.74906,18069.89648,0.0069
33.3,2.75706,18074.91211,0.00699
33.4,2.76562,18088.18945,0.00709
33.5,2.77419,18098.84961,0.00718
33.6,2.78262,18102.56445,0.00728
33.7,2.79062,18108.09375,0.00737
33.8,2.79912,18119.23438,0.00746
33.9,2.80731,18122.35742,0.00755
34,2.81537,18131.16797,0.00764
34.1,2.82419,18146.52539,0.00773
34.2,2.83262,18152.47852,0.00783
34.3,2.84081,18157.09375,0.00792
34.4,2.84912,18165.29492,0.00802
34.5,2.85737,18174.53711,0.0081
34.6,2.86581,18183.0293,0.00819
34.7,2.87387,18187.76953,0.00828
34.8,2.88225,18199.45898,0.00838
34.9,2.89087,18207.80859,0.00847
35,2.89887,18213.76953,0.00856
35.1,2.90737,18224.5918,0.00865
35.2,2.91594,18234.8418,0.00874
35.3,2.92412,18236.21484,0.00883
35.4,2.93225,18243.43945,0.00892
35.5,2.94056,18253.9375,0.009
35.6,2.94912,18262.7207,0.0091
35.7,2.95744,18271.84766,0.00919
35.8,2.96587,18282.16992,0.00928
35.9,2.97437,18286.04883,0.00937
36,2.98212,18289.80078,0.00946
36.1,2.9905,18301.52734,0.00954
36.2,2.999,18310.65625,0.00963
36.3,3.00719,18316.49609,0.00972
36.4,3.01575,18328.64648,0.00981
36.5,3.02412,18336.72266,0.0099
36.6,3.03231,18338.98242,0.00999
36.7,3.04062,18349.42383,0.01007
36.8,3.04912,18360.19141,0.01017
36.9,3.05756,18364.1582,0.01025
37,3.06544,18369.5332,0.01034
37.1,3.07394,18381.39258,0.01043
37.2,3.0825,18390.80273,0.01052
37.3,3.09087,18397.77734,0.01061
37.4,3.09931,18406.15039,0.01069
37.5,3.1075,18411.96289,0.01078
37.6,3.11569,18417.56641,0.01087
37.7,3.12375,18423.33789,0.01095
37.8,3.13225,18437.39648,0.01104
37.9,3.14087,18445.07812,0.01113
38,3.14906,18451.77734,0.01122
38.1,3.15731,18458.16797,0.0113
38.2,3.16575,18467.09766,0.01139
38.3,3.174,18472.62891,0.01148
38.4,3.18231,18481.44141,0.01157
38.5,3.19069,18489.64453,0.01165
38.6,3.19919,18496.2832,0.01174
38.7,3.20725,18502.51367,0.01183
38.8,3.21569,18514.16211,0.01192
38.9,3.22437,18521.44531,0.012
39,3.23231,18524.47461,0.01209
39.1,3.24069,18534.23047,0.01218
39.2,3.24887,18538.71484,0.01227
39.3,3.257,18545.77539,0.01235
39.4,3.26575,18560.56836,0.01244
39.5,3.27425,18568.76367,0.01253
39.6,3.28256,18569.7207,0.01262
39.7,3.29056,18575.94141,0.0127
39.8,3.29894,18586.62109,0.01279
39.9,3.30744,18592.21094,0.01288
40,3.3155,18599.7207,0.01297
40.1,3.32412,18611.02344,0.01306
40.2,3.33262,18617.38477,0.01315
40.3,3.34069,18620.49805,0.01323
40.4,3.34912,18630.86328,0.01332
40.5,3.3575,18639.78711,0.01341
40.6,3.36581,18644.19336,0.0135
40.7,3.37387,18648.12891,0.01359
40.8,3.38219,18659.65039,0.01368
40.9,3.39081,18668.02148,0.01376
41,3.39906,18675.07812,0.01385
41.1,3.40744,18682.15039,0.01394
41.2,3.41587,18690.01172,0.01403
41.3,3.42406,18692.43164,0.01412
41.4,3.43219,18699.16406,0.01421
41.5,3.44069,18710.67969,0.0143
41.6,3.44919,18717.18164,0.01438
41.7,3.45744,18723.61914,0.01447
41.8,3.46575,18732.53906,0.01457
41.9,3.47419,18736.4375,0.01465
42,3.48212,18741.48633,0.01474
42.1,3.49069,18753.17188,0.01483
42.2,3.49906,18757.66797,0.01492
42.3,3.50719,18762.64258,0.01501
42.4,3.51569,18773.76367,0.0151
42.5,3.52406,18782.07617,0.01518
42.6,3.5325,18785.57422,0.01527
42.7,3.54069,18792.81055,0.01536
42.8,3.54912,18801.01758,0.01546
42.9,3.5575,18803.82422,0.01554
43,3.56537,18809.28125,0.01563
43.1,3.574,18822.92773,0.01572
43.2,3.58269,18830.9668,0.01581
43.3,3.59081,18833.0332,0.0159
43.4,3.59925,18841.30273,0.01599
43.5,3.60731,18846.12305,0.01608
43.6,3.61562,18853.08398,0.01617
43.7,3.62381,18859.01367,0.01626
43.8,3.63225,18869.73828,0.01635
43.9,3.64094,18875.72656,0.01644
44,3.649,18881.01172,0.01653
44.1,3.65725,18887.24219,0.01662
44.2,3.66587,18897.01172,0.01671
44.3,3.67412,18899.91406,0.0168
44.4,3.68231,18905.33203,0.01689
44.5,3.69069,18913.49219,0.01698
44.6,3.699,18918.98828,0.01707
44.7,3.70731,18926.61328,0.01716
44.8,3.71581,18937.72266,0.01725
44.9,3.72444,18941.95312,0.01734
45,3.73225,18943.52539,0.01743
45.1,3.74062,18952.45703,0.01753
45.2,3.74894,18957.18164,0.01762
45.3,3.75712,18964.36719,0.01771
45.4,3.76581,18975.61523,0.0178
45.5,3.77425,18981.63086,0.01789
45.6,3.78244,18982.20312,0.01798
45.7,3.7905,18988.50391,0.01807
45.8,3.799,18998.99023,0.01816
45.9,3.80756,19003.68359,0.01825
46,3.8155,19006.99023,0.01834
46.1,3.82412,19018.81055,0.01843
46.2,3.8325,19022.99609,0.01852
46.3,3.84062,19027.19727,0.01861
46.4,3.84925,19038.12891,0.01871
46.5,3.8575,19043.49414,0.0188
46.6,3.86581,19046.50195,0.01888
46.7,3.87375,19048.58594,0.01898
46.8,3.88212,19060.67188,0.01907
46.9,3.89087,19069.11133,0.01916
47,3.89906,19074.08594,0.01925
47.1,3.90737,19078.81641,0.01934
47.2,3.91587,19086.31836,0.01944
47.3,3.92394,19087.0293,0.01953
47.4,3.93219,19095.59961,0.01962
47.5,3.94075,19105.14453,0.01971
47.6,3.94925,19109.76953,0.0198
47.7,3.95744,19114.54102,0.01989
47.8,3.96569,19121.42188,0.01999
47.818,3.96712,19121.31836,0.02
47.82,3.96725,19121.26562,0.02
47.85,3.96969,19121.28711,0.02003
47.95,3.9675,19029.14844,0.02009
48.05,3.95537,18756.25586,0.02009
48.15,3.94537,18500.17578,0.02006
48.25,3.93637,18295.73438,0.02004
48.35,3.92794,18109.40625,0.02002
48.45,3.91956,17934.64648,0.02
48.55,3.91131,17757.12695,0.01998
48.65,3.90281,17585.66406,0.01996
48.75,3.89431,17419.68164,0.01994
48.85,3.88619,17257.86328,0.01993
48.95,3.87775,17095.3125,0.0199
49.05,3.8695,16937.37305,0.01988
49.15,3.86131,16787.07031,0.01987
49.25,3.85287,16630.21094,0.01985
49.35,3.8445,16473.90234,0.01982
49.45,3.83594,16321.55762,0.01981
49.55,3.82787,16169.57812,0.01979
49.65,3.81937,16016.67969,0.01977
49.75,3.811,15867.0957,0.01975
49.85,3.80306,15721.40625,0.01973
49.95,3.79456,15569.47266,0.01971
50.05,3.78606,15417.0127,0.0197
50.15,3.77769,15272.35352,0.01968
50.25,3.76944,15123.44336,0.01966
50.35,3.761,14974.75195,0.01964
50.45,3.75256,14832.74414,0.01963
50.55,3.74456,14688.15332,0.0196
50.65,3.73625,14544.80762,0.01959
50.75,3.72769,14401.14062,0.01957
50.85,3.71956,14260.92969,0.01955
50.95,3.71106,14116.73145,0.01953
51.05,3.70262,13973.79785,0.01952
51.15,3.69437,13839.01367,0.01949
51.25,3.68619,13698.98047,0.01947
51.35,3.67794,13563.74902,0.01946
51.45,3.6695,13429.61523,0.01944
51.55,3.66125,13291.61328,0.01943
51.65,3.65269,13155.05371,0.01941
51.75,3.64425,13022.5332,0.01939
51.85,3.63606,12893.89258,0.01938
51.95,3.62769,12763.20215,0.01936
52.05,3.6195,12638.05371,0.01934
52.15,3.61119,12516.74902,0.01933
52.25,3.60281,12389.73438,0.01932
52.35,3.59444,12264.97656,0.01929
52.45,3.58594,12144.49707,0.01928
52.55,3.57781,12023.55078,0.01926
52.65,3.56931,11901.66895,0.01925
52.75,3.56094,11783.7627,0.01923
52.85,3.55294,11671.6582,0.01922
52.95,3.54456,11554.25293,0.01921
53.05,3.53612,11436.75488,0.01919
53.15,3.52775,11327.46289,0.01917
53.25,3.51944,11213.3291,0.01916
53.35,3.51094,11101.30371,0.01914
53.45,3.5025,10995.7627,0.01913
53.55,3.49456,10890,0.01911
53.65,3.48625,10784.82324,0.0191
53.75,3.47762,10678.82617,0.01909
53.85,3.4695,10579.4375,0.01908
53.95,3.46106,10477.25684,0.01906
54.05,3.45262,10378.29395,0.01905
54.15,3.44437,10287.73828,0.01903
54.25,3.43619,10191.30566,0.01903
54.35,3.42787,10100.40918,0.01901
54.45,3.41944,10009.61035,0.019
54.55,3.41125,9916.39844,0.01899
54.65,3.40275,9823.25195,0.01898
54.75,3.39425,9730.72363,0.01896
54.85,3.38606,9641.62207,0.01895
54.95,3.37762,9549.4707,0.01894
55.05,3.36937,9459.3252,0.01892
55.15,3.36119,9373.75098,0.01892
55.25,3.35287,9281.99707,0.0189
55.35,3.34444,9189.24121,0.01889
55.45,3.33587,9101.81348,0.01888
55.55,3.32775,9013.06836,0.01887
55.65,3.31931,8923.11133,0.01886
55.75,3.311,8836.0791,0.01885
55.85,3.303,8752.65332,0.01883
55.95,3.29456,8663.91797,0.01883
56.05,3.28606,8573.79688,0.01881
56.15,3.27762,8489.75879,0.0188
56.25,3.26944,8400.86719,0.01879
56.35,3.26094,8311.34863,0.01878
56.45,3.2525,8227.66797,0.01877
56.55,3.24456,8141.67285,0.01875
56.65,3.23625,8054.20898,0.01874
56.75,3.22769,7964.55518,0.01873
56.85,3.2195,7878.5166,0.01872
56.95,3.211,7787.89502,0.01871
57.05,3.20262,7699.83594,0.01869
57.15,3.19437,7616.72266,0.01868
57.25,3.18619,7528.00635,0.01867
57.35,3.17794,7441.29932,0.01865
57.45,3.16944,7355.65576,0.01864
57.55,3.16125,7267.53418,0.01863
57.65,3.15269,7176.45605,0.01862
57.75,3.14425,7088.72461,0.01861
57.85,3.13606,7003.34082,0.0186
57.95,3.12769,6915.29199,0.01858
58.05,3.11944,6829.13379,0.01857
58.15,3.11119,6747.61621,0.01856
58.25,3.10287,6660.04883,0.01855
58.35,3.09437,6571.02832,0.01853
58.45,3.08587,6487.12891,0.01852
58.55,3.07775,6404.56836,0.01851
58.65,3.06937,6319.01123,0.0185
58.75,3.061,6236.36377,0.01848
58.85,3.053,6158.08838,0.01847
58.95,3.04456,6072.99902,0.01846
59.05,3.03606,5987.13281,0.01844
59.15,3.02769,5909.19043,0.01844
59.25,3.01944,5826.79248,0.01843
59.35,3.011,5743.04785,0.01841
59.45,3.0025,5665.16553,0.0184
59.55,2.99456,5587.3418,0.01839
59.65,2.98631,5507.86523,0.01837
59.75,2.97762,5425.81104,0.01836
59.85,2.9695,5350.26318,0.01836
59.95,2.96106,5268.82471,0.01834
60.05,2.95262,5188.39209,0.01833
60.15,2.94437,5114.90674,0.01831
60.25,2.93625,5037.34766,0.0183
60.35,2.92794,4960.48389,0.01829
60.45,2.91937,4884.65234,0.01828
60.55,2.91125,4807.70264,0.01827
60.65,2.90269,4729.33154,0.01826
60.75,2.89419,4653.01514,0.01825
60.85,2.88606,4580.92725,0.01823
60.95,2.87769,4504.66553,0.01822
61.05,2.86944,4429.8501,0.01821
61.15,2.86112,4360.66357,0.0182
61.25,2.85287,4285.40869,0.01819
61.35,2.84444,4210.30469,0.01817
61.45,2.83587,4139.4165,0.01816
61.55,2.82775,4067.6438,0.01815
61.65,2.81931,3994.80884,0.01814
61.75,2.81094,3923.6062,0.01814
61.85,2.803,3858.35278,0.01812
61.95,2.79456,3785.68433,0.01811
62.05,2.78606,3712.45483,0.0181
62.15,2.77762,3645.84253,0.01809
62.25,2.76937,3576.9458,0.01808
62.35,2.761,3506.34985,0.01807
62.45,2.75256,3440.16187,0.01805
62.55,2.74456,3374.13281,0.01804
62.65,2.73625,3306.5415,0.01803
62.75,2.72756,3236.91284,0.01802
62.85,2.7195,3174.0293,0.01801
62.95,2.71112,3106.45801,0.018
63.05,2.70262,3038.40454,0.01798
63.15,2.69425,2977.06323,0.01798
63.25,2.68619,2912.63794,0.01797
63.35,2.67787,2848.82812,0.01796
63.45,2.66944,2787.95972,0.01794
63.55,2.66125,2725.00073,0.01793
63.65,2.65269,2660.16309,0.01792
63.75,2.64419,2598.33569,0.01791
63.85,2.636,2540.00732,0.0179
63.95,2.62775,2479.53638,0.01789
64.05,2.61944,2419.37329,0.01788
64.15,2.61112,2363.8877,0.01787
64.25,2.60287,2304.03052,0.01786
64.35,2.59437,2244.94092,0.01785
64.45,2.58581,2188.73267,0.01784
64.55,2.57781,2133.77002,0.01783
64.65,2.56931,2076.43237,0.01782
64.75,2.56094,2020.94336,0.01781
64.85,2.55294,1970.0874,0.0178
64.95,2.54456,1914.79675,0.01779
65.05,2.53606,1858.65149,0.01778
65.15,2.52762,1807.29443,0.01777
65.25,2.51937,1754.27026,0.01776
65.35,2.51094,1700.3324,0.01775
65.45,2.50244,1650.18164,0.01774
65.55,2.49462,1600.39221,0.01773
65.65,2.48625,1548.46497,0.01772
65.75,2.47756,1495.88672,0.01771
65.85,2.4695,1448.03687,0.0177
65.95,2.46106,1397.17017,0.0177
66.05,2.45262,1346.93982,0.01768
66.15,2.44437,1302.3075,0.01767
66.25,2.43625,1254.82434,0.01767
66.35,2.42787,1207.52075,0.01766
66.45,2.41937,1162.89099,0.01765
66.55,2.41125,1118.85095,0.01764
66.65,2.40275,1073.29407,0.01763
66.75,2.39425,1029.31628,0.01763
66.85,2.386,987.87311,0.01762
66.95,2.37762,945.41516,0.01761
67.05,2.36937,904.10822,0.0176
67.15,2.36119,866.85699,0.01759
67.25,2.35287,829.80182,0.01758
67.35,2.34437,793.11578,0.01758
67.45,2.33581,757.77808,0.01757
67.55,2.32775,723.7951,0.01756
67.65,2.31931,689.87842,0.01755
67.75,2.311,656.34985,0.01754
67.85,2.30294,626.09271,0.01753
67.95,2.29456,593.4552,0.01753
68.05,2.28606,559.37079,0.01752
68.15,2.27762,529.53168,0.0175
68.25,2.2695,500.06937,0.01749
68.35,2.261,470.49384,0.01748
68.45,2.25244,443.35245,0.01747
68.55,2.24456,419.01944,0.01746
68.65,2.23625,394.70987,0.01745
68.75,2.22762,370.22113,0.01744
68.85,2.2195,350.91153,0.01743
68.95,2.21106,330.52249,0.01742
69.05,2.20256,310.41568,0.01741
69.15,2.19425,294.29175,0.0174
69.25,2.18619,278.01642,0.01739
69.35,2.17794,262.27747,0.01738
69.45,2.16944,247.34598,0.01737
69.55,2.16125,233.26135,0.01736
69.65,2.15269,218.63808,0.01735
69.75,2.14419,204.99004,0.01735
69.85,2.13606,193.65823,0.01734
69.95,2.12775,181.54153,0.01733
70.05,2.11937,169.83835,0.01733
70.15,2.11106,159.47133,0.01732
70.25,2.10281,148.96143,0.01732
70.35,2.09437,139.3593,0.01732
70.45,2.08587,130.1718,0.01731
70.55,2.07775,122.20692,0.01731
70.65,2.06925,114.07211,0.01731
70.75,2.06094,102.98862,0.01731
70.85,2.05294,94.5194,0.0173
70.95,2.04456,82.63621,0.0173
71.05,2.03606,68.75095,0.0173
71.15,2.02756,56.79285,0.01729
71.25,2.01944,53.18102,0.01729
71.35,2.011,41.8435,0.01728
71.45,2.0025,27.61208,0.01727
71.55,1.99462,8.98563,0.01727
71.57,1.99294,4.75453,0.01726
71.572,1.99275,4.32046,0.01726
71.574,1.99256,3.88051,0.01726
71.654,1.99312,5.11247,0.01726