File: Material Science Data Analysis/Specimen_RawData_1_2.csv
Time (s),Extension (mm),Load (N),Tensile strain (mm/mm)
0,-0.00081,3.04628,0
0.3,0.02406,282.83347,0.00003
0.6,0.04937,409.99356,0.00002
0.9,0.07412,520.54688,0.00002
1.2,0.09925,634.59546,0.00003
1.5,0.12431,744.12231,0.00003
1.8,0.14931,853.14355,0.00004
2.1,0.17456,967.32245,0.00006
2.4,0.19944,1083.07996,0.00008
2.7,0.2245,1203.5498,0.00009
3,0.24931,1324.29297,0.00011
3.3,0.27431,1449.67993,0.00012
3.6,0.29937,1577.55127,0.00014
3.9,0.32419,1707.03564,0.00015
4.2,0.34931,1840.44312,0.00017
4.5,0.37431,1975.8562,0.00018
4.8,0.39925,2114.35938,0.0002
5.1,0.42456,2258.84326,0.00022
5.4,0.44944,2403.11987,0.00023
5.7,0.47444,2550.16357,0.00025
6,0.49937,2699.08594,0.00027
6.3,0.52419,2847.28784,0.0003
6.6,0.54937,3001.73193,0.00031
6.9,0.57412,3154.25854,0.00033
7.2,0.59931,3312.25439,0.00036
7.5,0.62431,3470.44507,0.00038
7.8,0.64931,3630.32104,0.0004
8.1,0.67456,3797.26733,0.00042
8.4,0.69937,3961.46289,0.00044
8.7,0.7245,4132.42139,0.00047
9,0.74925,4299.32617,0.00049
9.3,0.77425,4470.50049,0.00051
9.6,0.79931,4644.52295,0.00054
9.9,0.82419,4817.70312,0.00056
10.2,0.84931,4995.39697,0.00059
10.5,0.87425,5170.31152,0.00061
10.8,0.89937,5351.00684,0.00064
11.1,0.92444,5533.05469,0.00066
11.4,0.94944,5717.21484,0.00069
11.7,0.97437,5901.90332,0.00071
12,0.99931,6087.16064,0.00074
12.3,1.02425,6272.93164,0.00077
12.6,1.04937,6461.18066,0.0008
12.9,1.07425,6648.82861,0.00083
13.2,1.09931,6836.76611,0.00086
13.5,1.12431,7024.16992,0.00089
13.8,1.14925,7211.49902,0.00093
14.1,1.17456,7403.93555,0.00098
14.4,1.19931,7587.7085,0.00102
14.7,1.2245,7771.5835,0.0011
15,1.24931,7940.05225,0.0012
15.3,1.27425,8083.31543,0.00144
15.6,1.29944,8203.35254,0.00179
15.9,1.32412,8262.18555,0.00239
16.2,1.34937,8125.79248,0.00408
16.5,1.37425,8017.59277,0.00581
16.8,1.39937,8002.97021,0.00722
17.1,1.42456,8007.68652,0.00848
17.4,1.44944,8013.99951,0.00965
17.7,1.4745,8028.88867,0.01071
18,1.49931,8002.91211,0.01169
18.3,1.52431,7974.85938,0.01261
18.6,1.54931,7906.08398,0.01344
18.9,1.57425,7784.2832,0.01404
19.2,1.59919,7699.45752,0.01443
19.5,1.62437,7656.75098,0.01475
19.8,1.64931,7616.2832,0.01502
20.1,1.67456,7590.32764,0.01522
20.4,1.69944,7580.07178,0.01539
20.7,1.7245,7583.39111,0.01556
21,1.74937,7601.15771,0.01571
21.3,1.77419,7613.83984,0.01584
21.6,1.79937,7623.58105,0.016
21.9,1.82419,7610.68066,0.01619
22.2,1.84937,7596.18262,0.01639
22.5,1.87431,7593.17969,0.01661
22.8,1.89937,7608.35547,0.01683
23.1,1.92456,7643.18018,0.01707
23.4,1.94937,7664.5249,0.01729
23.7,1.97456,7692.1084,0.01747
24,1.99925,7703.25732,0.01758
24.3,2.02431,7717.7124,0.01762
24.6,2.04931,7728.51562,0.01757
24.9,2.07425,7729.73877,0.0175
25.2,2.09937,7726.46729,0.01749
25.5,2.12431,7712.18896,0.01751
25.8,2.14937,7711.78027,0.01753
26.1,2.17444,7728.31152,0.01753
26.4,2.19937,7765.01367,0.01754
26.7,2.22437,7800.58447,0.01757
27,2.24937,7821.85498,0.01763
27.3,2.27425,7840.25635,0.01769
27.6,2.29944,7858.49268,0.01778
27.9,2.32425,7871.71436,0.01787
28.2,2.34925,7887.1167,0.01796
28.5,2.37431,7885.83105,0.01806
28.8,2.39925,7855.68066,0.01813
29.1,2.42456,7875.99512,0.01822
29.4,2.44931,7962.14941,0.01834
29.7,2.4745,8030.46143,0.01851
30,2.49937,8071.57373,0.01871
30.3,2.52431,8104.36816,0.01892
30.6,2.54944,8136.48096,0.01913
30.9,2.57412,8162.05615,0.01935
31.2,2.59937,8193.49707,0.01958
31.5,2.62419,8217.20703,0.0198
31.768,2.6465,8243.29297,0.02
31.97,2.65087,8115.41064,0.02004
32.27,2.64969,7975.09766,0.02003
32.57,2.64912,7913.6582,0.02002
32.87,2.64906,7880.70117,0.02002
33.17,2.649,7857.96484,0.02002
33.47,2.649,7840.47412,0.02002
33.77,2.649,7826.37012,0.02002
34.07,2.649,7814.11621,0.02002
34.37,2.649,7803.89844,0.02002
34.67,2.649,7794.98877,0.02002
34.97,2.649,7786.5293,0.02002
35.27,2.649,7779.06055,0.02002
35.57,2.649,7772.62744,0.02002
35.87,2.649,7766.38818,0.02002
36.17,2.649,7760.66797,0.02002
36.47,2.649,7755.76758,0.02002
36.77,2.649,7750.88574,0.02002
37.07,2.649,7746.54834,0.02002
37.37,2.649,7742.27979,0.02002
37.67,2.649,7738.49268,0.02002
37.97,2.649,7734.74707,0.02002
38.27,2.649,7731.52344,0.02002
38.57,2.649,7728.03711,0.02002
38.87,2.649,7724.80957,0.02002
39.17,2.649,7722.0127,0.02002
39.47,2.649,7719.30566,0.02002
39.77,2.649,7716.60938,0.02002
40.07,2.649,7713.94385,0.02002
40.37,2.649,7711.62354,0.02002
40.67,2.649,7709.35498,0.02002
40.97,2.649,7707.11768,0.02002
41.27,2.649,7704.94189,0.02002
41.57,2.649,7702.68164,0.02002
41.87,2.649,7701.07275,0.02002
42.17,2.649,7699.24316,0.02002
42.47,2.649,7697.29785,0.02002
42.77,2.649,7695.44922,0.02002
43.07,2.649,7693.69824,0.02002
43.37,2.649,7691.98633,0.02002
43.67,2.649,7690.63818,0.02002
43.97,2.649,7688.91553,0.02002
44.27,2.649,7687.39209,0.02002
44.57,2.649,7686.08984,0.02002
44.87,2.649,7684.49512,0.02002
45.17,2.649,7682.62744,0.02002
45.47,2.649,7681.79004,0.02002
45.77,2.649,7679.8999,0.02002
46.07,2.649,7678.31934,0.02002
46.37,2.649,7676.92676,0.02002
46.67,2.649,7675.69385,0.02002
46.97,2.649,7673.94434,0.02002
47.27,2.649,7672.82715,0.02002
47.57,2.649,7671.41943,0.02002
47.87,2.649,7670.65527,0.02002
48.17,2.649,7670.97998,0.02002
48.47,2.649,7669.03516,0.02002
48.77,2.649,7668.00928,0.02002
49.07,2.649,7666.96875,0.02002
49.37,2.649,7666.23633,0.02002
49.67,2.649,7665.20068,0.02002
49.97,2.649,7664.41895,0.02002
50.27,2.649,7663.53223,0.02002
50.57,2.649,7662.62402,0.02002
50.87,2.649,7661.65869,0.02002
51.17,2.649,7661.01465,0.02002
51.47,2.649,7660.30615,0.02002
51.77,2.649,7659.66113,0.02002
52.07,2.649,7658.65381,0.02002
52.37,2.649,7657.84961,0.02002
52.67,2.649,7657.01318,0.02002
52.97,2.649,7656.47803,0.02002
53.27,2.649,7655.65771,0.02002
53.57,2.649,7654.75098,0.02002
53.87,2.649,7653.91797,0.02002
54.17,2.649,7653.1543,0.02002
54.47,2.649,7652.47119,0.02002
54.77,2.649,7651.98633,0.02002
55.07,2.649,7651.22705,0.02002
55.37,2.649,7650.69873,0.02002
55.67,2.649,7649.94678,0.02002
55.97,2.649,7649.29004,0.02002
56.27,2.649,7648.66016,0.02002
56.57,2.649,7647.94141,0.02002
56.754,2.6495,7648.06592,0.02002
57.054,2.67869,8167.38135,0.02025
57.354,2.70356,8315.1084,0.02045
57.654,2.72869,8352.07812,0.02065
57.954,2.75356,8369.45801,0.02084
58.254,2.77869,8394.26953,0.02104
58.554,2.80375,8417.13086,0.02124
58.854,2.82875,8442.62109,0.02144
59.154,2.85387,8472.2002,0.02163
59.454,2.87875,8494.20117,0.02183
59.754,2.90381,8522.79883,0.02203
60.054,2.92881,8544.0127,0.02222
60.354,2.95362,8567.5166,0.02242
60.654,2.97862,8592.70312,0.02262
60.954,3.00369,8615.05078,0.02281
61.254,3.02856,8639.40527,0.02301
61.554,3.05394,8663.07129,0.02321
61.854,3.07869,8687.90332,0.0234
62.154,3.10387,8714.30469,0.0236
62.454,3.12887,8738.53613,0.0238
62.754,3.15369,8761.42383,0.02399
63.054,3.17894,8785.45508,0.02419
63.354,3.2035,8802.99512,0.02439
63.654,3.22869,8830.09375,0.02459
63.954,3.25356,8848.57129,0.02478
64.254,3.27862,8871.45801,0.02498
64.554,3.30394,8896.36523,0.02518
64.854,3.32869,8915.20215,0.02537
65.154,3.35387,8943.32812,0.02557
65.454,3.37869,8960.78711,0.02577
65.754,3.40381,8986.47266,0.02596
66.054,3.42875,9005.29297,0.02616
66.354,3.45362,9024.56152,0.02636
66.654,3.47869,9050.03809,0.02655
66.954,3.50369,9065.91602,0.02675
67.254,3.52869,9090.68945,0.02695
67.554,3.55381,9107.52148,0.02715
67.854,3.57869,9130.66504,0.02734
68.154,3.60375,9153.10352,0.02754
68.454,3.62881,9173.5625,0.02774
68.754,3.65369,9194.74316,0.02793
69.054,3.67887,9213.89648,0.02813
69.354,3.70356,9231.98535,0.02832
69.654,3.72869,9253.94141,0.02852
69.954,3.75369,9272.51465,0.02872
70.254,3.77862,9290.57422,0.02892
70.554,3.80387,9311.58008,0.02911
70.854,3.82856,9329.4248,0.02931
71.154,3.85381,9353.11133,0.02951
71.454,3.87875,9371.47168,0.0297
71.754,3.90381,9391.79492,0.0299
72.054,3.92887,9411.50977,0.0301
72.354,3.95356,9425.64062,0.03029
72.654,3.97875,9449.3125,0.03049
72.954,4.00356,9461.35156,0.03069
73.254,4.02869,9481.79297,0.03088
73.554,4.05375,9498.59082,0.03108
73.854,4.07875,9517.70605,0.03128
74.154,4.10381,9539.58594,0.03148
74.454,4.12881,9555.02441,0.03167
74.754,4.15381,9576.51074,0.03187
75.054,4.17881,9590.91113,0.03207
75.354,4.20362,9607.10547,0.03226
75.654,4.22862,9624.61133,0.03246
75.954,4.25369,9639.62793,0.03266
76.254,4.27862,9657.61133,0.03285
76.554,4.30387,9672.46777,0.03305
76.854,4.32869,9691.05566,0.03325
77.154,4.35387,9710.48145,0.03344
77.454,4.37881,9727.05078,0.03364
77.754,4.40362,9742.6709,0.03384
78.054,4.42894,9760.84277,0.03404
78.354,4.4535,9770.98535,0.03423
78.654,4.47869,9791.7041,0.03443
78.954,4.50356,9803.25391,0.03462
79.254,4.52869,9820.01465,0.03482
79.554,4.55387,9836.51465,0.03502
79.854,4.57862,9849.63672,0.03521
80.154,4.60394,9871.66797,0.03541
80.454,4.62869,9883.93164,0.03561
80.754,4.65381,9902.02441,0.03581
81.054,4.67881,9915.76562,0.036
81.354,4.70362,9927.75195,0.0362
81.654,4.72869,9946.58496,0.0364
81.954,4.75362,9955.86523,0.03659
82.254,4.77862,9972.9541,0.03679
82.554,4.80375,9985.47266,0.03699
82.854,4.82875,10002.35254,0.03718
83.154,4.85381,10019.17676,0.03738
83.454,4.87887,10033.0625,0.03758
83.754,4.90369,10048.50586,0.03777
84.054,4.92894,10061.7832,0.03797
84.354,4.95356,10073.8418,0.03817
84.654,4.97869,10089.16699,0.03836
84.954,5.00369,10101.72656,0.03856
85.254,5.02862,10113.89746,0.03876
85.554,5.05394,10129.53418,0.03896
85.854,5.07862,10140.28418,0.03915
86.154,5.10387,10159.06348,0.03935
86.454,5.12875,10171.0332,0.03955
86.754,5.15381,10186.15723,0.03974
87.054,5.17887,10200.05859,0.03994
87.354,5.20356,10208.10352,0.04014
87.654,5.22869,10225.85547,0.04033
87.954,5.25356,10233.86914,0.04053
88.254,5.27875,10248.56641,0.04073
88.554,5.30375,10259.09082,0.04092
88.854,5.32875,10272.92676,0.04112
89.154,5.35387,10290.39355,0.04132
89.454,5.37875,10300.35059,0.04151
89.754,5.40381,10316.49707,0.04171
90.054,5.42887,10325.93945,0.04191
90.354,5.45356,10337.30762,0.0421
90.654,5.47862,10350.81738,0.0423
90.954,5.50369,10360.1416,0.0425
91.254,5.52856,10372.20312,0.04269
91.554,5.55387,10384.5332,0.04289
91.854,5.57869,10397.70215,0.04309
92.154,5.60387,10412.97168,0.04329
92.454,5.62881,10423.91211,0.04348
92.754,5.65369,10435.94238,0.04368
93.054,5.67894,10448.03223,0.04388
93.354,5.70356,10455.80176,0.04407
93.654,5.72875,10469.77832,0.04427
93.954,5.75356,10478.01562,0.04447
94.254,5.77869,10489.85645,0.04466
94.554,5.80387,10502.22754,0.04486
94.854,5.82869,10511.35254,0.04506
95.154,5.85387,10528.07129,0.04526
95.454,5.87875,10536.3252,0.04545
95.754,5.90381,10549.98145,0.04565
96.054,5.92881,10559.44727,0.04585
96.354,5.95362,10567.74121,0.04604
96.654,5.97869,10581.62402,0.04624
96.954,6.00362,10587.82715,0.04644
97.254,6.02869,10601.42188,0.04663
97.554,6.05381,10609.23242,0.04683
97.854,6.07875,10622.30957,0.04703
98.154,6.10375,10634.62598,0.04722
98.454,6.12881,10644.29199,0.04742
98.754,6.15369,10656.23535,0.04762
99.054,6.17894,10665.89453,0.04782
99.354,6.20356,10674.14551,0.04801
99.654,6.22869,10685.875,0.04821
99.954,6.25369,10694.04395,0.0484
100.254,6.27862,10703.05762,0.0486
100.554,6.30394,10713.84668,0.0488
100.854,6.32856,10722.01465,0.04899
101.154,6.35394,10737.59082,0.04919
101.454,6.37869,10745.71191,0.04939
101.754,6.40381,10756.62598,0.04959
102.054,6.42887,10766.93164,0.04978
102.354,6.45356,10771.54492,0.04998
102.654,6.47875,10786.41406,0.05018
102.954,6.5035,10788.50879,0.05037
103.254,6.52869,10801.30762,0.05057
103.554,6.55375,10808.95508,0.05077
103.854,6.57875,10818.57227,0.05096
104.154,6.60381,10832.66895,0.05116
104.454,6.62881,10839.00293,0.05136
104.754,6.65381,10851.7793,0.05155
105.054,6.67887,10858.16699,0.05175
105.354,6.70369,10865.70703,0.05195
105.654,6.72862,10875.33789,0.05214
105.954,6.75362,10880.89746,0.05234
106.254,6.77862,10891.36133,0.05254
106.554,6.80387,10898.75391,0.05274
106.854,6.82862,10908.29004,0.05293
107.154,6.85387,10919.86035,0.05313
107.454,6.87881,10928.01367,0.05333
107.754,6.90369,10936.88965,0.05352
108.054,6.92894,10945.92383,0.05372
108.354,6.9535,10949.55566,0.05391
108.654,6.97869,10961.48242,0.05411
108.954,7.00362,10966.0166,0.05431
109.254,7.02869,10973.91309,0.05451
109.554,7.05387,10983.43164,0.0547
109.854,7.07869,10989.97949,0.0549
110.154,7.10394,11003.52344,0.0551
110.454,7.12869,11007.21387,0.05529
110.754,7.15381,11019.16309,0.05549
111.054,7.17881,11024.49414,0.05569
111.354,7.20362,11030.03418,0.05588
111.654,7.22869,11041.90332,0.05608
111.954,7.25362,11043.94336,0.05628
112.254,7.27869,11054.6582,0.05647
112.554,7.30381,11059.27051,0.05667
112.854,7.32875,11068.81055,0.05687
113.154,7.35381,11078.8125,0.05707
113.454,7.37881,11084.99316,0.05726
113.754,7.40369,11094.39648,0.05746
114.054,7.42894,11100.37305,0.05766
114.354,7.45362,11107.37988,0.05785
114.654,7.47869,11114.57129,0.05805
114.954,7.50369,11119.76465,0.05825
115.254,7.52862,11125.84863,0.05844
115.554,7.55394,11134.21875,0.05864
115.854,7.57856,11139.71777,0.05884
116.154,7.60394,11151.74121,0.05904
116.454,7.62875,11157.63477,0.05923
116.754,7.65381,11165.24219,0.05943
117.054,7.67894,11173.77148,0.05963
117.354,7.70356,11174.7373,0.05982
117.654,7.72875,11186.70215,0.06002
117.954,7.75356,11187.41113,0.06021
118.254,7.77869,11197.02148,0.06041
118.554,7.80375,11201.67676,0.06061
118.854,7.82875,11208.99023,0.06081
119.154,7.85387,11220.93457,0.061
119.454,7.87881,11224.48242,0.0612
119.754,7.90381,11234.71289,0.0614
120.054,7.92881,11237.80566,0.06159
120.354,7.95362,11243.29102,0.06179
120.654,7.97856,11250.56641,0.06199
120.954,8.00369,11254.9248,0.06218
121.254,8.02862,11261.69824,0.06238
121.554,8.05387,11267.40527,0.06258
121.854,8.07869,11275.30469,0.06277
122.154,8.10381,11283.74023,0.06297
122.454,8.12881,11290.24902,0.06317
122.754,8.15369,11296.57812,0.06336
123.054,8.17894,11303.23242,0.06356
123.354,8.2035,11304.44922,0.06376
123.654,8.22869,11314.11523,0.06396
123.954,8.25362,11317.01465,0.06415
124.254,8.27869,11323.30762,0.06435
124.554,8.30394,11330.9082,0.06455
124.854,8.32862,11333.72168,0.06474
125.154,8.35394,11346.90039,0.06494
125.454,8.37869,11348.49512,0.06514
125.754,8.40381,11357.62891,0.06533
126.054,8.42881,11361.2373,0.06553
126.354,8.45362,11363.97363,0.06573
126.654,8.47869,11373.95801,0.06592
126.954,8.50362,11374.14453,0.06612
127.254,8.52875,11382.72656,0.06632
127.554,8.55375,11385.27734,0.06651
127.854,8.57875,11393.08496,0.06671
128.154,8.60381,11400.74609,0.06691
128.454,8.62881,11404.86816,0.06711
128.754,8.65369,11412.81836,0.0673
129.054,8.67894,11416.65625,0.0675
129.354,8.70356,11421.08398,0.06769
129.654,8.72869,11427.22363,0.06789
129.954,8.75369,11431.15723,0.06809
130.254,8.77856,11434.78418,0.06828
130.554,8.80394,11441.4248,0.06848
130.854,8.82856,11444.6875,0.06868
131.154,8.85394,11455.33203,0.06888
131.454,8.87875,11459.06934,0.06907
131.754,8.90381,11465.66602,0.06927
132.054,8.92894,11471.33301,0.06947
132.354,8.95356,11470.53223,0.06966
132.654,8.97875,11481.33105,0.06986
132.954,9.00356,11479.9668,0.07006
133.254,9.02869,11487.17188,0.07025
133.554,9.05375,11490.49902,0.07045
133.854,9.07875,11496.38672,0.07065
134.154,9.10387,11506.05762,0.07085
134.454,9.12881,11507.44531,0.07104
134.754,9.15381,11517.11328,0.07124
135.054,9.17881,11517.625,0.07144
135.354,9.20369,11521.9541,0.07163
135.654,9.22856,11526.78027,0.07183
135.954,9.25369,11529.1748,0.07203
136.254,9.27862,11534.75,0.07222
136.554,9.30387,11537.99414,0.07242
136.854,9.32869,11544.77051,0.07262
137.154,9.35387,11551.35156,0.07282
137.454,9.37881,11556.23242,0.07301
137.754,9.40362,11560.50293,0.07321
138.054,9.42894,11565.75,0.07341
138.354,9.4535,11565.16406,0.0736
138.654,9.47869,11573.27344,0.0738
138.954,9.50356,11574.72949,0.07399
139.254,9.52869,11579.44141,0.07419
139.554,9.55387,11584.69727,0.07439
139.854,9.57869,11587.19141,0.07459
140.154,9.60387,11597.18359,0.07478
140.454,9.62862,11596.9541,0.07498
140.754,9.65381,11605.57324,0.07518
141.054,9.67881,11607.63672,0.07537
141.354,9.70362,11608.41699,0.07557
141.654,9.72869,11617.11328,0.07577
141.954,9.75369,11615.83887,0.07596
142.254,9.77875,11622.82031,0.07616
142.554,9.80381,11624.41992,0.07636
142.854,9.82875,11630.09668,0.07655
143.154,9.85375,11636.00195,0.07675
143.454,9.87887,11639.81641,0.07695
143.754,9.90369,11645.58203,0.07714
144.054,9.92887,11647.45703,0.07734
144.354,9.95356,11650.39258,0.07754
144.654,9.97869,11655.01367,0.07773
144.954,10.00362,11657.30566,0.07793
145.254,10.02862,11660.27344,0.07813
145.554,10.05394,11665.14844,0.07833
145.854,10.07862,11667.11426,0.07852
146.154,10.10394,11675.92969,0.07872
146.454,10.12875,11678.14062,0.07892
146.754,10.15375,11683.14258,0.07911
147.054,10.17894,11687.48633,0.07931
147.354,10.20356,11686.33887,0.07951
147.654,10.22875,11694.5459,0.0797
147.954,10.25356,11692.38379,0.0799
148.254,10.27869,11698.15625,0.0801
148.554,10.30375,11700.35742,0.08029
148.854,10.32868,11704.25195,0.08049
149.154,10.35387,11713.08789,0.08069
149.454,10.37881,11713.17676,0.08089
149.754,10.40381,11720.51758,0.08108
150.054,10.42881,11720.93555,0.08128
150.354,10.45362,11723.52051,0.08147
150.654,10.47856,11726.99219,0.08167
150.954,10.50368,11728.07324,0.08187
151.254,10.52862,11732.69629,0.08207
151.554,10.55387,11735.04297,0.08226
151.854,10.57869,11739.83691,0.08246
152.154,10.60387,11745.59082,0.08266
152.454,10.62881,11749.25293,0.08285
152.754,10.65375,11752.9209,0.08305
153.054,10.67894,11756.16602,0.08325
153.354,10.7035,11755.00391,0.08344
153.654,10.72875,11761.74609,0.08364
153.954,10.75356,11761.07227,0.08384
154.254,10.77869,11764.78711,0.08403
154.554,10.80387,11769.37695,0.08423
154.854,10.82868,11770.74121,0.08443
155.154,10.85394,11779.55859,0.08463
155.454,10.87869,11778.30273,0.08482
155.754,10.90375,11784.86523,0.08502
156.054,10.92881,11786.22363,0.08522
156.354,10.95362,11786.6084,0.08541
156.654,10.97862,11792.56445,0.08561
156.954,11.00369,11791.18066,0.08581
157.254,11.02875,11797.12793,0.086
157.554,11.05381,11797.46875,0.0862
157.854,11.07875,11802.48242,0.0864
158.154,11.10375,11807.24316,0.08659
158.454,11.12881,11809.45117,0.08679
158.754,11.15369,11813.97754,0.08699
159.054,11.17887,11815.30566,0.08719
159.354,11.20356,11816.62891,0.08738
159.654,11.22869,11820.48145,0.08758
159.954,11.25368,11821.6709,0.08777
160.254,11.27862,11823.89258,0.08797
160.554,11.30394,11827.47852,0.08817
160.854,11.32862,11829.00977,0.08836
161.154,11.35394,11835.98828,0.08856
161.454,11.37875,11837.43457,0.08876
161.754,11.40381,11841.50391,0.08896
162.054,11.42887,11844.38281,0.08915
162.354,11.45356,11842.58398,0.08935
162.654,11.47875,11849.66016,0.08955
162.954,11.50356,11846.79785,0.08974
163.254,11.52868,11851.08203,0.08994
163.554,11.55381,11852.51953,0.09014
163.854,11.57869,11855.47266,0.09033
164.154,11.60381,11863.375,0.09053
164.454,11.62881,11863.21191,0.09073
164.754,11.65381,11869.45312,0.09092
165.054,11.67881,11868.15918,0.09112
165.354,11.70362,11869.7002,0.09132
165.654,11.72856,11872.6377,0.09151
165.954,11.75362,11872.0791,0.09171
166.254,11.77862,11876.45898,0.09191
166.554,11.80387,11877.53125,0.09211
166.854,11.82869,11881.92188,0.0923
167.154,11.85387,11886.7998,0.0925
167.454,11.87881,11888.57812,0.0927
167.754,11.90369,11890.85645,0.09289
168.054,11.92894,11894.13184,0.09309
168.354,11.9535,11892.00391,0.09328
168.654,11.97875,11897.88477,0.09348
168.954,12.00362,11897.14551,0.09368
169.254,12.02875,11899.90527,0.09388
169.554,12.05387,11903.25684,0.09407
169.854,12.07875,11904.00684,0.09427
170.154,12.10394,11912.08691,0.09447
170.454,12.12869,11909.72656,0.09466
170.754,12.15381,11915.76074,0.09486
171.054,12.17875,11915.23242,0.09506
171.354,12.20356,11914.8877,0.09525
171.654,12.22869,11920.62109,0.09545
171.954,12.25369,11918.22656,0.09565
172.254,12.27869,11924.05371,0.09585
172.554,12.30375,11922.43945,0.09604
172.854,12.32868,11926.14844,0.09624
173.154,12.35375,11930.80273,0.09644
173.454,12.37881,11931.56641,0.09663
173.754,12.40369,11936.53906,0.09683
174.054,12.42894,11937.25977,0.09703
174.354,12.45356,11936.44824,0.09722
174.654,12.47869,11940.7168,0.09742
174.954,12.50362,11940.50293,0.09762
175.254,12.52862,11941.74512,0.09781
175.554,12.55394,11944.22363,0.09801
175.854,12.57862,11945.36133,0.09821
176.154,12.60387,11951.07129,0.09841
176.454,12.62875,11952.20215,0.0986
176.754,12.65381,11955.05273,0.0988
177.054,12.67894,11958.14453,0.099
177.354,12.70362,11956.09473,0.09919
177.654,12.72869,11960.3584,0.09939
177.954,12.75356,11958.23535,0.09958
178.254,12.77875,11962.44336,0.09978
178.554,12.80375,11962.03418,0.09998
178.854,12.82875,11964.95312,0.10018
179.154,12.85387,11971.58398,0.10037
179.454,12.87881,11970.19336,0.10057
179.754,12.90381,11975.88184,0.10077
180.054,12.92881,11973.89062,0.10096
180.354,12.95362,11974.80566,0.10116
180.654,12.97862,11977.58398,0.10136
180.954,13.00369,11976.65332,0.10155
181.254,13.02862,11980.25977,0.10175
181.554,13.05387,11980.28027,0.10195
181.854,13.07868,11983.49707,0.10214
182.154,13.10381,11987.58398,0.10234
182.454,13.12887,11990.33105,0.10254
182.754,13.15369,11990.55273,0.10273
183.054,13.17894,11993.42188,0.10293
183.354,13.2035,11990.80664,0.10313
183.654,13.22869,11995.0127,0.10333
183.954,13.25356,11993.92383,0.10352
184.254,13.27869,11995.84375,0.10372
184.554,13.30394,11999.70508,0.10392
184.854,13.32862,11998.18555,0.10411
185.154,13.35394,12006.18262,0.10431
185.454,13.37869,12003.2998,0.10451
185.754,13.40381,12008.6709,0.1047
186.054,13.42881,12008.17188,0.1049
186.354,13.45362,12007.19141,0.1051
186.654,13.47869,12012.0625,0.10529
186.954,13.50362,12008.3457,0.10549
187.254,13.52868,12013.45801,0.10569
187.554,13.55381,12011.48535,0.10589
187.854,13.57875,12015.22852,0.10608
188.154,13.60375,12018.82129,0.10628
188.454,13.62881,12019.69434,0.10648
188.754,13.65369,12023.35254,0.10667
189.054,13.67894,12023.14453,0.10687
189.354,13.70356,12023.0918,0.10706
189.654,13.72869,12025.29102,0.10726
189.954,13.75369,12024.83301,0.10746
190.254,13.77856,12024.85449,0.10766
190.554,13.80387,12027.60156,0.10785
190.854,13.82862,12027.71289,0.10805
191.154,13.85387,12033.45801,0.10825
191.454,13.87875,12033.62988,0.10844
191.754,13.90381,12036.83008,0.10864
192.054,13.92887,12037.91602,0.10884
192.354,13.95362,12034.91797,0.10903
192.654,13.97875,12040.29395,0.10923
192.954,14.00356,12035.68066,0.10943
193.254,14.02869,12039.83691,0.10962
193.554,14.05375,12039.49512,0.10982
193.854,14.07875,12041.80469,0.11002
194.154,14.10381,12047.21289,0.11022
194.454,14.12881,12046.38477,0.11041
194.754,14.15381,12050.97559,0.11061
195.054,14.17887,12049.60156,0.11081
195.354,14.20362,12048.70312,0.111
195.654,14.22856,12050.53418,0.1112
195.954,14.25369,12049.37891,0.1114
196.254,14.27856,12051.28809,0.11159
196.554,14.30387,12052.17383,0.11179
196.854,14.32869,12054.6709,0.11199
197.154,14.35381,12057.99316,0.11218
197.454,14.37881,12059.74414,0.11238
197.754,14.40362,12060.22754,0.11258
198.054,14.42894,12061.82129,0.11278
198.354,14.4535,12059.30176,0.11297
198.654,14.47875,12063.22656,0.11317
198.954,14.50362,12061.19922,0.11336
199.254,14.52869,12063.01758,0.11356
199.554,14.55387,12064.96973,0.11376
199.854,14.57862,12063.98145,0.11395
200.154,14.60394,12071.38867,0.11415
200.454,14.62868,12068.49805,0.11435
200.754,14.65381,12073.0791,0.11455
201.054,14.67881,12072.34277,0.11474
201.354,14.70362,12069.97559,0.11494
201.654,14.72869,12075.26855,0.11514
201.954,14.75362,12071.32422,0.11533
202.254,14.77868,12075.83691,0.11553
202.554,14.80381,12073.79688,0.11573
202.854,14.82875,12076.30957,0.11592
203.154,14.85375,12079.74219,0.11612
203.454,14.87881,12079.74609,0.11632
203.754,14.90368,12082.56934,0.11651
204.054,14.92894,12082.73535,0.11671
204.354,14.95362,12082.20703,0.11691
204.654,14.97869,12084.01562,0.1171
204.954,15.00362,12082.97852,0.1173
205.254,15.02856,12082.89453,0.1175
205.554,15.05394,12084.74219,0.1177
205.854,15.07856,12084.25879,0.11789
206.154,15.10394,12090.17188,0.11809
206.454,15.12868,12089.8252,0.11829
206.754,15.15381,12092.77539,0.11848
207.054,15.17894,12093.40625,0.11868
207.354,15.20356,12089.78027,0.11888
207.654,15.22869,12094.0293,0.11907
207.954,15.25356,12090.11035,0.11927
208.254,15.27869,12092.99121,0.11947
208.554,15.30375,12092.74414,0.11966
208.854,15.32875,12094.10156,0.11986
209.154,15.35387,12099.20703,0.12006
209.454,15.37881,12097.83887,0.12026
209.754,15.40381,12102.44531,0.12045
210.054,15.42881,12099.43457,0.12065
210.354,15.45362,12099.99512,0.12084
210.654,15.47856,12100.91504,0.12104
210.954,15.50368,12099.28809,0.12124
211.254,15.52862,12101.10938,0.12144
211.554,15.55394,12101.24414,0.12163
211.854,15.57869,12102.96387,0.12183
212.154,15.60387,12106.9375,0.12203
212.454,15.62881,12106.79883,0.12222
212.754,15.65368,12108.31445,0.12242
213.054,15.67894,12109.03613,0.12262
213.354,15.70343,12105.75781,0.12281
213.654,15.72868,12109.20703,0.12301
213.954,15.75356,12107.52246,0.12321
214.254,15.77868,12108.52344,0.1234
214.554,15.80394,12110.79785,0.1236
214.854,15.82868,12109.64062,0.1238
215.154,15.85393,12115.29395,0.124
215.454,15.87868,12112.5918,0.12419
215.754,15.90375,12116.26172,0.12439
216.054,15.92875,12115.45215,0.12459
216.354,15.95362,12112.72559,0.12478
216.654,15.97868,12118.06055,0.12498
216.954,16.00368,12114.16504,0.12518
217.254,16.02875,12116.6084,0.12537
217.554,16.05381,12114.55176,0.12557
217.854,16.07875,12117.31348,0.12577
218.154,16.10375,12119.85742,0.12596
218.454,16.12881,12120.14746,0.12616
218.754,16.15368,12122.40625,0.12636
219.054,16.17893,12121.4375,0.12656
219.354,16.20362,12121.25977,0.12675
219.654,16.22869,12122.02637,0.12695
219.954,16.25368,12121.10254,0.12714
220.254,16.27862,12120.9502,0.12734
220.554,16.30393,12122.64258,0.12754
220.854,16.32862,12121.48438,0.12773
221.154,16.35387,12126.45312,0.12793
221.454,16.37875,12126.08496,0.12813
221.754,16.40381,12128.24609,0.12833
222.054,16.42893,12129.10449,0.12852
222.354,16.45356,12124.77344,0.12872
222.654,16.47875,12129.94043,0.12892
222.954,16.5035,12124.38672,0.12911
223.254,16.52875,12127.54785,0.12931
223.554,16.55375,12126.70605,0.12951
223.854,16.57875,12127.50195,0.1297
224.154,16.60381,12132.27441,0.1299
224.454,16.62881,12130.58887,0.1301
224.754,16.65375,12134.2998,0.13029
225.054,16.67881,12132.07812,0.13049
225.354,16.70362,12130.87988,0.13069
225.654,16.72856,12132.69336,0.13088
225.954,16.75368,12129.8877,0.13108
226.254,16.77862,12132.1123,0.13128
226.554,16.80394,12131.38281,0.13148
226.854,16.82868,12133.16699,0.13167
227.154,16.85387,12135.44336,0.13187
227.454,16.87881,12136.64258,0.13207
227.754,16.90362,12136.42871,0.13226
228.054,16.92894,12137.52441,0.13246
228.354,16.95343,12133.37207,0.13265
228.654,16.97869,12136.8584,0.13285
228.954,17.00362,12134.60938,0.13305
229.254,17.02868,12135.35645,0.13325
229.554,17.05393,12136.75684,0.13345
229.854,17.07868,12135.42383,0.13364
230.154,17.10394,12141.65723,0.13384
230.454,17.12868,12137.45703,0.13403
230.754,17.15381,12141.25195,0.13423
231.054,17.17875,12139.91309,0.13443
231.354,17.20362,12137.89258,0.13462
231.654,17.22869,12141.75781,0.13482
231.954,17.25362,12136.73535,0.13502
232.254,17.27875,12140.64551,0.13522
232.554,17.30381,12138.23828,0.13541
232.854,17.32875,12140.0459,0.13561
233.154,17.35381,12142.29492,0.13581
233.454,17.37881,12141.70508,0.136
233.754,17.40368,12143.73438,0.1362
234.054,17.42887,12142.59375,0.1364
234.354,17.45356,12142.61328,0.13659
234.654,17.47868,12142.64355,0.13679
234.954,17.50368,12142.10352,0.13699
235.254,17.52856,12140.875,0.13718
235.554,17.55387,12142.43359,0.13738
235.854,17.57856,12141.31055,0.13758
236.154,17.60393,12145.66895,0.13778
236.454,17.62868,12144.45801,0.13797
236.754,17.65381,12146.12695,0.13817
237.054,17.67887,12146.82422,0.13837
237.354,17.70356,12143.0127,0.13856
237.654,17.72875,12146.62109,0.13876
237.954,17.7535,12141.01953,0.13895
238.254,17.77875,12144.37402,0.13915
238.554,17.80375,12142.86621,0.13935
238.854,17.82875,12143.42773,0.13955
239.154,17.85381,12147.99316,0.13974
239.454,17.87875,12145.23438,0.13994
239.754,17.90381,12150.28223,0.14014
240.054,17.92881,12146.30273,0.14033
240.354,17.95362,12145.25293,0.14053
240.654,17.97862,12146.08594,0.14073
240.954,18.00368,12143.99316,0.14092
241.254,18.02862,12145.40527,0.14112
241.554,18.05393,12144.54102,0.14132
241.854,18.07869,12146.03906,0.14151
242.154,18.10387,12148.64746,0.14171
242.454,18.12887,12148.84473,0.14191
242.754,18.15368,12148.41797,0.1421
243.054,18.17893,12149.14941,0.1423
243.354,18.2035,12145.17383,0.1425
243.654,18.22869,12147.4043,0.1427
243.954,18.25356,12145.04004,0.14289
244.254,18.27868,12145.80859,0.14309
244.554,18.30393,12146.9209,0.14329
244.854,18.32869,12145.38379,0.14348
245.154,18.35387,12150.57227,0.14368
245.454,18.37868,12146.80566,0.14388
245.754,18.40381,12150.37402,0.14407
246.054,18.42881,12148.51074,0.14427
246.354,18.45356,12145.22461,0.14447
246.654,18.47868,12149.77344,0.14466
246.954,18.50362,12144.57812,0.14486
247.254,18.52868,12147.48242,0.14506
247.554,18.55381,12145.29395,0.14526
247.854,18.57875,12147.0957,0.14545
248.154,18.60375,12148.36621,0.14565
248.454,18.62881,12147.86133,0.14585
248.754,18.65368,12149.70215,0.14604
249.054,18.67894,12148.30371,0.14624
249.354,18.70356,12147.25195,0.14643
249.654,18.72869,12147.52539,0.14663
249.954,18.75368,12146.02246,0.14683
250.254,18.77856,12145.07129,0.14703
250.554,18.80387,12145.71289,0.14722
250.854,18.82862,12144.9043,0.14742
251.154,18.85394,12148.79199,0.14762
251.454,18.87875,12147.9873,0.14781
251.754,18.90381,12148.81055,0.14801
252.054,18.92893,12149.37598,0.14821
252.354,18.95356,12144.13477,0.1484
252.654,18.97875,12148.82324,0.1486
252.954,19.0035,12142.39355,0.1488
253.254,19.02875,12145.50684,0.149
253.554,19.05381,12143.72559,0.14919
253.854,19.07869,12143.67578,0.14939
254.154,19.10381,12148.78516,0.14959
254.454,19.12881,12145.89746,0.14978
254.754,19.15381,12149.79883,0.14998
255.054,19.17881,12145.85449,0.15018
255.354,19.20362,12144.76074,0.15037
255.654,19.22856,12144.87891,0.15057
255.954,19.25368,12142.81934,0.15077
256.254,19.27862,12143.7627,0.15096
256.554,19.30393,12142.25781,0.15116
256.854,19.32869,12143.87891,0.15136
257.154,19.35387,12145.81445,0.15156
257.454,19.37887,12145.84961,0.15175
257.754,19.40368,12145.31934,0.15195
258.054,19.42893,12145.64746,0.15215
258.354,19.4535,12141.19922,0.15234
258.654,19.47868,12144.24121,0.15254
258.954,19.50362,12141.31348,0.15273
259.254,19.52868,12141.34473,0.15293
259.554,19.55394,12142.59082,0.15313
259.854,19.57868,12140.17676,0.15333
260.154,19.60393,12145.40527,0.15352
260.454,19.62868,12141.85645,0.15372
260.754,19.65381,12144.08496,0.15392
261.054,19.67875,12141.62402,0.15411
261.354,19.70362,12139.2627,0.15431
261.654,19.72868,12142.82422,0.15451
261.954,19.75362,12137.82031,0.1547
262.254,19.77875,12140.62012,0.1549
262.554,19.80381,12137.09863,0.1551
262.854,19.82875,12138.98535,0.15529
263.154,19.85375,12140.92285,0.15549
263.454,19.87881,12139.59961,0.15569
263.754,19.90368,12140.90137,0.15588
264.054,19.92893,12139.40332,0.15608
264.354,19.95362,12137.69336,0.15628
264.654,19.97869,12138.56738,0.15647
264.954,20.00368,12136.79883,0.15667
265.254,20.02862,12135.59473,0.15687
265.554,20.05393,12136.02246,0.15707
265.854,20.07856,12134.05762,0.15726
266.154,20.10387,12138.25488,0.15746
266.454,20.12868,12136.80176,0.15766
266.754,20.15381,12137.76367,0.15785
267.054,20.17887,12137.17773,0.15805
267.354,20.20356,12132.59766,0.15825
267.654,20.22868,12136.51758,0.15844
267.954,20.25349,12130.78613,0.15864
268.254,20.27875,12133.56055,0.15884
268.554,20.30375,12131.09375,0.15903
268.854,20.32874,12130.87988,0.15923
269.154,20.35381,12134.96582,0.15943
269.454,20.37881,12132.12598,0.15963
269.754,20.40381,12135.93262,0.15982
270.054,20.42887,12131.99609,0.16002
270.354,20.45368,12131.04102,0.16022
270.654,20.47856,12130.49414,0.16041
270.954,20.50368,12127.86719,0.16061
271.254,20.52862,12128.8623,0.16081
271.554,20.55394,12126.88086,0.161
271.854,20.57868,12128.1582,0.1612
272.154,20.60387,12130.33496,0.1614
272.454,20.62881,12129.72266,0.16159
272.754,20.65375,12129.93457,0.16179
273.054,20.67894,12129.15918,0.16199
273.354,20.7035,12124.65234,0.16218
273.654,20.72869,12127.04297,0.16238
273.954,20.75356,12123.37109,0.16258
274.254,20.77868,12123.62988,0.16277
274.554,20.80387,12124.28418,0.16297
274.854,20.82868,12122.07227,0.16317
275.154,20.85387,12126.61816,0.16337
275.454,20.87868,12122.81934,0.16356
275.754,20.90381,12125.58887,0.16376
276.054,20.92881,12122.93164,0.16396
276.354,20.95362,12120.24805,0.16415
276.654,20.97869,12122.5166,0.16435
276.954,21.00368,12118.02051,0.16455
277.254,21.02868,12119.48145,0.16474
277.554,21.05381,12117.21289,0.16494
277.854,21.07875,12118.41699,0.16514
278.154,21.10375,12119.33105,0.16533
278.454,21.12881,12118.4834,0.16553
278.754,21.15368,12119.37109,0.16573
279.054,21.17893,12117.35938,0.16593
279.354,21.20356,12115.22266,0.16612
279.654,21.22875,12116.56445,0.16632
279.954,21.25368,12113.89648,0.16651
280.254,21.27856,12112.75195,0.16671
280.554,21.30393,12112.7832,0.16691
280.854,21.32862,12111.09961,0.1671
281.154,21.35387,12114.01758,0.1673
281.454,21.37874,12112.38281,0.1675
281.754,21.40375,12112.82129,0.1677
282.054,21.42881,12112.5293,0.16789
282.354,21.45356,12108.10352,0.16809
282.654,21.47875,12110.8916,0.16829
282.954,21.50356,12105.61621,0.16848
283.254,21.52875,12107.16797,0.16868
283.554,21.55381,12104.72852,0.16888
283.854,21.57868,12104.08105,0.16907
284.154,21.60381,12108.10645,0.16927
284.454,21.62875,12104.71191,0.16947
284.754,21.65381,12107.32031,0.16966
285.054,21.67887,12104.43848,0.16986
285.354,21.70362,12101.73438,0.17006
285.654,21.72862,12102.02539,0.17025
285.954,21.75368,12098.43848,0.17045
286.254,21.77862,12099.73145,0.17065
286.554,21.80387,12097.39258,0.17085
286.854,21.82869,12098.86621,0.17104
287.154,21.85387,12099.61816,0.17124
287.454,21.87881,12099.38184,0.17144
287.754,21.90368,12098.09375,0.17163
288.054,21.92893,12098.04297,0.17183
288.354,21.95343,12092.9043,0.17202
288.654,21.97875,12095.04199,0.17222
288.954,22.00356,12091.26074,0.17242
289.254,22.02868,12090.82617,0.17262
289.554,22.05387,12090.87305,0.17281
289.854,22.07869,12088.36328,0.17301
290.154,22.10387,12093.17969,0.17321
290.454,22.12875,12089.22559,0.1734
290.754,22.15381,12091.35742,0.1736
291.054,22.17881,12087.89844,0.1738
291.354,22.20368,12085.43945,0.17399
291.654,22.22868,12087.48633,0.17419
291.954,22.25368,12081.67188,0.17439
292.254,22.27875,12084.31934,0.17459
292.554,22.30381,12080.13184,0.17478
292.854,22.32868,12080.78711,0.17498
293.154,22.35375,12081.72461,0.17518
293.454,22.37881,12080.31445,0.17537
293.754,22.40368,12081.2959,0.17557
294.054,22.42893,12079.53516,0.17577
294.354,22.45356,12076.83887,0.17596
294.654,22.47875,12077.11426,0.17616
294.954,22.50368,12074.0625,0.17636
295.254,22.52862,12072.39941,0.17655
295.554,22.55387,12071.97949,0.17675
295.854,22.57856,12069.92383,0.17695
296.154,22.60387,12072.49121,0.17715
296.454,22.62868,12070.78418,0.17734
296.754,22.65375,12071.55762,0.17754
297.054,22.67893,12070.55371,0.17774
297.354,22.70356,12064.86914,0.17793
297.654,22.72869,12067.71875,0.17813
297.954,22.75356,12061.93066,0.17832
298.254,22.77868,12062.77344,0.17852
298.554,22.80381,12060.19629,0.17872
298.854,22.82875,12060.0332,0.17892
299.154,22.85381,12062.3584,0.17911
299.454,22.87875,12059.09668,0.17931
299.754,22.90381,12061.5752,0.17951
300.054,22.92881,12057,0.1797
300.354,22.95362,12055.08203,0.1799
300.654,22.97862,12053.95605,0.1801
300.954,23.00368,12050.63867,0.18029
301.254,23.02862,12050.96484,0.18049
301.554,23.05387,12048.43359,0.18069
301.854,23.07868,12048.36328,0.18088
302.154,23.10381,12049.02246,0.18108
302.454,23.12887,12048.48047,0.18128
302.754,23.15368,12047.03711,0.18147
303.054,23.17894,12045.88379,0.18167
303.354,23.2035,12040.62598,0.18187
303.654,23.22875,12041.84863,0.18207
303.954,23.25356,12037.75586,0.18226
304.254,23.27868,12036.45508,0.18246
304.554,23.30394,12037.24707,0.18266
304.854,23.32862,12032.92871,0.18285
305.154,23.35394,12037.19238,0.18305
305.454,23.37868,12031.82812,0.18325
305.754,23.40381,12033.79004,0.18344
306.054,23.42881,12030.37305,0.18364
306.354,23.45362,12026.13281,0.18384
306.654,23.47868,12028.47168,0.18403
306.954,23.50368,12022.01465,0.18423
307.254,23.52875,12023.40527,0.18443
307.554,23.55381,12019.26953,0.18463
307.854,23.57874,12019.12109,0.18482
308.154,23.60375,12018.88965,0.18502
308.454,23.62881,12016.71582,0.18522
308.754,23.65368,12017.13965,0.18541
309.054,23.67893,12013.74902,0.18561
309.354,23.70362,12011.03906,0.18581
309.654,23.72868,12009.58203,0.186
309.954,23.75368,12006.0127,0.1862
310.254,23.77856,12003.75,0.1864
310.554,23.80393,12002.0293,0.1866
310.854,23.82856,11999.0791,0.18679
311.154,23.85387,12000.65332,0.18699
311.454,23.87875,11998.50781,0.18718
311.754,23.90381,11997.96094,0.18738
312.054,23.92887,11995.50293,0.18758
312.354,23.95362,11989.9375,0.18777
312.654,23.97875,11990.93262,0.18797
312.954,24.00356,11983.74023,0.18817
313.254,24.02868,11983.66309,0.18836
313.554,24.05375,11980.22559,0.18856
313.854,24.07868,11977.98926,0.18876
314.154,24.10387,11980.22266,0.18896
314.454,24.12881,11975.50781,0.18915
314.754,24.15381,11976.73047,0.18935
315.054,24.17881,11970.81348,0.18955
315.354,24.20368,11967.67676,0.18974
315.654,24.22856,11965.56055,0.18994
315.954,24.25368,11961.33594,0.19014
316.254,24.27862,11958.95117,0.19033
316.554,24.30393,11955.31543,0.19053
316.854,24.32868,11953.96094,0.19073
317.154,24.35387,11953.23047,0.19093
317.454,24.37881,11951.04492,0.19112
317.754,24.40368,11947.08691,0.19132
318.054,24.42893,11944.45801,0.19152
318.354,24.45344,11937.61914,0.19171
318.654,24.47874,11937.71289,0.19191
318.954,24.50362,11932.0498,0.1921
319.254,24.52868,11928.18066,0.1923
319.554,24.55393,11926.38086,0.1925
319.854,24.57868,11920.88477,0.1927
320.154,24.60387,11922.59766,0.19289
320.454,24.62868,11915.69824,0.19309
320.754,24.65381,11914.74902,0.19329
321.054,24.67875,11909.26758,0.19348
321.354,24.70369,11903.07617,0.19368
321.654,24.72868,11902.46094,0.19388
321.954,24.75362,11893.63477,0.19407
322.254,24.77875,11893.16602,0.19427
322.554,24.80381,11885.80762,0.19447
322.854,24.82874,11883.19336,0.19466
323.154,24.85375,11880.31543,0.19486
323.454,24.87881,11874.9668,0.19506
323.754,24.90368,11871.59375,0.19525
324.054,24.92893,11865.9707,0.19545
324.354,24.95362,11859.77051,0.19565
324.654,24.97868,11854.72168,0.19585
324.954,25.00368,11848.33496,0.19604
325.254,25.02856,11842.14355,0.19624
325.554,25.05394,11837.44727,0.19644
325.854,25.07856,11830.08691,0.19663
326.154,25.10387,11828.38867,0.19683
326.454,25.12874,11821.91504,0.19703
326.754,25.15381,11817.15918,0.19722
327.054,25.17894,11810.83008,0.19742
327.354,25.20356,11799.93945,0.19762
327.654,25.22875,11797.19531,0.19781
327.954,25.25356,11785.45312,0.19801
328.254,25.27868,11780.43848,0.19821
328.554,25.30381,11772.69043,0.19841
328.854,25.32875,11765.08105,0.1986
329.154,25.35381,11762.3291,0.1988
329.454,25.37881,11751.97852,0.199
329.754,25.40381,11748.49902,0.19919
330.054,25.42887,11736.90918,0.19939
330.354,25.45362,11727.46094,0.19958
330.654,25.47856,11719.10352,0.19978
330.954,25.50362,11707.92871,0.19998
331.254,25.52856,11699.98828,0.20017
331.554,25.55393,11690.18262,0.20037
331.854,25.57868,11682.37402,0.20057
332.154,25.60387,11675.08105,0.20077
332.454,25.62887,11665.8125,0.20096
332.754,25.65368,11655.13965,0.20116
333.054,25.67887,11645.34277,0.20136
333.354,25.7035,11631.3916,0.20155
333.654,25.72868,11623.12988,0.20175
333.954,25.75362,11609.99414,0.20195
334.254,25.77868,11599.58496,0.20214
334.554,25.80387,11588.81543,0.20234
334.854,25.82868,11575.45605,0.20254
335.154,25.85393,11569.70898,0.20274
335.454,25.87868,11554.63184,0.20293
335.754,25.90381,11545.13574,0.20313
336.054,25.92881,11531.08398,0.20333
336.354,25.95362,11515.23242,0.20352
336.654,25.97868,11506.14551,0.20372
336.954,26.00368,11488.79492,0.20392
337.254,26.02868,11478.29395,0.20411
337.554,26.05381,11461.88281,0.20431
337.854,26.07874,11450.50293,0.20451
338.154,26.10375,11437.6416,0.2047
338.454,26.12881,11422.68652,0.2049
338.754,26.15368,11410.39355,0.2051
339.054,26.17894,11393.67188,0.2053
339.354,26.20356,11377.93164,0.20549
339.654,26.22869,11363.12988,0.20569
339.954,26.25368,11346.53711,0.20588
340.254,26.27862,11329.72461,0.20608
340.554,26.30393,11314.95215,0.20628
340.854,26.32862,11297.14355,0.20647
341.154,26.35387,11284.23242,0.20667
341.454,26.37875,11266.88965,0.20687
341.754,26.40375,11250.64746,0.20707
342.054,26.42887,11233.71875,0.20726
342.354,26.45362,11211.82227,0.20746
342.654,26.47875,11197.39648,0.20766
342.954,26.50356,11173.98438,0.20785
343.254,26.52875,11158.34668,0.20805
343.554,26.55375,11136.86914,0.20825
343.854,26.57868,11118.32227,0.20844
344.154,26.60381,11102.27637,0.20864
344.454,26.62881,11080.48047,0.20884
344.754,26.65381,11063.88379,0.20903
345.054,26.67887,11040.11621,0.20923
345.354,26.70362,11018.12305,0.20943
345.654,26.72862,10997.41895,0.20962
345.954,26.75368,10972.82324,0.20982
346.254,26.77862,10952.59473,0.21002
346.554,26.80393,10928.77344,0.21022
346.854,26.82868,10907.04004,0.21041
347.154,26.85387,10885.09668,0.21061
347.454,26.87881,10861.68457,0.21081
347.754,26.90368,10837.84375,0.211
348.054,26.929,10813.66992,0.2112
348.354,26.9535,10784.68848,0.21139
348.654,26.97875,10761.72266,0.21159
348.954,27.00362,10733.1123,0.21179
349.254,27.02868,10706.76074,0.21199
349.554,27.05393,10681.38965,0.21219
349.854,27.07868,10651.87109,0.21238
350.154,27.10394,10628.84375,0.21258
350.454,27.12875,10598.04395,0.21277
350.754,27.15375,10570.50195,0.21297
351.054,27.17881,10539.46387,0.21317
351.354,27.20362,10507.13086,0.21336
351.654,27.22869,10479.47754,0.21356
351.954,27.25368,10443.94727,0.21376
352.254,27.27875,10414.74609,0.21396
352.554,27.30381,10379.0625,0.21415
352.854,27.32875,10347.45898,0.21435
353.154,27.35374,10314.86719,0.21455
353.454,27.37881,10279.79102,0.21474
353.754,27.40368,10245.66504,0.21494
354.054,27.42893,10207.92285,0.21514
354.354,27.45356,10169.19043,0.21533
354.654,27.47868,10131.55762,0.21553
354.954,27.50368,10092.07129,0.21573
355.254,27.52862,10050.33789,0.21592
355.554,27.55393,10009.61719,0.21612
355.854,27.57856,9966.87891,0.21632
356.154,27.60394,9927.50684,0.21652
356.454,27.62868,9882.11621,0.21671
356.754,27.65381,9838.35059,0.21691
357.054,27.67893,9791.08105,0.21711
357.354,27.70356,9739.39453,0.2173
357.654,27.72875,9692.79883,0.2175
357.954,27.75356,9637.29883,0.21769
358.254,27.77868,9585.99219,0.21789
358.554,27.80375,9530.00488,0.21809
358.854,27.82875,9474.31348,0.21829
359.154,27.85387,9419.54785,0.21848
359.454,27.87881,9357.22266,0.21868
359.754,27.90381,9296.96973,0.21888
360.054,27.92881,9227.4082,0.21907
360.354,27.95362,9158.00098,0.21927
360.654,27.97862,9084.93066,0.21947
360.954,28.00368,9005.66504,0.21966
361.254,28.02862,8924.73438,0.21986
361.554,28.05393,8829.3916,0.22006
361.854,28.07868,8662.02539,0.22025
362.092,28.10231,-147.97504,0.22044